<?xml version="1.0" ?>
<!-- =================================================================================== -->
<!-- |    This document was autogenerated by xacro from src/exocet_mm40b3_description/urdf/exocet_mm40b3.xacro | -->
<!-- |    EDITING THIS FILE BY HAND IS NOT RECOMMENDED                                 | -->
<!-- =================================================================================== -->
<robot name="exocet_mm40b3">
  <material name="silver">
    <color rgba="0.700 0.700 0.700 1.000"/>
  </material>
  <transmission name="fins_fold1_tran">
    <type>transmission_interface/SimpleTransmission</type>
    <joint name="fins_fold1">
      <hardwareInterface>hardware_interface/EffortJointInterface</hardwareInterface>
    </joint>
    <actuator name="fins_fold1_actr">
      <hardwareInterface>hardware_interface/EffortJointInterface</hardwareInterface>
      <mechanicalReduction>1</mechanicalReduction>
    </actuator>
  </transmission>
  <transmission name="fins_rev1_tran">
    <type>transmission_interface/SimpleTransmission</type>
    <joint name="fins_rev1">
      <hardwareInterface>hardware_interface/EffortJointInterface</hardwareInterface>
    </joint>
    <actuator name="fins_rev1_actr">
      <hardwareInterface>hardware_interface/EffortJointInterface</hardwareInterface>
      <mechanicalReduction>1</mechanicalReduction>
    </actuator>
  </transmission>
  <transmission name="fins_fold4_tran">
    <type>transmission_interface/SimpleTransmission</type>
    <joint name="fins_fold4">
      <hardwareInterface>hardware_interface/EffortJointInterface</hardwareInterface>
    </joint>
    <actuator name="fins_fold4_actr">
      <hardwareInterface>hardware_interface/EffortJointInterface</hardwareInterface>
      <mechanicalReduction>1</mechanicalReduction>
    </actuator>
  </transmission>
  <transmission name="fins_rev4_tran">
    <type>transmission_interface/SimpleTransmission</type>
    <joint name="fins_rev4">
      <hardwareInterface>hardware_interface/EffortJointInterface</hardwareInterface>
    </joint>
    <actuator name="fins_rev4_actr">
      <hardwareInterface>hardware_interface/EffortJointInterface</hardwareInterface>
      <mechanicalReduction>1</mechanicalReduction>
    </actuator>
  </transmission>
  <transmission name="fins_fold3_tran">
    <type>transmission_interface/SimpleTransmission</type>
    <joint name="fins_fold3">
      <hardwareInterface>hardware_interface/EffortJointInterface</hardwareInterface>
    </joint>
    <actuator name="fins_fold3_actr">
      <hardwareInterface>hardware_interface/EffortJointInterface</hardwareInterface>
      <mechanicalReduction>1</mechanicalReduction>
    </actuator>
  </transmission>
  <transmission name="fins_rev3_tran">
    <type>transmission_interface/SimpleTransmission</type>
    <joint name="fins_rev3">
      <hardwareInterface>hardware_interface/EffortJointInterface</hardwareInterface>
    </joint>
    <actuator name="fins_rev3_actr">
      <hardwareInterface>hardware_interface/EffortJointInterface</hardwareInterface>
      <mechanicalReduction>1</mechanicalReduction>
    </actuator>
  </transmission>
  <transmission name="fins_fold2_tran">
    <type>transmission_interface/SimpleTransmission</type>
    <joint name="fins_fold2">
      <hardwareInterface>hardware_interface/EffortJointInterface</hardwareInterface>
    </joint>
    <actuator name="fins_fold2_actr">
      <hardwareInterface>hardware_interface/EffortJointInterface</hardwareInterface>
      <mechanicalReduction>1</mechanicalReduction>
    </actuator>
  </transmission>
  <transmission name="fins_rev2_tran">
    <type>transmission_interface/SimpleTransmission</type>
    <joint name="fins_rev2">
      <hardwareInterface>hardware_interface/EffortJointInterface</hardwareInterface>
    </joint>
    <actuator name="fins_rev2_actr">
      <hardwareInterface>hardware_interface/EffortJointInterface</hardwareInterface>
      <mechanicalReduction>1</mechanicalReduction>
    </actuator>
  </transmission>
  <transmission name="wings_fold1_tran">
    <type>transmission_interface/SimpleTransmission</type>
    <joint name="wings_fold1">
      <hardwareInterface>hardware_interface/EffortJointInterface</hardwareInterface>
    </joint>
    <actuator name="wings_fold1_actr">
      <hardwareInterface>hardware_interface/EffortJointInterface</hardwareInterface>
      <mechanicalReduction>1</mechanicalReduction>
    </actuator>
  </transmission>
  <transmission name="wings_fold2_tran">
    <type>transmission_interface/SimpleTransmission</type>
    <joint name="wings_fold2">
      <hardwareInterface>hardware_interface/EffortJointInterface</hardwareInterface>
    </joint>
    <actuator name="wings_fold2_actr">
      <hardwareInterface>hardware_interface/EffortJointInterface</hardwareInterface>
      <mechanicalReduction>1</mechanicalReduction>
    </actuator>
  </transmission>
  <transmission name="wings_fold3_tran">
    <type>transmission_interface/SimpleTransmission</type>
    <joint name="wings_fold3">
      <hardwareInterface>hardware_interface/EffortJointInterface</hardwareInterface>
    </joint>
    <actuator name="wings_fold3_actr">
      <hardwareInterface>hardware_interface/EffortJointInterface</hardwareInterface>
      <mechanicalReduction>1</mechanicalReduction>
    </actuator>
  </transmission>
  <transmission name="wings_fold4_tran">
    <type>transmission_interface/SimpleTransmission</type>
    <joint name="wings_fold4">
      <hardwareInterface>hardware_interface/EffortJointInterface</hardwareInterface>
    </joint>
    <actuator name="wings_fold4_actr">
      <hardwareInterface>hardware_interface/EffortJointInterface</hardwareInterface>
      <mechanicalReduction>1</mechanicalReduction>
    </actuator>
  </transmission>
  <!-- <gazebo>
    <plugin filename="libgazebo_ros_control.so" name="exocet_mm40b3_controller">
      <robotNamespace>exocet_mm40b3_controller</robotNamespace>
      <robotSimType>gazebo_ros_control/DefaultRobotHWSim</robotSimType>
    </plugin>
  </gazebo> -->
  <gazebo reference="base_link">
    <material>Gazebo/Silver</material>
    <mu1>0.2</mu1>
    <mu2>0.2</mu2>
    <selfCollide>true</selfCollide>
    <gravity>true</gravity>
  </gazebo>
  <gazebo reference="Fin_1">
    <material>Gazebo/Silver</material>
    <mu1>0.2</mu1>
    <mu2>0.2</mu2>
    <selfCollide>true</selfCollide>
  </gazebo>
  <gazebo reference="FinHolder_1">
    <material>Gazebo/Silver</material>
    <mu1>0.2</mu1>
    <mu2>0.2</mu2>
    <selfCollide>true</selfCollide>
  </gazebo>
  <gazebo reference="Fin_4">
    <material>Gazebo/Silver</material>
    <mu1>0.2</mu1>
    <mu2>0.2</mu2>
    <selfCollide>true</selfCollide>
  </gazebo>
  <gazebo reference="FinHolder_4">
    <material>Gazebo/Silver</material>
    <mu1>0.2</mu1>
    <mu2>0.2</mu2>
    <selfCollide>true</selfCollide>
  </gazebo>
  <gazebo reference="Fin_3">
    <material>Gazebo/Silver</material>
    <mu1>0.2</mu1>
    <mu2>0.2</mu2>
    <selfCollide>true</selfCollide>
  </gazebo>
  <gazebo reference="FinHolder_3">
    <material>Gazebo/Silver</material>
    <mu1>0.2</mu1>
    <mu2>0.2</mu2>
    <selfCollide>true</selfCollide>
  </gazebo>
  <gazebo reference="Fin_2">
    <material>Gazebo/Silver</material>
    <mu1>0.2</mu1>
    <mu2>0.2</mu2>
    <selfCollide>true</selfCollide>
  </gazebo>
  <gazebo reference="FinHolder_2">
    <material>Gazebo/Silver</material>
    <mu1>0.2</mu1>
    <mu2>0.2</mu2>
    <selfCollide>true</selfCollide>
  </gazebo>
  <gazebo reference="Wing1_1">
    <material>Gazebo/Silver</material>
    <mu1>0.2</mu1>
    <mu2>0.2</mu2>
    <selfCollide>true</selfCollide>
  </gazebo>
  <gazebo reference="Booster_1">
    <material>Gazebo/Silver</material>
    <mu1>0.2</mu1>
    <mu2>0.2</mu2>
    <selfCollide>true</selfCollide>
  </gazebo>
  <gazebo reference="Wing1_2">
    <material>Gazebo/Silver</material>
    <mu1>0.2</mu1>
    <mu2>0.2</mu2>
    <selfCollide>true</selfCollide>
  </gazebo>
  <gazebo reference="Wing1_3">
    <material>Gazebo/Silver</material>
    <mu1>0.2</mu1>
    <mu2>0.2</mu2>
    <selfCollide>true</selfCollide>
  </gazebo>
  <gazebo reference="Wing1_4">
    <material>Gazebo/Silver</material>
    <mu1>0.2</mu1>
    <mu2>0.2</mu2>
    <selfCollide>true</selfCollide>
  </gazebo>
  <gazebo reference="Holder_1">
    <material>Gazebo/Silver</material>
    <mu1>0.2</mu1>
    <mu2>0.2</mu2>
    <!-- <selfCollide>true</selfCollide> -->
    <selfCollide>false</selfCollide>
  </gazebo>
  <gazebo reference="Holder_2">
    <material>Gazebo/Silver</material>
    <mu1>0.2</mu1>
    <mu2>0.2</mu2>
    <!-- <selfCollide>true</selfCollide> -->
    <selfCollide>false</selfCollide>
  </gazebo>
  <gazebo reference="Holder_3">
    <material>Gazebo/Silver</material>
    <mu1>0.2</mu1>
    <mu2>0.2</mu2>
    <!-- <selfCollide>true</selfCollide> -->
    <selfCollide>false</selfCollide>
  </gazebo>
  <gazebo reference="Holder_4">
    <material>Gazebo/Silver</material>
    <mu1>0.2</mu1>
    <mu2>0.2</mu2>
    <!-- <selfCollide>true</selfCollide> -->
    <selfCollide>false</selfCollide>
  </gazebo>
  <gazebo reference="booster_fixing">
    <preserveFixedJoint>true</preserveFixedJoint>
  </gazebo>
  <gazebo reference="HolderJoint1">
    <preserveFixedJoint>true</preserveFixedJoint>
  </gazebo>
  <gazebo reference="HolderJoint2">
    <preserveFixedJoint>true</preserveFixedJoint>
  </gazebo>
  <gazebo reference="HolderJoint3">
    <preserveFixedJoint>true</preserveFixedJoint>
  </gazebo>
  <gazebo reference="HolderJoint4">
    <preserveFixedJoint>true</preserveFixedJoint>
  </gazebo>
  <link name="base_link">
    <inertial>
      <origin rpy="0 0 0" xyz="0.6111487363868037 -9.76514281557685e-10 9.765135572714681e-10"/>
      <mass value="564.9695328358481"/>
      <inertia ixx="13.560396" ixy="-0.0" ixz="0.0" iyy="1088.286862" iyz="0.0" izz="1088.286862"/>
    </inertial>
    <visual>
      <origin rpy="0 0 0" xyz="0 0 0"/>
      <geometry>
        <mesh filename="package://exocet_mm40b3_description/meshes/base_link.stl" scale="0.001 0.001 0.001"/>
      </geometry>
      <material name="silver"/>
    </visual>
    <collision>
      <origin rpy="0 0 0" xyz="0 0 0"/>
      <geometry>
        <mesh filename="package://exocet_mm40b3_description/meshes/base_link.stl" scale="0.001 0.001 0.001"/>
      </geometry>
    </collision>
  </link>
  <link name="Fin_1">
    <inertial>
      <origin rpy="0 0 0" xyz="-0.01567003850913462 -0.05105851626061409 -0.03315778654302706"/>
      <mass value="1.1914641784690367"/>
      <inertia ixx="0.003045" ixy="-0.000707" ixz="-0.000459" iyy="0.003419" iyz="-0.00136" izz="0.004631"/>
    </inertial>
    <visual>
      <origin rpy="0 0 0" xyz="1.508834 0.0 -0.235"/>
      <geometry>
        <mesh filename="package://exocet_mm40b3_description/meshes/Fin_1.stl" scale="0.001 0.001 0.001"/>
      </geometry>
      <material name="silver"/>
    </visual>
    <collision>
      <origin rpy="0 0 0" xyz="1.508834 0.0 -0.235"/>
      <geometry>
        <mesh filename="package://exocet_mm40b3_description/meshes/Fin_1.stl" scale="0.001 0.001 0.001"/>
      </geometry>
    </collision>
  </link>
  <link name="FinHolder_1">
    <inertial>
      <origin rpy="0 0 0" xyz="0.011989934287514492 3.4948123536970334e-06 0.035203705025338594"/>
      <mass value="0.6136418967408529"/>
      <inertia ixx="0.000219" ixy="-0.0" ixz="3.8e-05" iyy="0.004162" iyz="-0.0" izz="0.003989"/>
    </inertial>
    <visual>
      <origin rpy="0 0 0" xyz="1.508834 0.0 -0.18"/>
      <geometry>
        <mesh filename="package://exocet_mm40b3_description/meshes/FinHolder_1.stl" scale="0.001 0.001 0.001"/>
      </geometry>
      <material name="silver"/>
    </visual>
    <collision>
      <origin rpy="0 0 0" xyz="1.508834 0.0 -0.18"/>
      <geometry>
        <mesh filename="package://exocet_mm40b3_description/meshes/FinHolder_1.stl" scale="0.001 0.001 0.001"/>
      </geometry>
    </collision>
  </link>
  <link name="Fin_4">
    <inertial>
      <origin rpy="0 0 0" xyz="-0.01567003850913462 0.03315778654302701 -0.05105851430757993"/>
      <mass value="1.1914641784690367"/>
      <inertia ixx="0.003045" ixy="0.000459" ixz="-0.000707" iyy="0.004631" iyz="0.00136" izz="0.003419"/>
    </inertial>
    <visual>
      <origin rpy="0 0 0" xyz="1.508834 0.235 -0.0"/>
      <geometry>
        <mesh filename="package://exocet_mm40b3_description/meshes/Fin_4.stl" scale="0.001 0.001 0.001"/>
      </geometry>
      <material name="silver"/>
    </visual>
    <collision>
      <origin rpy="0 0 0" xyz="1.508834 0.235 -0.0"/>
      <geometry>
        <mesh filename="package://exocet_mm40b3_description/meshes/Fin_4.stl" scale="0.001 0.001 0.001"/>
      </geometry>
    </collision>
  </link>
  <link name="FinHolder_4">
    <inertial>
      <origin rpy="0 0 0" xyz="0.011989934287514492 -0.03520370502533865 3.4967653878920464e-06"/>
      <mass value="0.6136418967408529"/>
      <inertia ixx="0.000219" ixy="-3.8e-05" ixz="-0.0" iyy="0.003989" iyz="0.0" izz="0.004162"/>
    </inertial>
    <visual>
      <origin rpy="0 0 0" xyz="1.508834 0.18 -0.0"/>
      <geometry>
        <mesh filename="package://exocet_mm40b3_description/meshes/FinHolder_4.stl" scale="0.001 0.001 0.001"/>
      </geometry>
      <material name="silver"/>
    </visual>
    <collision>
      <origin rpy="0 0 0" xyz="1.508834 0.18 -0.0"/>
      <geometry>
        <mesh filename="package://exocet_mm40b3_description/meshes/FinHolder_4.stl" scale="0.001 0.001 0.001"/>
      </geometry>
    </collision>
  </link>
  <link name="Fin_3">
    <inertial>
      <origin rpy="0 0 0" xyz="-0.015670038509135065 0.05105822037918793 0.033157788496061325"/>
      <mass value="1.1914641784690367"/>
      <inertia ixx="0.003045" ixy="0.000707" ixz="0.000459" iyy="0.003419" iyz="-0.00136" izz="0.004631"/>
    </inertial>
    <visual>
      <origin rpy="0 0 0" xyz="1.508834 1.7e-05 0.235"/>
      <geometry>
        <mesh filename="package://exocet_mm40b3_description/meshes/Fin_3.stl" scale="0.001 0.001 0.001"/>
      </geometry>
      <material name="silver"/>
    </visual>
    <collision>
      <origin rpy="0 0 0" xyz="1.508834 1.7e-05 0.235"/>
      <geometry>
        <mesh filename="package://exocet_mm40b3_description/meshes/Fin_3.stl" scale="0.001 0.001 0.001"/>
      </geometry>
    </collision>
  </link>
  <link name="FinHolder_3">
    <inertial>
      <origin rpy="0 0 0" xyz="0.011989934287514492 -3.496765387940896e-06 -0.03520370307230428"/>
      <mass value="0.6136418967408529"/>
      <inertia ixx="0.000219" ixy="0.0" ixz="-3.8e-05" iyy="0.004162" iyz="-0.0" izz="0.003989"/>
    </inertial>
    <visual>
      <origin rpy="0 0 0" xyz="1.508834 0.0 0.18"/>
      <geometry>
        <mesh filename="package://exocet_mm40b3_description/meshes/FinHolder_3.stl" scale="0.001 0.001 0.001"/>
      </geometry>
      <material name="silver"/>
    </visual>
    <collision>
      <origin rpy="0 0 0" xyz="1.508834 0.0 0.18"/>
      <geometry>
        <mesh filename="package://exocet_mm40b3_description/meshes/FinHolder_3.stl" scale="0.001 0.001 0.001"/>
      </geometry>
    </collision>
  </link>
  <link name="Fin_2">
    <inertial>
      <origin rpy="0 0 0" xyz="-0.01567003850913551 -0.033157788496061325 0.051058222332222306"/>
      <mass value="1.1914641784690367"/>
      <inertia ixx="0.003045" ixy="-0.000459" ixz="0.000707" iyy="0.004631" iyz="0.00136" izz="0.003419"/>
    </inertial>
    <visual>
      <origin rpy="0 0 0" xyz="1.508834 -0.235 1.7e-05"/>
      <geometry>
        <mesh filename="package://exocet_mm40b3_description/meshes/Fin_2.stl" scale="0.001 0.001 0.001"/>
      </geometry>
      <material name="silver"/>
    </visual>
    <collision>
      <origin rpy="0 0 0" xyz="1.508834 -0.235 1.7e-05"/>
      <geometry>
        <mesh filename="package://exocet_mm40b3_description/meshes/Fin_2.stl" scale="0.001 0.001 0.001"/>
      </geometry>
    </collision>
  </link>
  <link name="FinHolder_2">
    <inertial>
      <origin rpy="0 0 0" xyz="0.011989934287514048 0.035203703072304304 -3.4948123536082156e-06"/>
      <mass value="0.6136418967408529"/>
      <inertia ixx="0.000219" ixy="3.8e-05" ixz="0.0" iyy="0.003989" iyz="0.0" izz="0.004162"/>
    </inertial>
    <visual>
      <origin rpy="0 0 0" xyz="1.508834 -0.18 -0.0"/>
      <geometry>
        <mesh filename="package://exocet_mm40b3_description/meshes/FinHolder_2.stl" scale="0.001 0.001 0.001"/>
      </geometry>
      <material name="silver"/>
    </visual>
    <collision>
      <origin rpy="0 0 0" xyz="1.508834 -0.18 -0.0"/>
      <geometry>
        <mesh filename="package://exocet_mm40b3_description/meshes/FinHolder_2.stl" scale="0.001 0.001 0.001"/>
      </geometry>
    </collision>
  </link>
  <link name="Wing1_1">
    <inertial>
      <origin rpy="0 0 0" xyz="-0.040666207659852904 -0.08074492818224165 -0.05243595001666804"/>
      <mass value="7.941525705671461"/>
      <inertia ixx="0.045859" ixy="-0.016465" ixz="-0.010693" iyy="0.280396" iyz="-0.020713" izz="0.29884"/>
    </inertial>
    <visual>
      <origin rpy="0 0 0" xyz="0.055606 0.0 -0.231018"/>
      <geometry>
        <mesh filename="package://exocet_mm40b3_description/meshes/Wing1_1.stl" scale="0.001 0.001 0.001"/>
      </geometry>
      <material name="silver"/>
    </visual>
    <collision>
      <origin rpy="0 0 0" xyz="0.055606 0.0 -0.231018"/>
      <geometry>
        <mesh filename="package://exocet_mm40b3_description/meshes/Wing1_1.stl" scale="0.001 0.001 0.001"/>
      </geometry>
    </collision>
  </link>
  <link name="Booster_1">
    <inertial>
      <origin rpy="0 0 0" xyz="-0.5309883305776795 4.1152716735485273e-10 1.8088332072416784e-09"/>
      <mass value="138.76341026969325"/>
      <inertia ixx="6.064544" ixy="-0.0" ixz="-0.0" iyy="17.450475" iyz="0.0" izz="17.450475"/>
    </inertial>
    <visual>
      <origin rpy="0 0 0" xyz="1.688846 0.0 -0.0"/>
      <geometry>
        <mesh filename="package://exocet_mm40b3_description/meshes/Booster_1.stl" scale="0.001 0.001 0.001"/>
      </geometry>
      <material name="silver"/>
    </visual>
    <collision>
      <origin rpy="0 0 0" xyz="1.688846 0.0 -0.0"/>
      <geometry>
        <mesh filename="package://exocet_mm40b3_description/meshes/Booster_1.stl" scale="0.001 0.001 0.001"/>
      </geometry>
    </collision>
  </link>
  <link name="Wing1_2">
    <inertial>
      <origin rpy="0 0 0" xyz="-0.040666207659852974 -0.05189131293468413 0.07990625761429629"/>
      <mass value="7.941525705671461"/>
      <inertia ixx="0.045859" ixy="-0.010693" ixz="0.016465" iyy="0.29884" iyz="0.020713" izz="0.280396"/>
    </inertial>
    <visual>
      <origin rpy="0 0 0" xyz="0.055606 -0.231018 -0.0"/>
      <geometry>
        <mesh filename="package://exocet_mm40b3_description/meshes/Wing1_2.stl" scale="0.001 0.001 0.001"/>
      </geometry>
      <material name="silver"/>
    </visual>
    <collision>
      <origin rpy="0 0 0" xyz="0.055606 -0.231018 -0.0"/>
      <geometry>
        <mesh filename="package://exocet_mm40b3_description/meshes/Wing1_2.stl" scale="0.001 0.001 0.001"/>
      </geometry>
    </collision>
  </link>
  <link name="Wing1_3">
    <inertial>
      <origin rpy="0 0 0" xyz="-0.04066620765985304 0.07990625566126518 0.05189131293468455"/>
      <mass value="7.941525705671461"/>
      <inertia ixx="0.045859" ixy="0.016465" ixz="0.010693" iyy="0.280396" iyz="-0.020713" izz="0.29884"/>
    </inertial>
    <visual>
      <origin rpy="0 0 0" xyz="0.055606 0.0 0.231018"/>
      <geometry>
        <mesh filename="package://exocet_mm40b3_description/meshes/Wing1_3.stl" scale="0.001 0.001 0.001"/>
      </geometry>
      <material name="silver"/>
    </visual>
    <collision>
      <origin rpy="0 0 0" xyz="0.055606 0.0 0.231018"/>
      <geometry>
        <mesh filename="package://exocet_mm40b3_description/meshes/Wing1_3.stl" scale="0.001 0.001 0.001"/>
      </geometry>
    </collision>
  </link>
  <link name="Wing1_4">
    <inertial>
      <origin rpy="0 0 0" xyz="-0.04066620765985225 0.05189131098165295 -0.07990625566126565"/>
      <mass value="7.941525705671461"/>
      <inertia ixx="0.045859" ixy="0.010693" ixz="-0.016465" iyy="0.29884" iyz="0.020713" izz="0.280396"/>
    </inertial>
    <visual>
      <origin rpy="0 0 0" xyz="0.055606 0.231018 -0.0"/>
      <geometry>
        <mesh filename="package://exocet_mm40b3_description/meshes/Wing1_4.stl" scale="0.001 0.001 0.001"/>
      </geometry>
      <material name="silver"/>
    </visual>
    <collision>
      <origin rpy="0 0 0" xyz="0.055606 0.231018 -0.0"/>
      <geometry>
        <mesh filename="package://exocet_mm40b3_description/meshes/Wing1_4.stl" scale="0.001 0.001 0.001"/>
      </geometry>
    </collision>
  </link>
  <link name="Holder_1">
    <inertial>
      <origin rpy="0 0 0" xyz="-0.1999999917328794 -9.765093429786492e-10 0.03551866363101741"/>
      <mass value="12.2115195694117"/>
      <inertia ixx="0.166572" ixy="-0.0" ixz="-0.0" iyy="0.702777" iyz="-0.0" izz="0.847629"/>
    </inertial>
    <visual>
      <origin rpy="0 0 0" xyz="-1.567625 0.0 -0.187374"/>
      <geometry>
        <mesh filename="package://exocet_mm40b3_description/meshes/Holder_1.stl" scale="0.001 0.001 0.001"/>
      </geometry>
      <material name="silver"/>
    </visual>
    <collision>
      <origin rpy="0 0 0" xyz="-1.567625 0.0 -0.187374"/>
      <geometry>
        <mesh filename="package://exocet_mm40b3_description/meshes/Holder_1.stl" scale="0.001 0.001 0.001"/>
      </geometry>
    </collision>
  </link>
  <link name="Holder_2">
    <inertial>
      <origin rpy="0 0 0" xyz="-0.1999999917328794 -0.03551866363101741 -9.765093293304098e-10"/>
      <mass value="12.2115195694117"/>
      <inertia ixx="0.166572" ixy="0.0" ixz="-0.0" iyy="0.847629" iyz="0.0" izz="0.702777"/>
    </inertial>
    <visual>
      <origin rpy="0 0 0" xyz="-1.567625 0.187374 -0.0"/>
      <geometry>
        <mesh filename="package://exocet_mm40b3_description/meshes/Holder_2.stl" scale="0.001 0.001 0.001"/>
      </geometry>
      <material name="silver"/>
    </visual>
    <collision>
      <origin rpy="0 0 0" xyz="-1.567625 0.187374 -0.0"/>
      <geometry>
        <mesh filename="package://exocet_mm40b3_description/meshes/Holder_2.stl" scale="0.001 0.001 0.001"/>
      </geometry>
    </collision>
  </link>
  <link name="Holder_3">
    <inertial>
      <origin rpy="0 0 0" xyz="-0.1999999917328794 9.765093156821704e-10 -0.03551866363101741"/>
      <mass value="12.2115195694117"/>
      <inertia ixx="0.166572" ixy="0.0" ixz="0.0" iyy="0.702777" iyz="-0.0" izz="0.847629"/>
    </inertial>
    <visual>
      <origin rpy="0 0 0" xyz="-1.567625 0.0 0.187374"/>
      <geometry>
        <mesh filename="package://exocet_mm40b3_description/meshes/Holder_3.stl" scale="0.001 0.001 0.001"/>
      </geometry>
      <material name="silver"/>
    </visual>
    <collision>
      <origin rpy="0 0 0" xyz="-1.567625 0.0 0.187374"/>
      <geometry>
        <mesh filename="package://exocet_mm40b3_description/meshes/Holder_3.stl" scale="0.001 0.001 0.001"/>
      </geometry>
    </collision>
  </link>
  <link name="Holder_4">
    <inertial>
      <origin rpy="0 0 0" xyz="-0.1999999917328794 0.03551866363101741 9.765093020339312e-10"/>
      <mass value="12.2115195694117"/>
      <inertia ixx="0.166572" ixy="-0.0" ixz="0.0" iyy="0.847629" iyz="0.0" izz="0.702777"/>
    </inertial>
    <visual>
      <origin rpy="0 0 0" xyz="-1.567625 -0.187374 -0.0"/>
      <geometry>
        <mesh filename="package://exocet_mm40b3_description/meshes/Holder_4.stl" scale="0.001 0.001 0.001"/>
      </geometry>
      <material name="silver"/>
    </visual>
    <collision>
      <origin rpy="0 0 0" xyz="-1.567625 -0.187374 -0.0"/>
      <geometry>
        <mesh filename="package://exocet_mm40b3_description/meshes/Holder_4.stl" scale="0.001 0.001 0.001"/>
      </geometry>
    </collision>
  </link>
  <joint name="fins_fold1" type="revolute">
    <origin rpy="0 0 0" xyz="0.0 0.0 0.055"/>
    <parent link="FinHolder_1"/>
    <child link="Fin_1"/>
    <axis xyz="-1.0 0.0 -0.0"/>
    <limit effort="100" lower="0.0" upper="2.146755" velocity="100"/>
  </joint>
  <joint name="fins_rev1" type="revolute">
    <origin rpy="0 0 0" xyz="-1.508834 0.0 0.18"/>
    <parent link="base_link"/>
    <child link="FinHolder_1"/>
    <axis xyz="-0.0 -0.0 1.0"/>
    <limit effort="100" lower="-0.349066" upper="0.349066" velocity="100"/>
  </joint>
  <joint name="fins_fold4" type="revolute">
    <origin rpy="0 0 0" xyz="0.0 -0.055 0.0"/>
    <parent link="FinHolder_4"/>
    <child link="Fin_4"/>
    <axis xyz="-1.0 0.0 0.0"/>
    <limit effort="100" lower="0.0" upper="2.146755" velocity="100"/>
  </joint>
  <joint name="fins_rev4" type="revolute">
    <origin rpy="0 0 0" xyz="-1.508834 -0.18 0.0"/>
    <parent link="base_link"/>
    <child link="FinHolder_4"/>
    <axis xyz="-0.0 -1.0 -0.0"/>
    <limit effort="100" lower="-0.349066" upper="0.349066" velocity="100"/>
  </joint>
  <joint name="fins_fold3" type="revolute">
    <origin rpy="0 0 0" xyz="0.0 -1.7e-05 -0.055"/>
    <parent link="FinHolder_3"/>
    <child link="Fin_3"/>
    <axis xyz="-1.0 0.0 -0.0"/>
    <limit effort="100" lower="0.0" upper="2.146755" velocity="100"/>
  </joint>
  <joint name="fins_rev3" type="revolute">
    <origin rpy="0 0 0" xyz="-1.508834 0.0 -0.18"/>
    <parent link="base_link"/>
    <child link="FinHolder_3"/>
    <axis xyz="-0.0 0.0 -1.0"/>
    <limit effort="100" lower="-0.349066" upper="0.349066" velocity="100"/>
  </joint>
  <joint name="fins_fold2" type="revolute">
    <origin rpy="0 0 0" xyz="0.0 0.055 -1.7e-05"/>
    <parent link="FinHolder_2"/>
    <child link="Fin_2"/>
    <axis xyz="-1.0 0.0 0.0"/>
    <limit effort="100" lower="0.0" upper="2.146755" velocity="100"/>
  </joint>
  <joint name="fins_rev2" type="revolute">
    <origin rpy="0 0 0" xyz="-1.508834 0.18 0.0"/>
    <parent link="base_link"/>
    <child link="FinHolder_2"/>
    <axis xyz="-0.0 1.0 0.0"/>
    <limit effort="100" lower="-0.349066" upper="0.349066" velocity="100"/>
  </joint>
  <joint name="wings_fold1" type="revolute">
    <origin rpy="0 0 0" xyz="-0.055606 0.0 0.231018"/>
    <parent link="base_link"/>
    <child link="Wing1_1"/>
    <axis xyz="1.0 0.0 -0.0"/>
    <limit effort="100" lower="-2.146755" upper="0.0" velocity="100"/>
  </joint>
  <joint name="booster_fixing" type="fixed">
    <origin rpy="0 0 0" xyz="-1.688846 0.0 0.0"/>
    <parent link="base_link"/>
    <child link="Booster_1"/>
  </joint>
  <joint name="wings_fold2" type="revolute">
    <origin rpy="0 0 0" xyz="-0.055606 0.231018 0.0"/>
    <parent link="base_link"/>
    <child link="Wing1_2"/>
    <axis xyz="1.0 0.0 -0.0"/>
    <limit effort="100" lower="-2.146755" upper="0.0" velocity="100"/>
  </joint>
  <joint name="wings_fold3" type="revolute">
    <origin rpy="0 0 0" xyz="-0.055606 0.0 -0.231018"/>
    <parent link="base_link"/>
    <child link="Wing1_3"/>
    <axis xyz="1.0 0.0 -0.0"/>
    <limit effort="100" lower="-2.146755" upper="0.0" velocity="100"/>
  </joint>
  <joint name="wings_fold4" type="revolute">
    <origin rpy="0 0 0" xyz="-0.055606 -0.231018 0.0"/>
    <parent link="base_link"/>
    <child link="Wing1_4"/>
    <axis xyz="1.0 0.0 -0.0"/>
    <limit effort="100" lower="-2.146755" upper="0.0" velocity="100"/>
  </joint>
  <joint name="HolderJoint1" type="fixed">
    <origin rpy="0 0 0" xyz="1.567625 0.0 0.187374"/>
    <parent link="base_link"/>
    <child link="Holder_1"/>
  </joint>
  <joint name="HolderJoint2" type="fixed">
    <origin rpy="0 0 0" xyz="1.567625 -0.187374 0.0"/>
    <parent link="base_link"/>
    <child link="Holder_2"/>
  </joint>
  <joint name="HolderJoint3" type="fixed">
    <origin rpy="0 0 0" xyz="1.567625 0.0 -0.187374"/>
    <parent link="base_link"/>
    <child link="Holder_3"/>
  </joint>
  <joint name="HolderJoint4" type="fixed">
    <origin rpy="0 0 0" xyz="1.567625 0.187374 0.0"/>
    <parent link="base_link"/>
    <child link="Holder_4"/>
  </joint>
</robot>
