<?xml version="1.0" ?>
<robot name="ex_mm40b3" xmlns:xacro="http://www.ros.org/wiki/xacro">

<xacro:include filename="$(find ex_mm40b3_description)/urdf/materials.xacro" />
<xacro:include filename="$(find ex_mm40b3_description)/urdf/ex_mm40b3.trans" />
<xacro:include filename="$(find ex_mm40b3_description)/urdf/ex_mm40b3.gazebo" />
<link name="base_link">
  <inertial>
    <origin xyz="0.5582187363868036 -9.491428765021313e-11 -7.544864658374226e-10" rpy="0 0 0"/>
    <mass value="564.9695328358481"/>
    <inertia ixx="13.560396" iyy="1088.286862" izz="1088.286862" ixy="-0.0" iyz="0.0" ixz="0.0"/>
  </inertial>
  <visual>
    <origin xyz="0 0 0" rpy="0 0 0"/>
    <geometry>
      <mesh filename="package://ex_mm40b3_description/meshes/base_link.stl" scale="0.001 0.001 0.001"/>
    </geometry>
    <material name="white"/>
  </visual>
  <collision>
    <origin xyz="0 0 0" rpy="0 0 0"/>
    <geometry>
      <mesh filename="package://ex_mm40b3_description/meshes/base_link.stl" scale="0.001 0.001 0.001"/>
    </geometry>
  </collision>
</link>

<link name="FinHolder_1">
  <inertial>
    <origin xyz="0.01198993428751427 3.495693953659855e-06 0.03520370329433853" rpy="0 0 0"/>
    <mass value="0.6136418967408529"/>
    <inertia ixx="0.000219" iyy="0.004162" izz="0.003989" ixy="-0.0" iyz="-0.0" ixz="3.8e-05"/>
  </inertial>
  <visual>
    <origin xyz="1.561764 0.0 -0.18" rpy="0 0 0"/>
    <geometry>
      <mesh filename="package://ex_mm40b3_description/meshes/FinHolder_1.stl" scale="0.001 0.001 0.001"/>
    </geometry>
    <material name="blue"/>
  </visual>
  <collision>
    <origin xyz="1.561764 0.0 -0.18" rpy="0 0 0"/>
    <geometry>
      <mesh filename="package://ex_mm40b3_description/meshes/FinHolder_1.stl" scale="0.001 0.001 0.001"/>
    </geometry>
  </collision>
</link>

<link name="FinHolder_4">
  <inertial>
    <origin xyz="0.01198993428751427 -0.03520370414373866 3.495034387886701e-06" rpy="0 0 0"/>
    <mass value="0.6136418967408529"/>
    <inertia ixx="0.000219" iyy="0.003989" izz="0.004162" ixy="-3.8e-05" iyz="0.0" ixz="-0.0"/>
  </inertial>
  <visual>
    <origin xyz="1.561764 0.18 0.0" rpy="0 0 0"/>
    <geometry>
      <mesh filename="package://ex_mm40b3_description/meshes/FinHolder_4.stl" scale="0.001 0.001 0.001"/>
    </geometry>
    <material name="blue"/>
  </visual>
  <collision>
    <origin xyz="1.561764 0.18 0.0" rpy="0 0 0"/>
    <geometry>
      <mesh filename="package://ex_mm40b3_description/meshes/FinHolder_4.stl" scale="0.001 0.001 0.001"/>
    </geometry>
  </collision>
</link>

<link name="FinHolder_3">
  <inertial>
    <origin xyz="0.01198993428751427 -3.4958837879403273e-06 -0.035203704803304314" rpy="0 0 0"/>
    <mass value="0.6136418967408529"/>
    <inertia ixx="0.000219" iyy="0.004162" izz="0.003989" ixy="0.0" iyz="-0.0" ixz="-3.8e-05"/>
  </inertial>
  <visual>
    <origin xyz="1.561764 0.0 0.18" rpy="0 0 0"/>
    <geometry>
      <mesh filename="package://ex_mm40b3_description/meshes/FinHolder_3.stl" scale="0.001 0.001 0.001"/>
    </geometry>
    <material name="blue"/>
  </visual>
  <collision>
    <origin xyz="1.561764 0.0 0.18" rpy="0 0 0"/>
    <geometry>
      <mesh filename="package://ex_mm40b3_description/meshes/FinHolder_3.stl" scale="0.001 0.001 0.001"/>
    </geometry>
  </collision>
</link>

<link name="FinHolder_2">
  <inertial>
    <origin xyz="0.01198993428751427 0.035203703953904264 -3.496543353653529e-06" rpy="0 0 0"/>
    <mass value="0.6136418967408529"/>
    <inertia ixx="0.000219" iyy="0.003989" izz="0.004162" ixy="3.8e-05" iyz="0.0" ixz="0.0"/>
  </inertial>
  <visual>
    <origin xyz="1.561764 -0.18 0.0" rpy="0 0 0"/>
    <geometry>
      <mesh filename="package://ex_mm40b3_description/meshes/FinHolder_2.stl" scale="0.001 0.001 0.001"/>
    </geometry>
    <material name="blue"/>
  </visual>
  <collision>
    <origin xyz="1.561764 -0.18 0.0" rpy="0 0 0"/>
    <geometry>
      <mesh filename="package://ex_mm40b3_description/meshes/FinHolder_2.stl" scale="0.001 0.001 0.001"/>
    </geometry>
  </collision>
</link>

<link name="Wing1_1">
  <inertial>
    <origin xyz="-0.04066620765985293 0.0807449272160705 -0.05243595158558506" rpy="0 0 0"/>
    <mass value="7.941525705671481"/>
    <inertia ixx="0.045859" iyy="0.280396" izz="0.29884" ixy="0.016465" iyz="0.020713" ixz="-0.010693"/>
  </inertial>
  <visual>
    <origin xyz="0.108536 0.0 -0.231018" rpy="0 0 0"/>
    <geometry>
      <mesh filename="package://ex_mm40b3_description/meshes/Wing1_1.stl" scale="0.001 0.001 0.001"/>
    </geometry>
    <material name="orange"/>
  </visual>
  <collision>
    <origin xyz="0.108536 0.0 -0.231018" rpy="0 0 0"/>
    <geometry>
      <mesh filename="package://ex_mm40b3_description/meshes/Wing1_1.stl" scale="0.001 0.001 0.001"/>
    </geometry>
  </collision>
</link>

<link name="Booster_1">
  <inertial>
    <origin xyz="-0.5309883305776795 1.2931271704902409e-09 7.783320420974786e-11" rpy="0 0 0"/>
    <mass value="138.76341026969325"/>
    <inertia ixx="6.064544" iyy="17.450475" izz="17.450475" ixy="-0.0" iyz="0.0" ixz="-0.0"/>
  </inertial>
  <visual>
    <origin xyz="1.741776 0.0 0.0" rpy="0 0 0"/>
    <geometry>
      <mesh filename="package://ex_mm40b3_description/meshes/Booster_1.stl" scale="0.001 0.001 0.001"/>
    </geometry>
    <material name="grey"/>
  </visual>
  <collision>
    <origin xyz="1.741776 0.0 0.0" rpy="0 0 0"/>
    <geometry>
      <mesh filename="package://ex_mm40b3_description/meshes/Booster_1.stl" scale="0.001 0.001 0.001"/>
    </geometry>
  </collision>
</link>

<link name="Wing1_2">
  <inertial>
    <origin xyz="-0.040666207659853376 -0.05189131189100127 -0.079906257497525" rpy="0 0 0"/>
    <mass value="7.941525705671481"/>
    <inertia ixx="0.045859" iyy="0.29884" izz="0.280396" ixy="-0.010693" iyz="-0.020713" ixz="-0.016465"/>
  </inertial>
  <visual>
    <origin xyz="0.108536 -0.231018 0.0" rpy="0 0 0"/>
    <geometry>
      <mesh filename="package://ex_mm40b3_description/meshes/Wing1_2.stl" scale="0.001 0.001 0.001"/>
    </geometry>
    <material name="orange"/>
  </visual>
  <collision>
    <origin xyz="0.108536 -0.231018 0.0" rpy="0 0 0"/>
    <geometry>
      <mesh filename="package://ex_mm40b3_description/meshes/Wing1_2.stl" scale="0.001 0.001 0.001"/>
    </geometry>
  </collision>
</link>

<link name="Wing1_3">
  <inertial>
    <origin xyz="-0.04066620765985307 -0.07990625683795603 0.051891311041601024" rpy="0 0 0"/>
    <mass value="7.941525705671481"/>
    <inertia ixx="0.045859" iyy="0.280396" izz="0.29884" ixy="-0.016465" iyz="0.020713" ixz="0.010693"/>
  </inertial>
  <visual>
    <origin xyz="0.108536 0.0 0.231018" rpy="0 0 0"/>
    <geometry>
      <mesh filename="package://ex_mm40b3_description/meshes/Wing1_3.stl" scale="0.001 0.001 0.001"/>
    </geometry>
    <material name="orange"/>
  </visual>
  <collision>
    <origin xyz="0.108536 0.0 0.231018" rpy="0 0 0"/>
    <geometry>
      <mesh filename="package://ex_mm40b3_description/meshes/Wing1_3.stl" scale="0.001 0.001 0.001"/>
    </geometry>
  </collision>
</link>

<link name="Wing1_4">
  <inertial>
    <origin xyz="-0.04066620765985285 0.051891311701170034 0.07990625598855573" rpy="0 0 0"/>
    <mass value="7.941525705671481"/>
    <inertia ixx="0.045859" iyy="0.29884" izz="0.280396" ixy="0.010693" iyz="-0.020713" ixz="0.016465"/>
  </inertial>
  <visual>
    <origin xyz="0.108536 0.231018 0.0" rpy="0 0 0"/>
    <geometry>
      <mesh filename="package://ex_mm40b3_description/meshes/Wing1_4.stl" scale="0.001 0.001 0.001"/>
    </geometry>
    <material name="orange"/>
  </visual>
  <collision>
    <origin xyz="0.108536 0.231018 0.0" rpy="0 0 0"/>
    <geometry>
      <mesh filename="package://ex_mm40b3_description/meshes/Wing1_4.stl" scale="0.001 0.001 0.001"/>
    </geometry>
  </collision>
</link>

<link name="Holder_1">
  <inertial>
    <origin xyz="-0.1999999917328792 -9.490927239922491e-11 0.03608121241836992" rpy="0 0 0"/>
    <mass value="12.085489344125179"/>
    <inertia ixx="0.161772" iyy="0.69521" izz="0.836017" ixy="-0.0" iyz="-0.0" ixz="-0.0"/>
  </inertial>
  <visual>
    <origin xyz="-1.514695 0.0 -0.187374" rpy="0 0 0"/>
    <geometry>
      <mesh filename="package://ex_mm40b3_description/meshes/Holder_1.stl" scale="0.001 0.001 0.001"/>
    </geometry>
    <material name="darkgrey"/>
  </visual>
  <collision>
    <origin xyz="-1.514695 0.0 -0.187374" rpy="0 0 0"/>
    <geometry>
      <mesh filename="package://ex_mm40b3_description/meshes/Holder_1.stl" scale="0.001 0.001 0.001"/>
    </geometry>
  </collision>
</link>

<link name="Holder_2">
  <inertial>
    <origin xyz="-0.1999999917328792 -0.03608121241836992 -9.490925871653939e-11" rpy="0 0 0"/>
    <mass value="12.085489344125179"/>
    <inertia ixx="0.161772" iyy="0.836017" izz="0.69521" ixy="0.0" iyz="0.0" ixz="-0.0"/>
  </inertial>
  <visual>
    <origin xyz="-1.514695 0.187374 0.0" rpy="0 0 0"/>
    <geometry>
      <mesh filename="package://ex_mm40b3_description/meshes/Holder_2.stl" scale="0.001 0.001 0.001"/>
    </geometry>
    <material name="darkgrey"/>
  </visual>
  <collision>
    <origin xyz="-1.514695 0.187374 0.0" rpy="0 0 0"/>
    <geometry>
      <mesh filename="package://ex_mm40b3_description/meshes/Holder_2.stl" scale="0.001 0.001 0.001"/>
    </geometry>
  </collision>
</link>

<link name="Holder_3">
  <inertial>
    <origin xyz="-0.1999999917328792 9.490924503385386e-11 -0.03608121241836992" rpy="0 0 0"/>
    <mass value="12.085489344125179"/>
    <inertia ixx="0.161772" iyy="0.69521" izz="0.836017" ixy="0.0" iyz="-0.0" ixz="0.0"/>
  </inertial>
  <visual>
    <origin xyz="-1.514695 0.0 0.187374" rpy="0 0 0"/>
    <geometry>
      <mesh filename="package://ex_mm40b3_description/meshes/Holder_3.stl" scale="0.001 0.001 0.001"/>
    </geometry>
    <material name="darkgrey"/>
  </visual>
  <collision>
    <origin xyz="-1.514695 0.0 0.187374" rpy="0 0 0"/>
    <geometry>
      <mesh filename="package://ex_mm40b3_description/meshes/Holder_3.stl" scale="0.001 0.001 0.001"/>
    </geometry>
  </collision>
</link>

<link name="Holder_4">
  <inertial>
    <origin xyz="-0.1999999917328792 0.03608121241836992 9.490923135116832e-11" rpy="0 0 0"/>
    <mass value="12.085489344125179"/>
    <inertia ixx="0.161772" iyy="0.836017" izz="0.69521" ixy="-0.0" iyz="-0.0" ixz="0.0"/>
  </inertial>
  <visual>
    <origin xyz="-1.514695 -0.187374 0.0" rpy="0 0 0"/>
    <geometry>
      <mesh filename="package://ex_mm40b3_description/meshes/Holder_4.stl" scale="0.001 0.001 0.001"/>
    </geometry>
    <material name="darkgrey"/>
  </visual>
  <collision>
    <origin xyz="-1.514695 -0.187374 0.0" rpy="0 0 0"/>
    <geometry>
      <mesh filename="package://ex_mm40b3_description/meshes/Holder_4.stl" scale="0.001 0.001 0.001"/>
    </geometry>
  </collision>
</link>

<link name="Fin_1">
  <inertial>
    <origin xyz="-0.015670038509134843 0.05105851518613127 -0.033157788278729644" rpy="0 0 0"/>
    <mass value="1.1914641784690367"/>
    <inertia ixx="0.003045" iyy="0.003419" izz="0.004631" ixy="0.000707" iyz="0.00136" ixz="-0.000459"/>
  </inertial>
  <visual>
    <origin xyz="1.561764 0.0 -0.235" rpy="0 0 0"/>
    <geometry>
      <mesh filename="package://ex_mm40b3_description/meshes/Fin_1.stl" scale="0.001 0.001 0.001"/>
    </geometry>
    <material name="orange"/>
  </visual>
  <collision>
    <origin xyz="1.561764 0.0 -0.235" rpy="0 0 0"/>
    <geometry>
      <mesh filename="package://ex_mm40b3_description/meshes/Fin_1.stl" scale="0.001 0.001 0.001"/>
    </geometry>
  </collision>
</link>

<link name="Fin_2">
  <inertial>
    <origin xyz="-0.015670038509135287 -0.03315778761916369 -0.05105880996392321" rpy="0 0 0"/>
    <mass value="1.1914641784690367"/>
    <inertia ixx="0.003045" iyy="0.004631" izz="0.003419" ixy="-0.000459" iyz="-0.00136" ixz="-0.000707"/>
  </inertial>
  <visual>
    <origin xyz="1.561764 -0.235 1.7e-05" rpy="0 0 0"/>
    <geometry>
      <mesh filename="package://ex_mm40b3_description/meshes/Fin_2.stl" scale="0.001 0.001 0.001"/>
    </geometry>
    <material name="orange"/>
  </visual>
  <collision>
    <origin xyz="1.561764 -0.235 1.7e-05" rpy="0 0 0"/>
    <geometry>
      <mesh filename="package://ex_mm40b3_description/meshes/Fin_2.stl" scale="0.001 0.001 0.001"/>
    </geometry>
  </collision>
</link>

<link name="Fin_3">
  <inertial>
    <origin xyz="-0.01567003850913551 -0.051058515375965514 0.033157786769763664" rpy="0 0 0"/>
    <mass value="1.1914641784690367"/>
    <inertia ixx="0.003045" iyy="0.003419" izz="0.004631" ixy="-0.000707" iyz="0.00136" ixz="0.000459"/>
  </inertial>
  <visual>
    <origin xyz="1.561764 0.0 0.235" rpy="0 0 0"/>
    <geometry>
      <mesh filename="package://ex_mm40b3_description/meshes/Fin_3.stl" scale="0.001 0.001 0.001"/>
    </geometry>
    <material name="orange"/>
  </visual>
  <collision>
    <origin xyz="1.561764 0.0 0.235" rpy="0 0 0"/>
    <geometry>
      <mesh filename="package://ex_mm40b3_description/meshes/Fin_3.stl" scale="0.001 0.001 0.001"/>
    </geometry>
  </collision>
</link>

<link name="Fin_4">
  <inertial>
    <origin xyz="-0.015670038509134843 0.03315778742932951 0.051058514526565395" rpy="0 0 0"/>
    <mass value="1.1914641784690367"/>
    <inertia ixx="0.003045" iyy="0.004631" izz="0.003419" ixy="0.000459" iyz="-0.00136" ixz="0.000707"/>
  </inertial>
  <visual>
    <origin xyz="1.561764 0.235 0.0" rpy="0 0 0"/>
    <geometry>
      <mesh filename="package://ex_mm40b3_description/meshes/Fin_4.stl" scale="0.001 0.001 0.001"/>
    </geometry>
    <material name="orange"/>
  </visual>
  <collision>
    <origin xyz="1.561764 0.235 0.0" rpy="0 0 0"/>
    <geometry>
      <mesh filename="package://ex_mm40b3_description/meshes/Fin_4.stl" scale="0.001 0.001 0.001"/>
    </geometry>
  </collision>
</link>

<joint name="fins_rev1" type="revolute">
  <origin xyz="-1.561764 0.0 0.18" rpy="0 0 0"/>
  <parent link="base_link"/>
  <child link="FinHolder_1"/>
  <axis xyz="-0.0 -0.0 1.0"/>
  <limit upper="0.349066" lower="-0.349066" effort="100" velocity="100"/>
</joint>

<joint name="fins_rev4" type="revolute">
  <origin xyz="-1.561764 -0.18 0.0" rpy="0 0 0"/>
  <parent link="base_link"/>
  <child link="FinHolder_4"/>
  <axis xyz="-0.0 -1.0 -0.0"/>
  <limit upper="0.349066" lower="-0.349066" effort="100" velocity="100"/>
</joint>

<joint name="fins_rev3" type="revolute">
  <origin xyz="-1.561764 0.0 -0.18" rpy="0 0 0"/>
  <parent link="base_link"/>
  <child link="FinHolder_3"/>
  <axis xyz="-0.0 0.0 -1.0"/>
  <limit upper="0.349066" lower="-0.349066" effort="100" velocity="100"/>
</joint>

<joint name="fins_rev2" type="revolute">
  <origin xyz="-1.561764 0.18 0.0" rpy="0 0 0"/>
  <parent link="base_link"/>
  <child link="FinHolder_2"/>
  <axis xyz="-0.0 1.0 0.0"/>
  <limit upper="0.349066" lower="-0.349066" effort="100" velocity="100"/>
</joint>

<joint name="wings_fold1" type="revolute">
  <origin xyz="-0.108536 0.0 0.231018" rpy="0 0 0"/>
  <parent link="base_link"/>
  <child link="Wing1_1"/>
  <axis xyz="1.0 -0.0 -0.0"/>
  <limit upper="2.146755" lower="0.0" effort="100" velocity="100"/>
</joint>

<joint name="booster_fixing" type="fixed">
  <origin xyz="-1.741776 0.0 0.0" rpy="0 0 0"/>
  <parent link="base_link"/>
  <child link="Booster_1"/>
</joint>

<joint name="wings_fold2" type="revolute">
  <origin xyz="-0.108536 0.231018 0.0" rpy="0 0 0"/>
  <parent link="base_link"/>
  <child link="Wing1_2"/>
  <axis xyz="1.0 0.0 -0.0"/>
  <limit upper="2.146755" lower="0.0" effort="100" velocity="100"/>
</joint>

<joint name="wings_fold3" type="revolute">
  <origin xyz="-0.108536 0.0 -0.231018" rpy="0 0 0"/>
  <parent link="base_link"/>
  <child link="Wing1_3"/>
  <axis xyz="1.0 0.0 -0.0"/>
  <limit upper="2.146755" lower="0.0" effort="100" velocity="100"/>
</joint>

<joint name="wings_fold4" type="revolute">
  <origin xyz="-0.108536 -0.231018 0.0" rpy="0 0 0"/>
  <parent link="base_link"/>
  <child link="Wing1_4"/>
  <axis xyz="1.0 -0.0 -0.0"/>
  <limit upper="2.146755" lower="0.0" effort="100" velocity="100"/>
</joint>

<joint name="HolderJoint1" type="fixed">
  <origin xyz="1.514695 0.0 0.187374" rpy="0 0 0"/>
  <parent link="base_link"/>
  <child link="Holder_1"/>
</joint>

<joint name="HolderJoint2" type="fixed">
  <origin xyz="1.514695 -0.187374 0.0" rpy="0 0 0"/>
  <parent link="base_link"/>
  <child link="Holder_2"/>
</joint>

<joint name="HolderJoint3" type="fixed">
  <origin xyz="1.514695 0.0 -0.187374" rpy="0 0 0"/>
  <parent link="base_link"/>
  <child link="Holder_3"/>
</joint>

<joint name="HolderJoint4" type="fixed">
  <origin xyz="1.514695 0.187374 0.0" rpy="0 0 0"/>
  <parent link="base_link"/>
  <child link="Holder_4"/>
</joint>

<joint name="fin_fold1" type="revolute">
  <origin xyz="0.0 0.0 0.055" rpy="0 0 0"/>
  <parent link="FinHolder_1"/>
  <child link="Fin_1"/>
  <axis xyz="1.0 -0.0 0.0"/>
  <limit upper="2.146755" lower="0.0" effort="100" velocity="100"/>
</joint>

<joint name="fin_fold2" type="revolute">
  <origin xyz="0.0 0.055 -1.7e-05" rpy="0 0 0"/>
  <parent link="FinHolder_2"/>
  <child link="Fin_2"/>
  <axis xyz="1.0 -0.0 -0.0"/>
  <limit upper="2.146755" lower="0.0" effort="100" velocity="100"/>
</joint>

<joint name="fin_fold3" type="revolute">
  <origin xyz="0.0 0.0 -0.055" rpy="0 0 0"/>
  <parent link="FinHolder_3"/>
  <child link="Fin_3"/>
  <axis xyz="1.0 -0.0 0.0"/>
  <limit upper="2.146755" lower="0.0" effort="100" velocity="100"/>
</joint>

<joint name="fin_fold4" type="revolute">
  <origin xyz="0.0 -0.055 0.0" rpy="0 0 0"/>
  <parent link="FinHolder_4"/>
  <child link="Fin_4"/>
  <axis xyz="1.0 -0.0 -0.0"/>
  <limit upper="2.146755" lower="0.0" effort="100" velocity="100"/>
</joint>

</robot>
