<?xml version="1.0" ?>
<!-- =================================================================================== -->
<!-- |    This document was autogenerated by xacro from src/ssm_models/mm40b3_description/urdf/mm40b3.xacro | -->
<!-- |    EDITING THIS FILE BY HAND IS NOT RECOMMENDED                                 | -->
<!-- =================================================================================== -->
<robot name="mm40b3">
  <material name="grey">
    <color rgba="0.82421875 0.82421875 0.82421875 1.0"/>
  </material>
  <material name="darkgrey">
    <color rgba="0.1843137254901961 0.30980392156862746 0.30980392156862746 1.000"/>
  </material>
  <material name="silver">
    <color rgba="0.700 0.700 0.700 1.000"/>
  </material>
  <material name="white">
    <color rgba="1 1 1 1"/>
  </material>
  <material name="orange">
    <color rgba="1 0.3 0.1 1"/>
  </material>
  <material name="blue">
    <color rgba="0.2 0.2 1 1"/>
  </material>
  <material name="red">
    <color rgba="0.8 0 0 1"/>
  </material>
  <material name="green">
    <color rgba="0.0 1 0.0 1"/>
  </material>
  <material name="black">
    <color rgba="0 0 0 1"/>
  </material>
  <transmission name="fins_rev1_tran">
    <type>transmission_interface/SimpleTransmission</type>
    <joint name="fins_rev1">
      <hardwareInterface>hardware_interface/EffortJointInterface</hardwareInterface>
    </joint>
    <actuator name="fins_rev1_actr">
      <hardwareInterface>hardware_interface/EffortJointInterface</hardwareInterface>
      <mechanicalReduction>1</mechanicalReduction>
    </actuator>
  </transmission>
  <transmission name="fins_rev4_tran">
    <type>transmission_interface/SimpleTransmission</type>
    <joint name="fins_rev4">
      <hardwareInterface>hardware_interface/EffortJointInterface</hardwareInterface>
    </joint>
    <actuator name="fins_rev4_actr">
      <hardwareInterface>hardware_interface/EffortJointInterface</hardwareInterface>
      <mechanicalReduction>1</mechanicalReduction>
    </actuator>
  </transmission>
  <transmission name="fins_rev3_tran">
    <type>transmission_interface/SimpleTransmission</type>
    <joint name="fins_rev3">
      <hardwareInterface>hardware_interface/EffortJointInterface</hardwareInterface>
    </joint>
    <actuator name="fins_rev3_actr">
      <hardwareInterface>hardware_interface/EffortJointInterface</hardwareInterface>
      <mechanicalReduction>1</mechanicalReduction>
    </actuator>
  </transmission>
  <transmission name="fins_rev2_tran">
    <type>transmission_interface/SimpleTransmission</type>
    <joint name="fins_rev2">
      <hardwareInterface>hardware_interface/EffortJointInterface</hardwareInterface>
    </joint>
    <actuator name="fins_rev2_actr">
      <hardwareInterface>hardware_interface/EffortJointInterface</hardwareInterface>
      <mechanicalReduction>1</mechanicalReduction>
    </actuator>
  </transmission>
  <transmission name="wings_fold1_tran">
    <type>transmission_interface/SimpleTransmission</type>
    <joint name="wings_fold1">
      <hardwareInterface>hardware_interface/EffortJointInterface</hardwareInterface>
    </joint>
    <actuator name="wings_fold1_actr">
      <hardwareInterface>hardware_interface/EffortJointInterface</hardwareInterface>
      <mechanicalReduction>1</mechanicalReduction>
    </actuator>
  </transmission>
  <transmission name="wings_fold2_tran">
    <type>transmission_interface/SimpleTransmission</type>
    <joint name="wings_fold2">
      <hardwareInterface>hardware_interface/EffortJointInterface</hardwareInterface>
    </joint>
    <actuator name="wings_fold2_actr">
      <hardwareInterface>hardware_interface/EffortJointInterface</hardwareInterface>
      <mechanicalReduction>1</mechanicalReduction>
    </actuator>
  </transmission>
  <transmission name="wings_fold3_tran">
    <type>transmission_interface/SimpleTransmission</type>
    <joint name="wings_fold3">
      <hardwareInterface>hardware_interface/EffortJointInterface</hardwareInterface>
    </joint>
    <actuator name="wings_fold3_actr">
      <hardwareInterface>hardware_interface/EffortJointInterface</hardwareInterface>
      <mechanicalReduction>1</mechanicalReduction>
    </actuator>
  </transmission>
  <transmission name="wings_fold4_tran">
    <type>transmission_interface/SimpleTransmission</type>
    <joint name="wings_fold4">
      <hardwareInterface>hardware_interface/EffortJointInterface</hardwareInterface>
    </joint>
    <actuator name="wings_fold4_actr">
      <hardwareInterface>hardware_interface/EffortJointInterface</hardwareInterface>
      <mechanicalReduction>1</mechanicalReduction>
    </actuator>
  </transmission>
  <transmission name="fin_fold1_tran">
    <type>transmission_interface/SimpleTransmission</type>
    <joint name="fin_fold1">
      <hardwareInterface>hardware_interface/EffortJointInterface</hardwareInterface>
    </joint>
    <actuator name="fin_fold1_actr">
      <hardwareInterface>hardware_interface/EffortJointInterface</hardwareInterface>
      <mechanicalReduction>1</mechanicalReduction>
    </actuator>
  </transmission>
  <transmission name="fin_fold2_tran">
    <type>transmission_interface/SimpleTransmission</type>
    <joint name="fin_fold2">
      <hardwareInterface>hardware_interface/EffortJointInterface</hardwareInterface>
    </joint>
    <actuator name="fin_fold2_actr">
      <hardwareInterface>hardware_interface/EffortJointInterface</hardwareInterface>
      <mechanicalReduction>1</mechanicalReduction>
    </actuator>
  </transmission>
  <transmission name="fin_fold3_tran">
    <type>transmission_interface/SimpleTransmission</type>
    <joint name="fin_fold3">
      <hardwareInterface>hardware_interface/EffortJointInterface</hardwareInterface>
    </joint>
    <actuator name="fin_fold3_actr">
      <hardwareInterface>hardware_interface/EffortJointInterface</hardwareInterface>
      <mechanicalReduction>1</mechanicalReduction>
    </actuator>
  </transmission>
  <transmission name="fin_fold4_tran">
    <type>transmission_interface/SimpleTransmission</type>
    <joint name="fin_fold4">
      <hardwareInterface>hardware_interface/EffortJointInterface</hardwareInterface>
    </joint>
    <actuator name="fin_fold4_actr">
      <hardwareInterface>hardware_interface/EffortJointInterface</hardwareInterface>
      <mechanicalReduction>1</mechanicalReduction>
    </actuator>
  </transmission>
  <gazebo>
    <plugin filename="libgazebo_ros_control.so" name="mm40b3_controller">
      <robotNamespace>mm40b3_controller</robotNamespace>
      <robotSimType>gazebo_ros_control/DefaultRobotHWSim</robotSimType>
    </plugin>
    <plugin filename="libSimpleThruster.so" name="BoosterThrust">
      <link_name>Booster_1</link_name>
      <forward_dir>1 0 0</forward_dir>
      <thrust_origin>-0.820 0 0</thrust_origin>
      <robotNamespace/>
      <topic_name>booster_visual</topic_name>
      <thrust_topic>booster_force</thrust_topic>
    </plugin>
    <plugin filename="libThrustVectoring.so" name="ThrustVectoring">
      <link_name>base_link</link_name>
      <forward_dir>1 0 0</forward_dir>
      <thrust_origin>-1.540 0 0</thrust_origin>
      <robotNamespace/>
      <topic_name>thrust_visual</topic_name>
      <vector_topic>thrust_force</vector_topic>
    </plugin>
    <plugin filename="libAerodynamic.so" name="FullBodyAerodynamic">
      <!-- <upward>0 0 1</upward> -->
      <cp>0.0 0.0 0.0</cp>
      <sref>0.096</sref>
      <lref>0.350</lref>
      <topic_name>AeroVectors</topic_name>
      <air_density>1.2041</air_density>
      <link_name>base_link</link_name>
      <robotNamespace/>
      <radial_symmetry>1/</radial_symmetry>
      <forward>1 0 0</forward>
    </plugin>
  </gazebo>
  <gazebo reference="base_link">
    <material>Gazebo/White</material>
    <mu1>0.2</mu1>
    <mu2>0.2</mu2>
    <selfCollide>true</selfCollide>
    <gravity>true</gravity>
    <visual>
      <plugin filename="libMultiplevectorVisual.so" name="LiftDragVisual">
        <topic_name vector_size="5">AeroVectors</topic_name>
      </plugin>
      <plugin filename="libForceVisual.so" name="VectoredThrustVisual">
        <topic_name>thrust_visual</topic_name>
        <color>Gazebo/Green</color>
      </plugin>
    </visual>
    <sensor name="camera_top_side" type="camera">
      <pose>-2.0 0.0 1.5 0.0 0.7854 0.0</pose>
      <!-- 3.1416 -->
      <camera>
        <!-- <horizontal_fov>1.347</horizontal_fov> -->
        <horizontal_fov>2</horizontal_fov>
        <image>
          <width>640</width>
          <height>480</height>
        </image>
        <clip>
          <near>0.1</near>
          <far>100</far>
        </clip>
      </camera>
      <always_on>1</always_on>
      <update_rate>30</update_rate>
      <!-- <visualize>true</visualize> -->
    </sensor>
    <sensor name="camera_right_side" type="camera">
      <pose>-0.0 -2.0 0.0 0.0 0.0 1.5708</pose>
      <!-- 3.1416 -->
      <camera>
        <!-- <horizontal_fov>1.347</horizontal_fov> -->
        <horizontal_fov>2</horizontal_fov>
        <image>
          <width>640</width>
          <height>480</height>
        </image>
        <clip>
          <near>0.1</near>
          <far>1000</far>
        </clip>
      </camera>
      <always_on>1</always_on>
      <update_rate>30</update_rate>
      <!-- <visualize>true</visualize> -->
    </sensor>
    <!-- <sensor name="camera_wide" type="camera">
    <pose>16 0 2.0 0 0.3 3.1416</pose>
    <camera>
      <horizontal_fov>2.0</horizontal_fov>
      <image>
        <width>640</width>
        <height>480</height>
      </image>
      <clip>
        <near>0.1</near>
        <far>1000</far>
      </clip>
    </camera>
    <always_on>1</always_on>
    <update_rate>30</update_rate>
    <visualize>true</visualize>
  </sensor>   -->
  </gazebo>
  <gazebo reference="FinHolder_1">
    <material>Gazebo/Blue</material>
    <mu1>0.2</mu1>
    <mu2>0.2</mu2>
    <selfCollide>true</selfCollide>
  </gazebo>
  <gazebo reference="FinHolder_4">
    <material>Gazebo/Blue</material>
    <mu1>0.2</mu1>
    <mu2>0.2</mu2>
    <selfCollide>true</selfCollide>
  </gazebo>
  <gazebo reference="FinHolder_3">
    <material>Gazebo/Blue</material>
    <mu1>0.2</mu1>
    <mu2>0.2</mu2>
    <selfCollide>true</selfCollide>
  </gazebo>
  <gazebo reference="FinHolder_2">
    <material>Gazebo/Blue</material>
    <mu1>0.2</mu1>
    <mu2>0.2</mu2>
    <selfCollide>true</selfCollide>
  </gazebo>
  <gazebo reference="Wing1_1">
    <material>Gazebo/Orange</material>
    <mu1>0.2</mu1>
    <mu2>0.2</mu2>
    <selfCollide>true</selfCollide>
  </gazebo>
  <gazebo reference="Booster_1">
    <material>Gazebo/Gray</material>
    <mu1>0.2</mu1>
    <mu2>0.2</mu2>
    <selfCollide>true</selfCollide>
    <visual>
      <plugin filename="libForceVisual.so" name="SimpleThrustVisual">
        <topic_name>booster_visual</topic_name>
        <color>Gazebo/Green</color>
      </plugin>
    </visual>
  </gazebo>
  <gazebo reference="Wing1_2">
    <material>Gazebo/Orange</material>
    <mu1>0.2</mu1>
    <mu2>0.2</mu2>
    <selfCollide>true</selfCollide>
  </gazebo>
  <gazebo reference="Wing1_3">
    <material>Gazebo/Orange</material>
    <mu1>0.2</mu1>
    <mu2>0.2</mu2>
    <selfCollide>true</selfCollide>
  </gazebo>
  <gazebo reference="Wing1_4">
    <material>Gazebo/Orange</material>
    <mu1>0.2</mu1>
    <mu2>0.2</mu2>
    <selfCollide>true</selfCollide>
  </gazebo>
  <gazebo reference="Holder_1">
    <material>Gazebo/Grey</material>
    <mu1>0.2</mu1>
    <mu2>0.2</mu2>
    <selfCollide>0</selfCollide>
  </gazebo>
  <gazebo reference="Holder_2">
    <material>Gazebo/Grey</material>
    <mu1>0.2</mu1>
    <mu2>0.2</mu2>
    <selfCollide>0</selfCollide>
  </gazebo>
  <gazebo reference="Holder_3">
    <material>Gazebo/Grey</material>
    <mu1>0.2</mu1>
    <mu2>0.2</mu2>
    <selfCollide>0</selfCollide>
  </gazebo>
  <gazebo reference="Holder_4">
    <material>Gazebo/Grey</material>
    <mu1>0.2</mu1>
    <mu2>0.2</mu2>
    <selfCollide>0</selfCollide>
  </gazebo>
  <gazebo reference="Fin_1">
    <material>Gazebo/Orange</material>
    <mu1>0.2</mu1>
    <mu2>0.2</mu2>
    <selfCollide>true</selfCollide>
  </gazebo>
  <gazebo reference="Fin_2">
    <material>Gazebo/Orange</material>
    <mu1>0.2</mu1>
    <mu2>0.2</mu2>
    <selfCollide>true</selfCollide>
  </gazebo>
  <gazebo reference="Fin_3">
    <material>Gazebo/Orange</material>
    <mu1>0.2</mu1>
    <mu2>0.2</mu2>
    <selfCollide>true</selfCollide>
  </gazebo>
  <gazebo reference="Fin_4">
    <material>Gazebo/Orange</material>
    <mu1>0.2</mu1>
    <mu2>0.2</mu2>
    <selfCollide>true</selfCollide>
  </gazebo>
  <gazebo reference="booster_fixing">
    <preserveFixedJoint>true</preserveFixedJoint>
  </gazebo>
  <gazebo reference="HolderJoint1">
    <preserveFixedJoint>true</preserveFixedJoint>
  </gazebo>
  <gazebo reference="HolderJoint2">
    <preserveFixedJoint>true</preserveFixedJoint>
  </gazebo>
  <gazebo reference="HolderJoint3">
    <preserveFixedJoint>true</preserveFixedJoint>
  </gazebo>
  <gazebo reference="HolderJoint4">
    <preserveFixedJoint>true</preserveFixedJoint>
  </gazebo>
  <link name="base_link">
    <inertial>
      <origin rpy="0 0 0" xyz="0.4387109641054164 -8.999584500533236e-06 -8.999321300238793e-06"/>
      <mass value="562.7679612503737"/>
      <inertia ixx="12.078708" ixy="0.0" ixz="0.0" iyy="817.09871" iyz="-0.0" izz="817.09871"/>
    </inertial>
    <visual>
      <origin rpy="0 0 0" xyz="0 0 0"/>
      <geometry>
        <mesh filename="package://mm40b3_description/meshes/base_link.stl" scale="0.001 0.001 0.001"/>
      </geometry>
      <material name="white"/>
    </visual>
    <collision>
      <origin rpy="0 0 0" xyz="0 0 0"/>
      <geometry>
        <mesh filename="package://mm40b3_description/meshes/base_link.stl" scale="0.001 0.001 0.001"/>
      </geometry>
    </collision>
  </link>
  <link name="FinHolder_1">
    <inertial>
      <origin rpy="0 0 0" xyz="0.011989934287455206 0.02489547078090079 0.02489052725207211"/>
      <mass value="0.6999999481439694"/>
      <inertia ixx="0.00025" ixy="3e-05" ixz="3e-05" iyy="0.004649" iyz="-9.8e-05" izz="0.004649"/>
    </inertial>
    <visual>
      <origin rpy="0 0 0" xyz="1.262133 -0.12727 -0.12727"/>
      <geometry>
        <mesh filename="package://mm40b3_description/meshes/FinHolder_1.stl" scale="0.001 0.001 0.001"/>
      </geometry>
      <material name="blue"/>
    </visual>
    <collision>
      <origin rpy="0 0 0" xyz="1.262133 -0.12727 -0.12727"/>
      <geometry>
        <mesh filename="package://mm40b3_description/meshes/FinHolder_1.stl" scale="0.001 0.001 0.001"/>
      </geometry>
    </collision>
  </link>
  <link name="FinHolder_4">
    <inertial>
      <origin rpy="0 0 0" xyz="0.011989934287455206 -0.024890526157868437 0.024895471044104445"/>
      <mass value="0.6999999481439694"/>
      <inertia ixx="0.00025" ixy="-3e-05" ixz="3e-05" iyy="0.004649" iyz="9.8e-05" izz="0.004649"/>
    </inertial>
    <visual>
      <origin rpy="0 0 0" xyz="1.262133 0.127288 -0.12727"/>
      <geometry>
        <mesh filename="package://mm40b3_description/meshes/FinHolder_4.stl" scale="0.001 0.001 0.001"/>
      </geometry>
      <material name="blue"/>
    </visual>
    <collision>
      <origin rpy="0 0 0" xyz="1.262133 0.127288 -0.12727"/>
      <geometry>
        <mesh filename="package://mm40b3_description/meshes/FinHolder_4.stl" scale="0.001 0.001 0.001"/>
      </geometry>
    </collision>
  </link>
  <link name="FinHolder_3">
    <inertial>
      <origin rpy="0 0 0" xyz="0.011989934287454318 -0.024895469949900717 -0.024890525894664756"/>
      <mass value="0.6999999481439694"/>
      <inertia ixx="0.00025" ixy="-3e-05" ixz="-3e-05" iyy="0.004649" iyz="-9.8e-05" izz="0.004649"/>
    </inertial>
    <visual>
      <origin rpy="0 0 0" xyz="1.262133 0.127288 0.127288"/>
      <geometry>
        <mesh filename="package://mm40b3_description/meshes/FinHolder_3.stl" scale="0.001 0.001 0.001"/>
      </geometry>
      <material name="blue"/>
    </visual>
    <collision>
      <origin rpy="0 0 0" xyz="1.262133 0.127288 0.127288"/>
      <geometry>
        <mesh filename="package://mm40b3_description/meshes/FinHolder_3.stl" scale="0.001 0.001 0.001"/>
      </geometry>
    </collision>
  </link>
  <link name="FinHolder_2">
    <inertial>
      <origin rpy="0 0 0" xyz="0.011989934287454318 0.024890526988868455 -0.02489546968669709"/>
      <mass value="0.6999999481439694"/>
      <inertia ixx="0.00025" ixy="3e-05" ixz="-3e-05" iyy="0.004649" iyz="9.8e-05" izz="0.004649"/>
    </inertial>
    <visual>
      <origin rpy="0 0 0" xyz="1.262133 -0.12727 0.127288"/>
      <geometry>
        <mesh filename="package://mm40b3_description/meshes/FinHolder_2.stl" scale="0.001 0.001 0.001"/>
      </geometry>
      <material name="blue"/>
    </visual>
    <collision>
      <origin rpy="0 0 0" xyz="1.262133 -0.12727 0.127288"/>
      <geometry>
        <mesh filename="package://mm40b3_description/meshes/FinHolder_2.stl" scale="0.001 0.001 0.001"/>
      </geometry>
    </collision>
  </link>
  <link name="Wing1_1">
    <inertial>
      <origin rpy="0 0 0" xyz="-0.03120809779189968 0.02095895116205243 -0.0986058785075822"/>
      <mass value="9.299979574219174"/>
      <inertia ixx="0.055746" ixy="0.003624" ixz="-0.017051" iyy="0.442635" iyz="0.011218" izz="0.392244"/>
    </inertial>
    <visual>
      <origin rpy="0 0 0" xyz="-0.057855 -0.163346 -0.163346"/>
      <geometry>
        <mesh filename="package://mm40b3_description/meshes/Wing1_1.stl" scale="0.001 0.001 0.001"/>
      </geometry>
      <material name="orange"/>
    </visual>
    <collision>
      <origin rpy="0 0 0" xyz="-0.057855 -0.163346 -0.163346"/>
      <geometry>
        <mesh filename="package://mm40b3_description/meshes/Wing1_1.stl" scale="0.001 0.001 0.001"/>
      </geometry>
    </collision>
  </link>
  <link name="Booster_1">
    <inertial>
      <origin rpy="0 0 0" xyz="-0.530558737878678 4.101072758561376e-09 -2.4372112422003445e-10"/>
      <mass value="120.00001114591107"/>
      <inertia ixx="5.768641" ixy="-0.0" ixz="0.0" iyy="16.618567" iyz="-0.0" izz="16.618567"/>
    </inertial>
    <visual>
      <origin rpy="0 0 0" xyz="1.442145 9e-06 9e-06"/>
      <geometry>
        <mesh filename="package://mm40b3_description/meshes/Booster_1.stl" scale="0.001 0.001 0.001"/>
      </geometry>
      <material name="grey"/>
    </visual>
    <collision>
      <origin rpy="0 0 0" xyz="1.442145 9e-06 9e-06"/>
      <geometry>
        <mesh filename="package://mm40b3_description/meshes/Booster_1.stl" scale="0.001 0.001 0.001"/>
      </geometry>
    </collision>
  </link>
  <link name="Wing1_2">
    <inertial>
      <origin rpy="0 0 0" xyz="-0.031208097791900133 -0.09762773117005005 -0.020751038377032932"/>
      <mass value="9.299979574219174"/>
      <inertia ixx="0.055746" ixy="-0.017051" ixz="-0.003624" iyy="0.392244" iyz="-0.011218" izz="0.442635"/>
    </inertial>
    <visual>
      <origin rpy="0 0 0" xyz="-0.057855 -0.163346 0.163364"/>
      <geometry>
        <mesh filename="package://mm40b3_description/meshes/Wing1_2.stl" scale="0.001 0.001 0.001"/>
      </geometry>
      <material name="orange"/>
    </visual>
    <collision>
      <origin rpy="0 0 0" xyz="-0.057855 -0.163346 0.163364"/>
      <geometry>
        <mesh filename="package://mm40b3_description/meshes/Wing1_2.stl" scale="0.001 0.001 0.001"/>
      </geometry>
    </collision>
  </link>
  <link name="Wing1_3">
    <inertial>
      <origin rpy="0 0 0" xyz="-0.031208097791899873 -0.020751038640234615 0.09762773226425157"/>
      <mass value="9.299979574219174"/>
      <inertia ixx="0.055746" ixy="-0.003624" ixz="0.017051" iyy="0.442635" iyz="0.011218" izz="0.392244"/>
    </inertial>
    <visual>
      <origin rpy="0 0 0" xyz="-0.057855 0.163364 0.163364"/>
      <geometry>
        <mesh filename="package://mm40b3_description/meshes/Wing1_3.stl" scale="0.001 0.001 0.001"/>
      </geometry>
      <material name="orange"/>
    </visual>
    <collision>
      <origin rpy="0 0 0" xyz="-0.057855 0.163364 0.163364"/>
      <geometry>
        <mesh filename="package://mm40b3_description/meshes/Wing1_3.stl" scale="0.001 0.001 0.001"/>
      </geometry>
    </collision>
  </link>
  <link name="Wing1_4">
    <inertial>
      <origin rpy="0 0 0" xyz="-0.031208097791899553 0.09762773200104996 0.020751039734436066"/>
      <mass value="9.299979574219174"/>
      <inertia ixx="0.055746" ixy="0.017051" ixz="0.003624" iyy="0.392244" iyz="-0.011218" izz="0.442635"/>
    </inertial>
    <visual>
      <origin rpy="0 0 0" xyz="-0.057855 0.163364 -0.163346"/>
      <geometry>
        <mesh filename="package://mm40b3_description/meshes/Wing1_4.stl" scale="0.001 0.001 0.001"/>
      </geometry>
      <material name="orange"/>
    </visual>
    <collision>
      <origin rpy="0 0 0" xyz="-0.057855 0.163364 -0.163346"/>
      <geometry>
        <mesh filename="package://mm40b3_description/meshes/Wing1_4.stl" scale="0.001 0.001 0.001"/>
      </geometry>
    </collision>
  </link>
  <link name="Holder_1">
    <inertial>
      <origin rpy="0 0 0" xyz="-0.19999999173289051 0.02523252069763124 0.025232520960823845"/>
      <mass value="13.50000107858645"/>
      <inertia ixx="0.184494" ixy="-0.0" ixz="-0.0" iyy="0.864601" iyz="0.079825" izz="0.864601"/>
    </inertial>
    <visual>
      <origin rpy="0 0 0" xyz="-1.814326 -0.132484 -0.132484"/>
      <geometry>
        <mesh filename="package://mm40b3_description/meshes/Holder_1.stl" scale="0.001 0.001 0.001"/>
      </geometry>
      <material name="darkgrey"/>
    </visual>
    <collision>
      <origin rpy="0 0 0" xyz="-1.814326 -0.132484 -0.132484"/>
      <geometry>
        <mesh filename="package://mm40b3_description/meshes/Holder_1.stl" scale="0.001 0.001 0.001"/>
      </geometry>
    </collision>
  </link>
  <link name="Holder_2">
    <inertial>
      <origin rpy="0 0 0" xyz="-0.19999999173289051 -0.025232519866623837 0.02523252096083123"/>
      <mass value="13.50000107858645"/>
      <inertia ixx="0.184494" ixy="0.0" ixz="-0.0" iyy="0.864601" iyz="-0.079825" izz="0.864601"/>
    </inertial>
    <visual>
      <origin rpy="0 0 0" xyz="-1.814326 0.132502 -0.132484"/>
      <geometry>
        <mesh filename="package://mm40b3_description/meshes/Holder_2.stl" scale="0.001 0.001 0.001"/>
      </geometry>
      <material name="darkgrey"/>
    </visual>
    <collision>
      <origin rpy="0 0 0" xyz="-1.814326 0.132502 -0.132484"/>
      <geometry>
        <mesh filename="package://mm40b3_description/meshes/Holder_2.stl" scale="0.001 0.001 0.001"/>
      </geometry>
    </collision>
  </link>
  <link name="Holder_3">
    <inertial>
      <origin rpy="0 0 0" xyz="-0.19999999173289051 -0.025232519866631248 -0.025232519603423792"/>
      <mass value="13.50000107858645"/>
      <inertia ixx="0.184494" ixy="0.0" ixz="0.0" iyy="0.864601" iyz="0.079825" izz="0.864601"/>
    </inertial>
    <visual>
      <origin rpy="0 0 0" xyz="-1.814326 0.132502 0.132502"/>
      <geometry>
        <mesh filename="package://mm40b3_description/meshes/Holder_3.stl" scale="0.001 0.001 0.001"/>
      </geometry>
      <material name="darkgrey"/>
    </visual>
    <collision>
      <origin rpy="0 0 0" xyz="-1.814326 0.132502 0.132502"/>
      <geometry>
        <mesh filename="package://mm40b3_description/meshes/Holder_3.stl" scale="0.001 0.001 0.001"/>
      </geometry>
    </collision>
  </link>
  <link name="Holder_4">
    <inertial>
      <origin rpy="0 0 0" xyz="-0.19999999173289051 0.0252325206976238 -0.02523251960343123"/>
      <mass value="13.50000107858645"/>
      <inertia ixx="0.184494" ixy="-0.0" ixz="0.0" iyy="0.864601" iyz="-0.079825" izz="0.864601"/>
    </inertial>
    <visual>
      <origin rpy="0 0 0" xyz="-1.814326 -0.132484 0.132502"/>
      <geometry>
        <mesh filename="package://mm40b3_description/meshes/Holder_4.stl" scale="0.001 0.001 0.001"/>
      </geometry>
      <material name="darkgrey"/>
    </visual>
    <collision>
      <origin rpy="0 0 0" xyz="-1.814326 -0.132484 0.132502"/>
      <geometry>
        <mesh filename="package://mm40b3_description/meshes/Holder_4.stl" scale="0.001 0.001 0.001"/>
      </geometry>
    </collision>
  </link>
  <link name="Fin_1">
    <inertial>
      <origin rpy="0 0 0" xyz="-0.014318287010841813 0.018052617673020382 -0.08493035219325562"/>
      <mass value="1.500000007859579"/>
      <inertia ixx="0.006929" ixy="0.000264" ixz="-0.001243" iyy="0.010397" iyz="0.001396" izz="0.004127"/>
    </inertial>
    <visual>
      <origin rpy="0 0 0" xyz="1.262133 -0.166161 -0.166161"/>
      <geometry>
        <mesh filename="package://mm40b3_description/meshes/Fin_1.stl" scale="0.001 0.001 0.001"/>
      </geometry>
      <material name="orange"/>
    </visual>
    <collision>
      <origin rpy="0 0 0" xyz="1.262133 -0.166161 -0.166161"/>
      <geometry>
        <mesh filename="package://mm40b3_description/meshes/Fin_1.stl" scale="0.001 0.001 0.001"/>
      </geometry>
    </collision>
  </link>
  <link name="Fin_2">
    <inertial>
      <origin rpy="0 0 0" xyz="-0.014318287010842479 -0.08493058111049845 -0.018052845232855996"/>
      <mass value="1.500000007859579"/>
      <inertia ixx="0.006929" ixy="-0.001243" ixz="-0.000264" iyy="0.004127" iyz="-0.001396" izz="0.010397"/>
    </inertial>
    <visual>
      <origin rpy="0 0 0" xyz="1.262133 -0.166149 0.166191"/>
      <geometry>
        <mesh filename="package://mm40b3_description/meshes/Fin_2.stl" scale="0.001 0.001 0.001"/>
      </geometry>
      <material name="orange"/>
    </visual>
    <collision>
      <origin rpy="0 0 0" xyz="1.262133 -0.166149 0.166191"/>
      <geometry>
        <mesh filename="package://mm40b3_description/meshes/Fin_2.stl" scale="0.001 0.001 0.001"/>
      </geometry>
    </collision>
  </link>
  <link name="Fin_3">
    <inertial>
      <origin rpy="0 0 0" xyz="-0.014318287010841813 -0.018052616842020475 0.08493035355066292"/>
      <mass value="1.500000007859579"/>
      <inertia ixx="0.006929" ixy="-0.000264" ixz="0.001243" iyy="0.010397" iyz="0.001396" izz="0.004127"/>
    </inertial>
    <visual>
      <origin rpy="0 0 0" xyz="1.262133 0.166179 0.166179"/>
      <geometry>
        <mesh filename="package://mm40b3_description/meshes/Fin_3.stl" scale="0.001 0.001 0.001"/>
      </geometry>
      <material name="orange"/>
    </visual>
    <collision>
      <origin rpy="0 0 0" xyz="1.262133 0.166179 0.166179"/>
      <geometry>
        <mesh filename="package://mm40b3_description/meshes/Fin_3.stl" scale="0.001 0.001 0.001"/>
      </geometry>
    </collision>
  </link>
  <link name="Fin_4">
    <inertial>
      <origin rpy="0 0 0" xyz="-0.014318287010842257 0.0849303532874592 0.018052617936223952"/>
      <mass value="1.500000007859579"/>
      <inertia ixx="0.006929" ixy="0.001243" ixz="0.000264" iyy="0.004127" iyz="-0.001396" izz="0.010397"/>
    </inertial>
    <visual>
      <origin rpy="0 0 0" xyz="1.262133 0.166179 -0.166161"/>
      <geometry>
        <mesh filename="package://mm40b3_description/meshes/Fin_4.stl" scale="0.001 0.001 0.001"/>
      </geometry>
      <material name="orange"/>
    </visual>
    <collision>
      <origin rpy="0 0 0" xyz="1.262133 0.166179 -0.166161"/>
      <geometry>
        <mesh filename="package://mm40b3_description/meshes/Fin_4.stl" scale="0.001 0.001 0.001"/>
      </geometry>
    </collision>
  </link>
  <joint name="fins_rev1" type="revolute">
    <origin rpy="0 0 0" xyz="-1.262133 0.12727 0.12727"/>
    <parent link="base_link"/>
    <child link="FinHolder_1"/>
    <axis xyz="-0.0 0.707107 0.707107"/>
    <limit effort="100" lower="-0.349066" upper="0.349066" velocity="100"/>
  </joint>
  <joint name="fins_rev4" type="revolute">
    <origin rpy="0 0 0" xyz="-1.262133 -0.127288 0.12727"/>
    <parent link="base_link"/>
    <child link="FinHolder_4"/>
    <axis xyz="-0.0 -0.707107 0.707107"/>
    <limit effort="100" lower="-0.349066" upper="0.349066" velocity="100"/>
  </joint>
  <joint name="fins_rev3" type="revolute">
    <origin rpy="0 0 0" xyz="-1.262133 -0.127288 -0.127288"/>
    <parent link="base_link"/>
    <child link="FinHolder_3"/>
    <axis xyz="-0.0 -0.707107 -0.707107"/>
    <limit effort="100" lower="-0.349066" upper="0.349066" velocity="100"/>
  </joint>
  <joint name="fins_rev2" type="revolute">
    <origin rpy="0 0 0" xyz="-1.262133 0.12727 -0.127288"/>
    <parent link="base_link"/>
    <child link="FinHolder_2"/>
    <axis xyz="-0.0 0.707107 -0.707107"/>
    <limit effort="100" lower="-0.349066" upper="0.349066" velocity="100"/>
  </joint>
  <joint name="wings_fold1" type="revolute">
    <origin rpy="0 0 0" xyz="0.057855 0.163346 0.163346"/>
    <parent link="base_link"/>
    <child link="Wing1_1"/>
    <axis xyz="1.0 -0.0 -0.0"/>
    <limit effort="100" lower="0.0" upper="2.146755" velocity="100"/>
  </joint>
  <joint name="booster_fixing" type="fixed">
    <origin rpy="0 0 0" xyz="-1.442145 -9e-06 -9e-06"/>
    <parent link="base_link"/>
    <child link="Booster_1"/>
  </joint>
  <joint name="wings_fold2" type="revolute">
    <origin rpy="0 0 0" xyz="0.057855 0.163346 -0.163364"/>
    <parent link="base_link"/>
    <child link="Wing1_2"/>
    <axis xyz="1.0 0.0 -0.0"/>
    <limit effort="100" lower="0.0" upper="2.146755" velocity="100"/>
  </joint>
  <joint name="wings_fold3" type="revolute">
    <origin rpy="0 0 0" xyz="0.057855 -0.163364 -0.163364"/>
    <parent link="base_link"/>
    <child link="Wing1_3"/>
    <axis xyz="1.0 0.0 -0.0"/>
    <limit effort="100" lower="0.0" upper="2.146755" velocity="100"/>
  </joint>
  <joint name="wings_fold4" type="revolute">
    <origin rpy="0 0 0" xyz="0.057855 -0.163364 0.163346"/>
    <parent link="base_link"/>
    <child link="Wing1_4"/>
    <axis xyz="1.0 -0.0 -0.0"/>
    <limit effort="100" lower="0.0" upper="2.146755" velocity="100"/>
  </joint>
  <joint name="HolderJoint1" type="fixed">
    <origin rpy="0 0 0" xyz="1.814326 0.132484 0.132484"/>
    <parent link="base_link"/>
    <child link="Holder_1"/>
  </joint>
  <joint name="HolderJoint2" type="fixed">
    <origin rpy="0 0 0" xyz="1.814326 -0.132502 0.132484"/>
    <parent link="base_link"/>
    <child link="Holder_2"/>
  </joint>
  <joint name="HolderJoint3" type="fixed">
    <origin rpy="0 0 0" xyz="1.814326 -0.132502 -0.132502"/>
    <parent link="base_link"/>
    <child link="Holder_3"/>
  </joint>
  <joint name="HolderJoint4" type="fixed">
    <origin rpy="0 0 0" xyz="1.814326 0.132484 -0.132502"/>
    <parent link="base_link"/>
    <child link="Holder_4"/>
  </joint>
  <joint name="fin_fold1" type="revolute">
    <origin rpy="0 0 0" xyz="0.0 0.038891 0.038891"/>
    <parent link="FinHolder_1"/>
    <child link="Fin_1"/>
    <axis xyz="1.0 0.0 0.0"/>
    <limit effort="100" lower="0.0" upper="2.146755" velocity="100"/>
  </joint>
  <joint name="fin_fold2" type="revolute">
    <origin rpy="0 0 0" xyz="0.0 0.038879 -0.038903"/>
    <parent link="FinHolder_2"/>
    <child link="Fin_2"/>
    <axis xyz="1.0 0.0 -0.0"/>
    <limit effort="100" lower="0.0" upper="2.146755" velocity="100"/>
  </joint>
  <joint name="fin_fold3" type="revolute">
    <origin rpy="0 0 0" xyz="0.0 -0.038891 -0.038891"/>
    <parent link="FinHolder_3"/>
    <child link="Fin_3"/>
    <axis xyz="1.0 -0.0 -0.0"/>
    <limit effort="100" lower="0.0" upper="2.146755" velocity="100"/>
  </joint>
  <joint name="fin_fold4" type="revolute">
    <origin rpy="0 0 0" xyz="0.0 -0.038891 0.038891"/>
    <parent link="FinHolder_4"/>
    <child link="Fin_4"/>
    <axis xyz="1.0 -0.0 -0.0"/>
    <limit effort="100" lower="0.0" upper="2.146755" velocity="100"/>
  </joint>
</robot>

