<sdf version='1.7'>
  <model name='ex_mm40b3'>
    <link name='base_link'>
      <inertial>
        <pose>0.558219 -0 -0 0 -0 0</pose>
        <mass>564.97</mass>
        <inertia>
          <ixx>13.5604</ixx>
          <ixy>0</ixy>
          <ixz>0</ixz>
          <iyy>1088.29</iyy>
          <iyz>0</iyz>
          <izz>1088.29</izz>
        </inertia>
      </inertial>
      <collision name='base_link_collision'>
        <pose>0 0 0 0 -0 0</pose>
        <geometry>
          <mesh>
            <scale>0.001 0.001 0.001</scale>
            <uri>model://ex_mm40b3_description/meshes/base_link.stl</uri>
          </mesh>
        </geometry>
        <surface>
          <contact>
            <ode/>
          </contact>
          <friction>
            <ode>
              <mu>0.2</mu>
              <mu2>0.2</mu2>
            </ode>
          </friction>
        </surface>
      </collision>
      <visual name='base_link_visual'>
        <pose>0 0 0 0 -0 0</pose>
        <geometry>
          <mesh>
            <scale>0.001 0.001 0.001</scale>
            <uri>model://ex_mm40b3_description/meshes/base_link.stl</uri>
          </mesh>
        </geometry>
        <material>
          <script>
            <name>Gazebo/White</name>
            <uri>file://media/materials/scripts/gazebo.material</uri>
          </script>
        </material>
      </visual>
      <self_collide>1</self_collide>
      <gravity>1</gravity>
    </link>
    <joint name='HolderJoint1' type='fixed'>
      <pose relative_to='base_link'>1.51469 0 0.187374 0 -0 0</pose>
      <parent>base_link</parent>
      <child>Holder_1</child>
      <axis>
        <dynamics>
          <spring_reference>0</spring_reference>
          <spring_stiffness>0</spring_stiffness>
        </dynamics>
        <xyz>0 0 1</xyz>
        <limit>
          <lower>-1e+16</lower>
          <upper>1e+16</upper>
        </limit>
      </axis>
      <physics>
        <ode>
          <limit>
            <cfm>0</cfm>
            <erp>0.2</erp>
          </limit>
        </ode>
      </physics>
    </joint>
    <link name='Holder_1'>
      <pose relative_to='HolderJoint1'>0 0 0 0 -0 0</pose>
      <inertial>
        <pose>-0.2 -0 0.036081 0 -0 0</pose>
        <mass>12.0855</mass>
        <inertia>
          <ixx>0.161772</ixx>
          <ixy>0</ixy>
          <ixz>0</ixz>
          <iyy>0.69521</iyy>
          <iyz>0</iyz>
          <izz>0.836017</izz>
        </inertia>
      </inertial>
      <collision name='Holder_1_collision'>
        <pose>-1.51469 0 -0.187374 0 -0 0</pose>
        <geometry>
          <mesh>
            <scale>0.001 0.001 0.001</scale>
            <uri>model://ex_mm40b3_description/meshes/Holder_1.stl</uri>
          </mesh>
        </geometry>
        <surface>
          <contact>
            <ode/>
          </contact>
          <friction>
            <ode>
              <mu>0.2</mu>
              <mu2>0.2</mu2>
            </ode>
          </friction>
        </surface>
      </collision>
      <visual name='Holder_1_visual'>
        <pose>-1.51469 0 -0.187374 0 -0 0</pose>
        <geometry>
          <mesh>
            <scale>0.001 0.001 0.001</scale>
            <uri>model://ex_mm40b3_description/meshes/Holder_1.stl</uri>
          </mesh>
        </geometry>
        <material>
          <script>
            <name>Gazebo/Grey</name>
            <uri>file://media/materials/scripts/gazebo.material</uri>
          </script>
        </material>
      </visual>
      <self_collide>1</self_collide>
    </link>
    <joint name='HolderJoint2' type='fixed'>
      <pose relative_to='base_link'>1.51469 -0.187374 0 0 -0 0</pose>
      <parent>base_link</parent>
      <child>Holder_2</child>
      <axis>
        <dynamics>
          <spring_reference>0</spring_reference>
          <spring_stiffness>0</spring_stiffness>
        </dynamics>
        <xyz>0 0 1</xyz>
        <limit>
          <lower>-1e+16</lower>
          <upper>1e+16</upper>
        </limit>
      </axis>
      <physics>
        <ode>
          <limit>
            <cfm>0</cfm>
            <erp>0.2</erp>
          </limit>
        </ode>
      </physics>
    </joint>
    <link name='Holder_2'>
      <pose relative_to='HolderJoint2'>0 0 0 0 -0 0</pose>
      <inertial>
        <pose>-0.2 -0.036081 -0 0 -0 0</pose>
        <mass>12.0855</mass>
        <inertia>
          <ixx>0.161772</ixx>
          <ixy>0</ixy>
          <ixz>0</ixz>
          <iyy>0.836017</iyy>
          <iyz>0</iyz>
          <izz>0.69521</izz>
        </inertia>
      </inertial>
      <collision name='Holder_2_collision'>
        <pose>-1.51469 0.187374 0 0 -0 0</pose>
        <geometry>
          <mesh>
            <scale>0.001 0.001 0.001</scale>
            <uri>model://ex_mm40b3_description/meshes/Holder_2.stl</uri>
          </mesh>
        </geometry>
        <surface>
          <contact>
            <ode/>
          </contact>
          <friction>
            <ode>
              <mu>0.2</mu>
              <mu2>0.2</mu2>
            </ode>
          </friction>
        </surface>
      </collision>
      <visual name='Holder_2_visual'>
        <pose>-1.51469 0.187374 0 0 -0 0</pose>
        <geometry>
          <mesh>
            <scale>0.001 0.001 0.001</scale>
            <uri>model://ex_mm40b3_description/meshes/Holder_2.stl</uri>
          </mesh>
        </geometry>
        <material>
          <script>
            <name>Gazebo/Grey</name>
            <uri>file://media/materials/scripts/gazebo.material</uri>
          </script>
        </material>
      </visual>
      <self_collide>1</self_collide>
    </link>
    <joint name='HolderJoint3' type='fixed'>
      <pose relative_to='base_link'>1.51469 0 -0.187374 0 -0 0</pose>
      <parent>base_link</parent>
      <child>Holder_3</child>
      <axis>
        <dynamics>
          <spring_reference>0</spring_reference>
          <spring_stiffness>0</spring_stiffness>
        </dynamics>
        <xyz>0 0 1</xyz>
        <limit>
          <lower>-1e+16</lower>
          <upper>1e+16</upper>
        </limit>
      </axis>
      <physics>
        <ode>
          <limit>
            <cfm>0</cfm>
            <erp>0.2</erp>
          </limit>
        </ode>
      </physics>
    </joint>
    <link name='Holder_3'>
      <pose relative_to='HolderJoint3'>0 0 0 0 -0 0</pose>
      <inertial>
        <pose>-0.2 0 -0.036081 0 -0 0</pose>
        <mass>12.0855</mass>
        <inertia>
          <ixx>0.161772</ixx>
          <ixy>0</ixy>
          <ixz>0</ixz>
          <iyy>0.69521</iyy>
          <iyz>0</iyz>
          <izz>0.836017</izz>
        </inertia>
      </inertial>
      <collision name='Holder_3_collision'>
        <pose>-1.51469 0 0.187374 0 -0 0</pose>
        <geometry>
          <mesh>
            <scale>0.001 0.001 0.001</scale>
            <uri>model://ex_mm40b3_description/meshes/Holder_3.stl</uri>
          </mesh>
        </geometry>
        <surface>
          <contact>
            <ode/>
          </contact>
          <friction>
            <ode>
              <mu>0.2</mu>
              <mu2>0.2</mu2>
            </ode>
          </friction>
        </surface>
      </collision>
      <visual name='Holder_3_visual'>
        <pose>-1.51469 0 0.187374 0 -0 0</pose>
        <geometry>
          <mesh>
            <scale>0.001 0.001 0.001</scale>
            <uri>model://ex_mm40b3_description/meshes/Holder_3.stl</uri>
          </mesh>
        </geometry>
        <material>
          <script>
            <name>Gazebo/Grey</name>
            <uri>file://media/materials/scripts/gazebo.material</uri>
          </script>
        </material>
      </visual>
      <self_collide>1</self_collide>
    </link>
    <joint name='HolderJoint4' type='fixed'>
      <pose relative_to='base_link'>1.51469 0.187374 0 0 -0 0</pose>
      <parent>base_link</parent>
      <child>Holder_4</child>
      <axis>
        <dynamics>
          <spring_reference>0</spring_reference>
          <spring_stiffness>0</spring_stiffness>
        </dynamics>
        <xyz>0 0 1</xyz>
        <limit>
          <lower>-1e+16</lower>
          <upper>1e+16</upper>
        </limit>
      </axis>
      <physics>
        <ode>
          <limit>
            <cfm>0</cfm>
            <erp>0.2</erp>
          </limit>
        </ode>
      </physics>
    </joint>
    <link name='Holder_4'>
      <pose relative_to='HolderJoint4'>0 0 0 0 -0 0</pose>
      <inertial>
        <pose>-0.2 0.036081 0 0 -0 0</pose>
        <mass>12.0855</mass>
        <inertia>
          <ixx>0.161772</ixx>
          <ixy>0</ixy>
          <ixz>0</ixz>
          <iyy>0.836017</iyy>
          <iyz>0</iyz>
          <izz>0.69521</izz>
        </inertia>
      </inertial>
      <collision name='Holder_4_collision'>
        <pose>-1.51469 -0.187374 0 0 -0 0</pose>
        <geometry>
          <mesh>
            <scale>0.001 0.001 0.001</scale>
            <uri>model://ex_mm40b3_description/meshes/Holder_4.stl</uri>
          </mesh>
        </geometry>
        <surface>
          <contact>
            <ode/>
          </contact>
          <friction>
            <ode>
              <mu>0.2</mu>
              <mu2>0.2</mu2>
            </ode>
          </friction>
        </surface>
      </collision>
      <visual name='Holder_4_visual'>
        <pose>-1.51469 -0.187374 0 0 -0 0</pose>
        <geometry>
          <mesh>
            <scale>0.001 0.001 0.001</scale>
            <uri>model://ex_mm40b3_description/meshes/Holder_4.stl</uri>
          </mesh>
        </geometry>
        <material>
          <script>
            <name>Gazebo/Grey</name>
            <uri>file://media/materials/scripts/gazebo.material</uri>
          </script>
        </material>
      </visual>
      <self_collide>1</self_collide>
    </link>
    <joint name='booster_fixing' type='fixed'>
      <pose relative_to='base_link'>-1.74178 0 0 0 -0 0</pose>
      <parent>base_link</parent>
      <child>Booster_1</child>
      <axis>
        <dynamics>
          <spring_reference>0</spring_reference>
          <spring_stiffness>0</spring_stiffness>
        </dynamics>
        <xyz>0 0 1</xyz>
        <limit>
          <lower>-1e+16</lower>
          <upper>1e+16</upper>
        </limit>
      </axis>
      <physics>
        <ode>
          <limit>
            <cfm>0</cfm>
            <erp>0.2</erp>
          </limit>
        </ode>
      </physics>
    </joint>
    <link name='Booster_1'>
      <pose relative_to='booster_fixing'>0 0 0 0 -0 0</pose>
      <inertial>
        <pose>-0.530988 0 0 0 -0 0</pose>
        <mass>138.763</mass>
        <inertia>
          <ixx>6.06454</ixx>
          <ixy>0</ixy>
          <ixz>0</ixz>
          <iyy>17.4505</iyy>
          <iyz>0</iyz>
          <izz>17.4505</izz>
        </inertia>
      </inertial>
      <collision name='Booster_1_collision'>
        <pose>1.74178 0 0 0 -0 0</pose>
        <geometry>
          <mesh>
            <scale>0.001 0.001 0.001</scale>
            <uri>model://ex_mm40b3_description/meshes/Booster_1.stl</uri>
          </mesh>
        </geometry>
        <surface>
          <contact>
            <ode/>
          </contact>
          <friction>
            <ode>
              <mu>0.2</mu>
              <mu2>0.2</mu2>
            </ode>
          </friction>
        </surface>
      </collision>
      <visual name='Booster_1_visual'>
        <pose>1.74178 0 0 0 -0 0</pose>
        <geometry>
          <mesh>
            <scale>0.001 0.001 0.001</scale>
            <uri>model://ex_mm40b3_description/meshes/Booster_1.stl</uri>
          </mesh>
        </geometry>
        <plugin name='SimpleThrustVisual' filename='libForceVisual.so'>
          <topic_name>booster_visual</topic_name>
          <color>Gazebo/Red</color>
        </plugin>
        <material>
          <script>
            <name>Gazebo/Gray</name>
            <uri>file://media/materials/scripts/gazebo.material</uri>
          </script>
        </material>
      </visual>
      <self_collide>1</self_collide>
    </link>
    <joint name='fins_rev1' type='revolute'>
      <pose relative_to='base_link'>-1.56176 0 0.18 0 -0 0</pose>
      <parent>base_link</parent>
      <child>FinHolder_1</child>
      <axis>
        <xyz>0 0 1</xyz>
        <limit>
          <lower>-0.349066</lower>
          <upper>0.349066</upper>
          <effort>100</effort>
          <velocity>100</velocity>
        </limit>
        <dynamics>
          <spring_reference>0</spring_reference>
          <spring_stiffness>0</spring_stiffness>
        </dynamics>
      </axis>
    </joint>
    <link name='FinHolder_1'>
      <pose relative_to='fins_rev1'>0 0 0 0 -0 0</pose>
      <inertial>
        <pose>0.01199 3e-06 0.035204 0 -0 0</pose>
        <mass>0.613642</mass>
        <inertia>
          <ixx>0.000219</ixx>
          <ixy>0</ixy>
          <ixz>3.8e-05</ixz>
          <iyy>0.004162</iyy>
          <iyz>0</iyz>
          <izz>0.003989</izz>
        </inertia>
      </inertial>
      <collision name='FinHolder_1_collision'>
        <pose>1.56176 0 -0.18 0 -0 0</pose>
        <geometry>
          <mesh>
            <scale>0.001 0.001 0.001</scale>
            <uri>model://ex_mm40b3_description/meshes/FinHolder_1.stl</uri>
          </mesh>
        </geometry>
        <surface>
          <contact>
            <ode/>
          </contact>
          <friction>
            <ode>
              <mu>0.2</mu>
              <mu2>0.2</mu2>
            </ode>
          </friction>
        </surface>
      </collision>
      <visual name='FinHolder_1_visual'>
        <pose>1.56176 0 -0.18 0 -0 0</pose>
        <geometry>
          <mesh>
            <scale>0.001 0.001 0.001</scale>
            <uri>model://ex_mm40b3_description/meshes/FinHolder_1.stl</uri>
          </mesh>
        </geometry>
        <material>
          <script>
            <name>Gazebo/Blue</name>
            <uri>file://media/materials/scripts/gazebo.material</uri>
          </script>
        </material>
      </visual>
      <self_collide>1</self_collide>
    </link>
    <joint name='fin_fold1' type='revolute'>
      <pose relative_to='FinHolder_1'>0 0 0.055 0 -0 0</pose>
      <parent>FinHolder_1</parent>
      <child>Fin_1</child>
      <axis>
        <xyz>1 0 0</xyz>
        <limit>
          <lower>0</lower>
          <upper>2.14676</upper>
          <effort>100</effort>
          <velocity>100</velocity>
        </limit>
        <dynamics>
          <spring_reference>0</spring_reference>
          <spring_stiffness>0</spring_stiffness>
        </dynamics>
      </axis>
    </joint>
    <link name='Fin_1'>
      <pose relative_to='fin_fold1'>0 0 0 0 -0 0</pose>
      <inertial>
        <pose>-0.01567 0.051059 -0.033158 0 -0 0</pose>
        <mass>1.19146</mass>
        <inertia>
          <ixx>0.003045</ixx>
          <ixy>0.000707</ixy>
          <ixz>-0.000459</ixz>
          <iyy>0.003419</iyy>
          <iyz>0.00136</iyz>
          <izz>0.004631</izz>
        </inertia>
      </inertial>
      <collision name='Fin_1_collision'>
        <pose>1.56176 0 -0.235 0 -0 0</pose>
        <geometry>
          <mesh>
            <scale>0.001 0.001 0.001</scale>
            <uri>model://ex_mm40b3_description/meshes/Fin_1.stl</uri>
          </mesh>
        </geometry>
        <surface>
          <contact>
            <ode/>
          </contact>
          <friction>
            <ode>
              <mu>0.2</mu>
              <mu2>0.2</mu2>
            </ode>
          </friction>
        </surface>
      </collision>
      <visual name='Fin_1_visual'>
        <pose>1.56176 0 -0.235 0 -0 0</pose>
        <geometry>
          <mesh>
            <scale>0.001 0.001 0.001</scale>
            <uri>model://ex_mm40b3_description/meshes/Fin_1.stl</uri>
          </mesh>
        </geometry>
        <material>
          <script>
            <name>Gazebo/Orange</name>
            <uri>file://media/materials/scripts/gazebo.material</uri>
          </script>
        </material>
      </visual>
      <self_collide>1</self_collide>
    </link>
    <joint name='fins_rev2' type='revolute'>
      <pose relative_to='base_link'>-1.56176 0.18 0 0 -0 0</pose>
      <parent>base_link</parent>
      <child>FinHolder_2</child>
      <axis>
        <xyz>0 1 0</xyz>
        <limit>
          <lower>-0.349066</lower>
          <upper>0.349066</upper>
          <effort>100</effort>
          <velocity>100</velocity>
        </limit>
        <dynamics>
          <spring_reference>0</spring_reference>
          <spring_stiffness>0</spring_stiffness>
        </dynamics>
      </axis>
    </joint>
    <link name='FinHolder_2'>
      <pose relative_to='fins_rev2'>0 0 0 0 -0 0</pose>
      <inertial>
        <pose>0.01199 0.035204 -3e-06 0 -0 0</pose>
        <mass>0.613642</mass>
        <inertia>
          <ixx>0.000219</ixx>
          <ixy>3.8e-05</ixy>
          <ixz>0</ixz>
          <iyy>0.003989</iyy>
          <iyz>0</iyz>
          <izz>0.004162</izz>
        </inertia>
      </inertial>
      <collision name='FinHolder_2_collision'>
        <pose>1.56176 -0.18 0 0 -0 0</pose>
        <geometry>
          <mesh>
            <scale>0.001 0.001 0.001</scale>
            <uri>model://ex_mm40b3_description/meshes/FinHolder_2.stl</uri>
          </mesh>
        </geometry>
        <surface>
          <contact>
            <ode/>
          </contact>
          <friction>
            <ode>
              <mu>0.2</mu>
              <mu2>0.2</mu2>
            </ode>
          </friction>
        </surface>
      </collision>
      <visual name='FinHolder_2_visual'>
        <pose>1.56176 -0.18 0 0 -0 0</pose>
        <geometry>
          <mesh>
            <scale>0.001 0.001 0.001</scale>
            <uri>model://ex_mm40b3_description/meshes/FinHolder_2.stl</uri>
          </mesh>
        </geometry>
        <material>
          <script>
            <name>Gazebo/Blue</name>
            <uri>file://media/materials/scripts/gazebo.material</uri>
          </script>
        </material>
      </visual>
      <self_collide>1</self_collide>
    </link>
    <joint name='fin_fold2' type='revolute'>
      <pose relative_to='FinHolder_2'>0 0.055 -1.7e-05 0 -0 0</pose>
      <parent>FinHolder_2</parent>
      <child>Fin_2</child>
      <axis>
        <xyz>1 0 0</xyz>
        <limit>
          <lower>0</lower>
          <upper>2.14676</upper>
          <effort>100</effort>
          <velocity>100</velocity>
        </limit>
        <dynamics>
          <spring_reference>0</spring_reference>
          <spring_stiffness>0</spring_stiffness>
        </dynamics>
      </axis>
    </joint>
    <link name='Fin_2'>
      <pose relative_to='fin_fold2'>0 0 0 0 -0 0</pose>
      <inertial>
        <pose>-0.01567 -0.033158 -0.051059 0 -0 0</pose>
        <mass>1.19146</mass>
        <inertia>
          <ixx>0.003045</ixx>
          <ixy>-0.000459</ixy>
          <ixz>-0.000707</ixz>
          <iyy>0.004631</iyy>
          <iyz>-0.00136</iyz>
          <izz>0.003419</izz>
        </inertia>
      </inertial>
      <collision name='Fin_2_collision'>
        <pose>1.56176 -0.235 1.7e-05 0 -0 0</pose>
        <geometry>
          <mesh>
            <scale>0.001 0.001 0.001</scale>
            <uri>model://ex_mm40b3_description/meshes/Fin_2.stl</uri>
          </mesh>
        </geometry>
        <surface>
          <contact>
            <ode/>
          </contact>
          <friction>
            <ode>
              <mu>0.2</mu>
              <mu2>0.2</mu2>
            </ode>
          </friction>
        </surface>
      </collision>
      <visual name='Fin_2_visual'>
        <pose>1.56176 -0.235 1.7e-05 0 -0 0</pose>
        <geometry>
          <mesh>
            <scale>0.001 0.001 0.001</scale>
            <uri>model://ex_mm40b3_description/meshes/Fin_2.stl</uri>
          </mesh>
        </geometry>
        <material>
          <script>
            <name>Gazebo/Orange</name>
            <uri>file://media/materials/scripts/gazebo.material</uri>
          </script>
        </material>
      </visual>
      <self_collide>1</self_collide>
    </link>
    <joint name='fins_rev3' type='revolute'>
      <pose relative_to='base_link'>-1.56176 0 -0.18 0 -0 0</pose>
      <parent>base_link</parent>
      <child>FinHolder_3</child>
      <axis>
        <xyz>0 0 -1</xyz>
        <limit>
          <lower>-0.349066</lower>
          <upper>0.349066</upper>
          <effort>100</effort>
          <velocity>100</velocity>
        </limit>
        <dynamics>
          <spring_reference>0</spring_reference>
          <spring_stiffness>0</spring_stiffness>
        </dynamics>
      </axis>
    </joint>
    <link name='FinHolder_3'>
      <pose relative_to='fins_rev3'>0 0 0 0 -0 0</pose>
      <inertial>
        <pose>0.01199 -3e-06 -0.035204 0 -0 0</pose>
        <mass>0.613642</mass>
        <inertia>
          <ixx>0.000219</ixx>
          <ixy>0</ixy>
          <ixz>-3.8e-05</ixz>
          <iyy>0.004162</iyy>
          <iyz>0</iyz>
          <izz>0.003989</izz>
        </inertia>
      </inertial>
      <collision name='FinHolder_3_collision'>
        <pose>1.56176 0 0.18 0 -0 0</pose>
        <geometry>
          <mesh>
            <scale>0.001 0.001 0.001</scale>
            <uri>model://ex_mm40b3_description/meshes/FinHolder_3.stl</uri>
          </mesh>
        </geometry>
        <surface>
          <contact>
            <ode/>
          </contact>
          <friction>
            <ode>
              <mu>0.2</mu>
              <mu2>0.2</mu2>
            </ode>
          </friction>
        </surface>
      </collision>
      <visual name='FinHolder_3_visual'>
        <pose>1.56176 0 0.18 0 -0 0</pose>
        <geometry>
          <mesh>
            <scale>0.001 0.001 0.001</scale>
            <uri>model://ex_mm40b3_description/meshes/FinHolder_3.stl</uri>
          </mesh>
        </geometry>
        <material>
          <script>
            <name>Gazebo/Blue</name>
            <uri>file://media/materials/scripts/gazebo.material</uri>
          </script>
        </material>
      </visual>
      <self_collide>1</self_collide>
    </link>
    <joint name='fin_fold3' type='revolute'>
      <pose relative_to='FinHolder_3'>0 0 -0.055 0 -0 0</pose>
      <parent>FinHolder_3</parent>
      <child>Fin_3</child>
      <axis>
        <xyz>1 0 0</xyz>
        <limit>
          <lower>0</lower>
          <upper>2.14676</upper>
          <effort>100</effort>
          <velocity>100</velocity>
        </limit>
        <dynamics>
          <spring_reference>0</spring_reference>
          <spring_stiffness>0</spring_stiffness>
        </dynamics>
      </axis>
    </joint>
    <link name='Fin_3'>
      <pose relative_to='fin_fold3'>0 0 0 0 -0 0</pose>
      <inertial>
        <pose>-0.01567 -0.051059 0.033158 0 -0 0</pose>
        <mass>1.19146</mass>
        <inertia>
          <ixx>0.003045</ixx>
          <ixy>-0.000707</ixy>
          <ixz>0.000459</ixz>
          <iyy>0.003419</iyy>
          <iyz>0.00136</iyz>
          <izz>0.004631</izz>
        </inertia>
      </inertial>
      <collision name='Fin_3_collision'>
        <pose>1.56176 0 0.235 0 -0 0</pose>
        <geometry>
          <mesh>
            <scale>0.001 0.001 0.001</scale>
            <uri>model://ex_mm40b3_description/meshes/Fin_3.stl</uri>
          </mesh>
        </geometry>
        <surface>
          <contact>
            <ode/>
          </contact>
          <friction>
            <ode>
              <mu>0.2</mu>
              <mu2>0.2</mu2>
            </ode>
          </friction>
        </surface>
      </collision>
      <visual name='Fin_3_visual'>
        <pose>1.56176 0 0.235 0 -0 0</pose>
        <geometry>
          <mesh>
            <scale>0.001 0.001 0.001</scale>
            <uri>model://ex_mm40b3_description/meshes/Fin_3.stl</uri>
          </mesh>
        </geometry>
        <material>
          <script>
            <name>Gazebo/Orange</name>
            <uri>file://media/materials/scripts/gazebo.material</uri>
          </script>
        </material>
      </visual>
      <self_collide>1</self_collide>
    </link>
    <joint name='fins_rev4' type='revolute'>
      <pose relative_to='base_link'>-1.56176 -0.18 0 0 -0 0</pose>
      <parent>base_link</parent>
      <child>FinHolder_4</child>
      <axis>
        <xyz>0 -1 0</xyz>
        <limit>
          <lower>-0.349066</lower>
          <upper>0.349066</upper>
          <effort>100</effort>
          <velocity>100</velocity>
        </limit>
        <dynamics>
          <spring_reference>0</spring_reference>
          <spring_stiffness>0</spring_stiffness>
        </dynamics>
      </axis>
    </joint>
    <link name='FinHolder_4'>
      <pose relative_to='fins_rev4'>0 0 0 0 -0 0</pose>
      <inertial>
        <pose>0.01199 -0.035204 3e-06 0 -0 0</pose>
        <mass>0.613642</mass>
        <inertia>
          <ixx>0.000219</ixx>
          <ixy>-3.8e-05</ixy>
          <ixz>0</ixz>
          <iyy>0.003989</iyy>
          <iyz>0</iyz>
          <izz>0.004162</izz>
        </inertia>
      </inertial>
      <collision name='FinHolder_4_collision'>
        <pose>1.56176 0.18 0 0 -0 0</pose>
        <geometry>
          <mesh>
            <scale>0.001 0.001 0.001</scale>
            <uri>model://ex_mm40b3_description/meshes/FinHolder_4.stl</uri>
          </mesh>
        </geometry>
        <surface>
          <contact>
            <ode/>
          </contact>
          <friction>
            <ode>
              <mu>0.2</mu>
              <mu2>0.2</mu2>
            </ode>
          </friction>
        </surface>
      </collision>
      <visual name='FinHolder_4_visual'>
        <pose>1.56176 0.18 0 0 -0 0</pose>
        <geometry>
          <mesh>
            <scale>0.001 0.001 0.001</scale>
            <uri>model://ex_mm40b3_description/meshes/FinHolder_4.stl</uri>
          </mesh>
        </geometry>
        <material>
          <script>
            <name>Gazebo/Blue</name>
            <uri>file://media/materials/scripts/gazebo.material</uri>
          </script>
        </material>
      </visual>
      <self_collide>1</self_collide>
    </link>
    <joint name='fin_fold4' type='revolute'>
      <pose relative_to='FinHolder_4'>0 -0.055 0 0 -0 0</pose>
      <parent>FinHolder_4</parent>
      <child>Fin_4</child>
      <axis>
        <xyz>1 0 0</xyz>
        <limit>
          <lower>0</lower>
          <upper>2.14676</upper>
          <effort>100</effort>
          <velocity>100</velocity>
        </limit>
        <dynamics>
          <spring_reference>0</spring_reference>
          <spring_stiffness>0</spring_stiffness>
        </dynamics>
      </axis>
    </joint>
    <link name='Fin_4'>
      <pose relative_to='fin_fold4'>0 0 0 0 -0 0</pose>
      <inertial>
        <pose>-0.01567 0.033158 0.051059 0 -0 0</pose>
        <mass>1.19146</mass>
        <inertia>
          <ixx>0.003045</ixx>
          <ixy>0.000459</ixy>
          <ixz>0.000707</ixz>
          <iyy>0.004631</iyy>
          <iyz>-0.00136</iyz>
          <izz>0.003419</izz>
        </inertia>
      </inertial>
      <collision name='Fin_4_collision'>
        <pose>1.56176 0.235 0 0 -0 0</pose>
        <geometry>
          <mesh>
            <scale>0.001 0.001 0.001</scale>
            <uri>model://ex_mm40b3_description/meshes/Fin_4.stl</uri>
          </mesh>
        </geometry>
        <surface>
          <contact>
            <ode/>
          </contact>
          <friction>
            <ode>
              <mu>0.2</mu>
              <mu2>0.2</mu2>
            </ode>
          </friction>
        </surface>
      </collision>
      <visual name='Fin_4_visual'>
        <pose>1.56176 0.235 0 0 -0 0</pose>
        <geometry>
          <mesh>
            <scale>0.001 0.001 0.001</scale>
            <uri>model://ex_mm40b3_description/meshes/Fin_4.stl</uri>
          </mesh>
        </geometry>
        <material>
          <script>
            <name>Gazebo/Orange</name>
            <uri>file://media/materials/scripts/gazebo.material</uri>
          </script>
        </material>
      </visual>
      <self_collide>1</self_collide>
    </link>
    <joint name='wings_fold1' type='revolute'>
      <pose relative_to='base_link'>-0.108536 0 0.231018 0 -0 0</pose>
      <parent>base_link</parent>
      <child>Wing1_1</child>
      <axis>
        <xyz>1 0 0</xyz>
        <limit>
          <lower>0</lower>
          <upper>2.14676</upper>
          <effort>100</effort>
          <velocity>100</velocity>
        </limit>
        <dynamics>
          <spring_reference>0</spring_reference>
          <spring_stiffness>0</spring_stiffness>
        </dynamics>
      </axis>
    </joint>
    <link name='Wing1_1'>
      <pose relative_to='wings_fold1'>0 0 0 0 -0 0</pose>
      <inertial>
        <pose>-0.040666 0.080745 -0.052436 0 -0 0</pose>
        <mass>7.94153</mass>
        <inertia>
          <ixx>0.045859</ixx>
          <ixy>0.016465</ixy>
          <ixz>-0.010693</ixz>
          <iyy>0.280396</iyy>
          <iyz>0.020713</iyz>
          <izz>0.29884</izz>
        </inertia>
      </inertial>
      <collision name='Wing1_1_collision'>
        <pose>0.108536 0 -0.231018 0 -0 0</pose>
        <geometry>
          <mesh>
            <scale>0.001 0.001 0.001</scale>
            <uri>model://ex_mm40b3_description/meshes/Wing1_1.stl</uri>
          </mesh>
        </geometry>
        <surface>
          <contact>
            <ode/>
          </contact>
          <friction>
            <ode>
              <mu>0.2</mu>
              <mu2>0.2</mu2>
            </ode>
          </friction>
        </surface>
      </collision>
      <visual name='Wing1_1_visual'>
        <pose>0.108536 0 -0.231018 0 -0 0</pose>
        <geometry>
          <mesh>
            <scale>0.001 0.001 0.001</scale>
            <uri>model://ex_mm40b3_description/meshes/Wing1_1.stl</uri>
          </mesh>
        </geometry>
        <material>
          <script>
            <name>Gazebo/Orange</name>
            <uri>file://media/materials/scripts/gazebo.material</uri>
          </script>
        </material>
      </visual>
      <self_collide>1</self_collide>
    </link>
    <joint name='wings_fold2' type='revolute'>
      <pose relative_to='base_link'>-0.108536 0.231018 0 0 -0 0</pose>
      <parent>base_link</parent>
      <child>Wing1_2</child>
      <axis>
        <xyz>1 0 0</xyz>
        <limit>
          <lower>0</lower>
          <upper>2.14676</upper>
          <effort>100</effort>
          <velocity>100</velocity>
        </limit>
        <dynamics>
          <spring_reference>0</spring_reference>
          <spring_stiffness>0</spring_stiffness>
        </dynamics>
      </axis>
    </joint>
    <link name='Wing1_2'>
      <pose relative_to='wings_fold2'>0 0 0 0 -0 0</pose>
      <inertial>
        <pose>-0.040666 -0.051891 -0.079906 0 -0 0</pose>
        <mass>7.94153</mass>
        <inertia>
          <ixx>0.045859</ixx>
          <ixy>-0.010693</ixy>
          <ixz>-0.016465</ixz>
          <iyy>0.29884</iyy>
          <iyz>-0.020713</iyz>
          <izz>0.280396</izz>
        </inertia>
      </inertial>
      <collision name='Wing1_2_collision'>
        <pose>0.108536 -0.231018 0 0 -0 0</pose>
        <geometry>
          <mesh>
            <scale>0.001 0.001 0.001</scale>
            <uri>model://ex_mm40b3_description/meshes/Wing1_2.stl</uri>
          </mesh>
        </geometry>
        <surface>
          <contact>
            <ode/>
          </contact>
          <friction>
            <ode>
              <mu>0.2</mu>
              <mu2>0.2</mu2>
            </ode>
          </friction>
        </surface>
      </collision>
      <visual name='Wing1_2_visual'>
        <pose>0.108536 -0.231018 0 0 -0 0</pose>
        <geometry>
          <mesh>
            <scale>0.001 0.001 0.001</scale>
            <uri>model://ex_mm40b3_description/meshes/Wing1_2.stl</uri>
          </mesh>
        </geometry>
        <material>
          <script>
            <name>Gazebo/Orange</name>
            <uri>file://media/materials/scripts/gazebo.material</uri>
          </script>
        </material>
      </visual>
      <self_collide>1</self_collide>
    </link>
    <joint name='wings_fold3' type='revolute'>
      <pose relative_to='base_link'>-0.108536 0 -0.231018 0 -0 0</pose>
      <parent>base_link</parent>
      <child>Wing1_3</child>
      <axis>
        <xyz>1 0 0</xyz>
        <limit>
          <lower>0</lower>
          <upper>2.14676</upper>
          <effort>100</effort>
          <velocity>100</velocity>
        </limit>
        <dynamics>
          <spring_reference>0</spring_reference>
          <spring_stiffness>0</spring_stiffness>
        </dynamics>
      </axis>
    </joint>
    <link name='Wing1_3'>
      <pose relative_to='wings_fold3'>0 0 0 0 -0 0</pose>
      <inertial>
        <pose>-0.040666 -0.079906 0.051891 0 -0 0</pose>
        <mass>7.94153</mass>
        <inertia>
          <ixx>0.045859</ixx>
          <ixy>-0.016465</ixy>
          <ixz>0.010693</ixz>
          <iyy>0.280396</iyy>
          <iyz>0.020713</iyz>
          <izz>0.29884</izz>
        </inertia>
      </inertial>
      <collision name='Wing1_3_collision'>
        <pose>0.108536 0 0.231018 0 -0 0</pose>
        <geometry>
          <mesh>
            <scale>0.001 0.001 0.001</scale>
            <uri>model://ex_mm40b3_description/meshes/Wing1_3.stl</uri>
          </mesh>
        </geometry>
        <surface>
          <contact>
            <ode/>
          </contact>
          <friction>
            <ode>
              <mu>0.2</mu>
              <mu2>0.2</mu2>
            </ode>
          </friction>
        </surface>
      </collision>
      <visual name='Wing1_3_visual'>
        <pose>0.108536 0 0.231018 0 -0 0</pose>
        <geometry>
          <mesh>
            <scale>0.001 0.001 0.001</scale>
            <uri>model://ex_mm40b3_description/meshes/Wing1_3.stl</uri>
          </mesh>
        </geometry>
        <material>
          <script>
            <name>Gazebo/Orange</name>
            <uri>file://media/materials/scripts/gazebo.material</uri>
          </script>
        </material>
      </visual>
      <self_collide>1</self_collide>
    </link>
    <joint name='wings_fold4' type='revolute'>
      <pose relative_to='base_link'>-0.108536 -0.231018 0 0 -0 0</pose>
      <parent>base_link</parent>
      <child>Wing1_4</child>
      <axis>
        <xyz>1 0 0</xyz>
        <limit>
          <lower>0</lower>
          <upper>2.14676</upper>
          <effort>100</effort>
          <velocity>100</velocity>
        </limit>
        <dynamics>
          <spring_reference>0</spring_reference>
          <spring_stiffness>0</spring_stiffness>
        </dynamics>
      </axis>
    </joint>
    <link name='Wing1_4'>
      <pose relative_to='wings_fold4'>0 0 0 0 -0 0</pose>
      <inertial>
        <pose>-0.040666 0.051891 0.079906 0 -0 0</pose>
        <mass>7.94153</mass>
        <inertia>
          <ixx>0.045859</ixx>
          <ixy>0.010693</ixy>
          <ixz>0.016465</ixz>
          <iyy>0.29884</iyy>
          <iyz>-0.020713</iyz>
          <izz>0.280396</izz>
        </inertia>
      </inertial>
      <collision name='Wing1_4_collision'>
        <pose>0.108536 0.231018 0 0 -0 0</pose>
        <geometry>
          <mesh>
            <scale>0.001 0.001 0.001</scale>
            <uri>model://ex_mm40b3_description/meshes/Wing1_4.stl</uri>
          </mesh>
        </geometry>
        <surface>
          <contact>
            <ode/>
          </contact>
          <friction>
            <ode>
              <mu>0.2</mu>
              <mu2>0.2</mu2>
            </ode>
          </friction>
        </surface>
      </collision>
      <visual name='Wing1_4_visual'>
        <pose>0.108536 0.231018 0 0 -0 0</pose>
        <geometry>
          <mesh>
            <scale>0.001 0.001 0.001</scale>
            <uri>model://ex_mm40b3_description/meshes/Wing1_4.stl</uri>
          </mesh>
        </geometry>
        <material>
          <script>
            <name>Gazebo/Orange</name>
            <uri>file://media/materials/scripts/gazebo.material</uri>
          </script>
        </material>
      </visual>
      <self_collide>1</self_collide>
    </link>
    <static>0</static>
    <plugin name='ex_mm40b3_controller' filename='libgazebo_ros_control.so'>
      <robotNamespace>ex_mm40b3_controller</robotNamespace>
      <robotSimType>gazebo_ros_control/DefaultRobotHWSim</robotSimType>
    </plugin>
    <plugin name='BoosterThrust' filename='libSimpleThruster.so'>
      <link_name>Booster_1</link_name>
      <forward_dir>1 0 0</forward_dir>
      <thrust_origin>0 0 0</thrust_origin>
      <robotNamespace/>
      <topic_name>booster_visual</topic_name>
      <thrust_topic>booster_force</thrust_topic>
    </plugin>
  </model>
</sdf>
