<?xml version="1.0" ?>
<robot name="exocet_launcher_half" xmlns:xacro="http://www.ros.org/wiki/xacro">

<xacro:include filename="$(find exocet_launcher_half_description)/urdf/materials.xacro" />
<xacro:include filename="$(find exocet_launcher_half_description)/urdf/exocet_launcher_half.trans" />
<xacro:include filename="$(find exocet_launcher_half_description)/urdf/exocet_launcher_half.gazebo" />
<link name="base_link">
  <inertial>
    <origin xyz="0.21956009217606984 4.3636388735968575e-16 0.6746334924440056" rpy="0 0 0"/>
    <mass value="10722.621074762288"/>
    <inertia ixx="3680.005759" iyy="13504.573497" izz="12126.040929" ixy="0.0" iyz="0.0" ixz="-2210.827735"/>
  </inertial>
  <visual>
    <origin xyz="0 0 0" rpy="0 0 0"/>
    <geometry>
      <mesh filename="package://exocet_launcher_half_description/meshes/base_link.stl" scale="0.001 0.001 0.001"/>
    </geometry>
    <material name="darkgrey"/>
  </visual>
  <collision>
    <origin xyz="0 0 0" rpy="0 0 0"/>
    <geometry>
      <mesh filename="package://exocet_launcher_half_description/meshes/base_link.stl" scale="0.001 0.001 0.001"/>
    </geometry>
  </collision>
</link>

<link name="Canister_1">
  <inertial>
    <origin xyz="-1.3455029394993274 -5.851690442643435e-12 -0.6889676216530494" rpy="0 0 0"/>
    <mass value="804.672730610412"/>
    <inertia ixx="373.324731" iyy="2888.906844" izz="2576.368498" ixy="-0.0" iyz="-0.0" ixz="-924.286606"/>
  </inertial>
  <visual>
    <origin xyz="-1.262326 0.0 -2.249618" rpy="0 0 0"/>
    <geometry>
      <mesh filename="package://exocet_launcher_half_description/meshes/Canister_1.stl" scale="0.001 0.001 0.001"/>
    </geometry>
    <material name="white"/>
  </visual>
  <collision>
    <origin xyz="-1.262326 0.0 -2.249618" rpy="0 0 0"/>
    <geometry>
      <mesh filename="package://exocet_launcher_half_description/meshes/Canister_1.stl" scale="0.001 0.001 0.001"/>
    </geometry>
  </collision>
</link>

<link name="Cup_3">
  <inertial>
    <origin xyz="-0.10791790928581646 -8.207033013996926e-09 0.281244501140661" rpy="0 0 0"/>
    <mass value="124.35780308588551"/>
    <inertia ixx="5.91815" iyy="3.153552" izz="3.54169" ixy="0.0" iyz="0.0" ixz="0.997121"/>
  </inertial>
  <visual>
    <origin xyz="-2.805247 0.0 -2.491208" rpy="0 0 0"/>
    <geometry>
      <mesh filename="package://exocet_launcher_half_description/meshes/Cup_3.stl" scale="0.001 0.001 0.001"/>
    </geometry>
    <material name="black"/>
  </visual>
  <collision>
    <origin xyz="-2.805247 0.0 -2.491208" rpy="0 0 0"/>
    <geometry>
      <mesh filename="package://exocet_launcher_half_description/meshes/Cup_3.stl" scale="0.001 0.001 0.001"/>
    </geometry>
  </collision>
</link>

<link name="Cup_1">
  <inertial>
    <origin xyz="0.1876428588086605 8.207050409553099e-09 -0.6865610652939461" rpy="0 0 0"/>
    <mass value="124.35780308588551"/>
    <inertia ixx="5.918226" iyy="3.153552" izz="3.541614" ixy="0.0" iyz="-0.0" ixz="0.99703"/>
  </inertial>
  <visual>
    <origin xyz="3.177629 -0.0 -1.389734" rpy="0 0 0"/>
    <geometry>
      <mesh filename="package://exocet_launcher_half_description/meshes/Cup_1.stl" scale="0.001 0.001 0.001"/>
    </geometry>
    <material name="black"/>
  </visual>
  <collision>
    <origin xyz="3.177629 -0.0 -1.389734" rpy="0 0 0"/>
    <geometry>
      <mesh filename="package://exocet_launcher_half_description/meshes/Cup_1.stl" scale="0.001 0.001 0.001"/>
    </geometry>
  </collision>
</link>

<link name="CanisterHolder_1">
  <inertial>
    <origin xyz="-0.05951337321479344 1.4715522383126382e-16 0.16351174115532052" rpy="0 0 0"/>
    <mass value="335.0395971576902"/>
    <inertia ixx="43.686085" iyy="22.365267" izz="51.43432" ixy="0.0" iyz="0.0" ixz="-3.25077"/>
  </inertial>
  <visual>
    <origin xyz="1.419944 0.0 -0.847681" rpy="0 0 0"/>
    <geometry>
      <mesh filename="package://exocet_launcher_half_description/meshes/CanisterHolder_1.stl" scale="0.001 0.001 0.001"/>
    </geometry>
    <material name="green"/>
  </visual>
  <collision>
    <origin xyz="1.419944 0.0 -0.847681" rpy="0 0 0"/>
    <geometry>
      <mesh filename="package://exocet_launcher_half_description/meshes/CanisterHolder_1.stl" scale="0.001 0.001 0.001"/>
    </geometry>
  </collision>
</link>

<link name="CanisterHolder_2">
  <inertial>
    <origin xyz="-0.05951351085707057 1.4715522383126382e-16 0.16351217113232974" rpy="0 0 0"/>
    <mass value="335.0395971576902"/>
    <inertia ixx="43.686085" iyy="22.365267" izz="51.43432" ixy="0.0" iyz="0.0" ixz="-3.25077"/>
  </inertial>
  <visual>
    <origin xyz="-1.399134 0.0 -1.873741" rpy="0 0 0"/>
    <geometry>
      <mesh filename="package://exocet_launcher_half_description/meshes/CanisterHolder_2.stl" scale="0.001 0.001 0.001"/>
    </geometry>
    <material name="green"/>
  </visual>
  <collision>
    <origin xyz="-1.399134 0.0 -1.873741" rpy="0 0 0"/>
    <geometry>
      <mesh filename="package://exocet_launcher_half_description/meshes/CanisterHolder_2.stl" scale="0.001 0.001 0.001"/>
    </geometry>
  </collision>
</link>

<joint name="CanisterToHolder2" type="fixed">
  <origin xyz="-0.136808 0.0 0.375877" rpy="0 0 0"/>
  <parent link="CanisterHolder_2"/>
  <child link="Canister_1"/>
</joint>

<joint name="CupOpener" type="revolute">
  <origin xyz="1.542921 0.0 0.24159" rpy="0 0 0"/>
  <parent link="Canister_1"/>
  <child link="Cup_3"/>
  <axis xyz="0.0 1.0 0.0"/>
  <limit upper="4.712389" lower="0.0" effort="100" velocity="100"/>
</joint>

<joint name="CupCloser" type="fixed">
  <origin xyz="-4.439955 0.0 -0.859884" rpy="0 0 0"/>
  <parent link="Canister_1"/>
  <child link="Cup_1"/>
</joint>

<joint name="BaseToHolder1" type="fixed">
  <origin xyz="-1.419944 0.0 0.847681" rpy="0 0 0"/>
  <parent link="base_link"/>
  <child link="CanisterHolder_1"/>
</joint>

<joint name="BaseToHolder2" type="fixed">
  <origin xyz="1.399134 0.0 1.873741" rpy="0 0 0"/>
  <parent link="base_link"/>
  <child link="CanisterHolder_2"/>
</joint>

</robot>
