<?xml version="1.0" ?>
<!-- =================================================================================== -->
<!-- |    This document was autogenerated by xacro from src/ex_mm40b3_description/urdf/ex_mm40b3.xacro | -->
<!-- |    EDITING THIS FILE BY HAND IS NOT RECOMMENDED                                 | -->
<!-- =================================================================================== -->
<robot name="ex_mm40b3">
  <material name="grey">
    <color rgba="0.82421875 0.82421875 0.82421875 1.0"/>
  </material>
  <material name="darkgrey">
    <color rgba="0.1843137254901961 0.30980392156862746 0.30980392156862746 1.000"/>
  </material>
  <material name="silver">
    <color rgba="0.700 0.700 0.700 1.000"/>
  </material>
  <material name="white">
    <color rgba="1 1 1 1"/>
  </material>
  <material name="orange">
    <color rgba="1 0.3 0.1 1"/>
  </material>
  <material name="blue">
    <color rgba="0.2 0.2 1 1"/>
  </material>
  <material name="red">
    <color rgba="0.8 0 0 1"/>
  </material>
  <material name="green">
    <color rgba="0.0 1 0.0 1"/>
  </material>
  <material name="black">
    <color rgba="0 0 0 1"/>
  </material>
  <transmission name="fins_rev1_tran">
    <type>transmission_interface/SimpleTransmission</type>
    <joint name="fins_rev1">
      <hardwareInterface>hardware_interface/EffortJointInterface</hardwareInterface>
    </joint>
    <actuator name="fins_rev1_actr">
      <hardwareInterface>hardware_interface/EffortJointInterface</hardwareInterface>
      <mechanicalReduction>1</mechanicalReduction>
    </actuator>
  </transmission>
  <transmission name="fins_rev4_tran">
    <type>transmission_interface/SimpleTransmission</type>
    <joint name="fins_rev4">
      <hardwareInterface>hardware_interface/EffortJointInterface</hardwareInterface>
    </joint>
    <actuator name="fins_rev4_actr">
      <hardwareInterface>hardware_interface/EffortJointInterface</hardwareInterface>
      <mechanicalReduction>1</mechanicalReduction>
    </actuator>
  </transmission>
  <transmission name="fins_rev3_tran">
    <type>transmission_interface/SimpleTransmission</type>
    <joint name="fins_rev3">
      <hardwareInterface>hardware_interface/EffortJointInterface</hardwareInterface>
    </joint>
    <actuator name="fins_rev3_actr">
      <hardwareInterface>hardware_interface/EffortJointInterface</hardwareInterface>
      <mechanicalReduction>1</mechanicalReduction>
    </actuator>
  </transmission>
  <transmission name="fins_rev2_tran">
    <type>transmission_interface/SimpleTransmission</type>
    <joint name="fins_rev2">
      <hardwareInterface>hardware_interface/EffortJointInterface</hardwareInterface>
    </joint>
    <actuator name="fins_rev2_actr">
      <hardwareInterface>hardware_interface/EffortJointInterface</hardwareInterface>
      <mechanicalReduction>1</mechanicalReduction>
    </actuator>
  </transmission>
  <transmission name="wings_fold1_tran">
    <type>transmission_interface/SimpleTransmission</type>
    <joint name="wings_fold1">
      <hardwareInterface>hardware_interface/EffortJointInterface</hardwareInterface>
    </joint>
    <actuator name="wings_fold1_actr">
      <hardwareInterface>hardware_interface/EffortJointInterface</hardwareInterface>
      <mechanicalReduction>1</mechanicalReduction>
    </actuator>
  </transmission>
  <transmission name="wings_fold2_tran">
    <type>transmission_interface/SimpleTransmission</type>
    <joint name="wings_fold2">
      <hardwareInterface>hardware_interface/EffortJointInterface</hardwareInterface>
    </joint>
    <actuator name="wings_fold2_actr">
      <hardwareInterface>hardware_interface/EffortJointInterface</hardwareInterface>
      <mechanicalReduction>1</mechanicalReduction>
    </actuator>
  </transmission>
  <transmission name="wings_fold3_tran">
    <type>transmission_interface/SimpleTransmission</type>
    <joint name="wings_fold3">
      <hardwareInterface>hardware_interface/EffortJointInterface</hardwareInterface>
    </joint>
    <actuator name="wings_fold3_actr">
      <hardwareInterface>hardware_interface/EffortJointInterface</hardwareInterface>
      <mechanicalReduction>1</mechanicalReduction>
    </actuator>
  </transmission>
  <transmission name="wings_fold4_tran">
    <type>transmission_interface/SimpleTransmission</type>
    <joint name="wings_fold4">
      <hardwareInterface>hardware_interface/EffortJointInterface</hardwareInterface>
    </joint>
    <actuator name="wings_fold4_actr">
      <hardwareInterface>hardware_interface/EffortJointInterface</hardwareInterface>
      <mechanicalReduction>1</mechanicalReduction>
    </actuator>
  </transmission>
  <transmission name="fin_fold1_tran">
    <type>transmission_interface/SimpleTransmission</type>
    <joint name="fin_fold1">
      <hardwareInterface>hardware_interface/EffortJointInterface</hardwareInterface>
    </joint>
    <actuator name="fin_fold1_actr">
      <hardwareInterface>hardware_interface/EffortJointInterface</hardwareInterface>
      <mechanicalReduction>1</mechanicalReduction>
    </actuator>
  </transmission>
  <transmission name="fin_fold2_tran">
    <type>transmission_interface/SimpleTransmission</type>
    <joint name="fin_fold2">
      <hardwareInterface>hardware_interface/EffortJointInterface</hardwareInterface>
    </joint>
    <actuator name="fin_fold2_actr">
      <hardwareInterface>hardware_interface/EffortJointInterface</hardwareInterface>
      <mechanicalReduction>1</mechanicalReduction>
    </actuator>
  </transmission>
  <transmission name="fin_fold3_tran">
    <type>transmission_interface/SimpleTransmission</type>
    <joint name="fin_fold3">
      <hardwareInterface>hardware_interface/EffortJointInterface</hardwareInterface>
    </joint>
    <actuator name="fin_fold3_actr">
      <hardwareInterface>hardware_interface/EffortJointInterface</hardwareInterface>
      <mechanicalReduction>1</mechanicalReduction>
    </actuator>
  </transmission>
  <transmission name="fin_fold4_tran">
    <type>transmission_interface/SimpleTransmission</type>
    <joint name="fin_fold4">
      <hardwareInterface>hardware_interface/EffortJointInterface</hardwareInterface>
    </joint>
    <actuator name="fin_fold4_actr">
      <hardwareInterface>hardware_interface/EffortJointInterface</hardwareInterface>
      <mechanicalReduction>1</mechanicalReduction>
    </actuator>
  </transmission>
  <gazebo>
    <plugin filename="libgazebo_ros_control.so" name="ex_mm40b3_controller">
      <robotNamespace>ex_mm40b3_controller</robotNamespace>
      <robotSimType>gazebo_ros_control/DefaultRobotHWSim</robotSimType>
    </plugin>
    <plugin filename="libSimpleThruster.so" name="BoosterThrust">
      <link_name>Booster_1</link_name>
      <forward_dir>1 0 0</forward_dir>
      <thrust_origin>0 0 0</thrust_origin>
      <robotNamespace/>
      <topic_name>booster_visual</topic_name>
      <thrust_topic>booster_force</thrust_topic>
    </plugin>
  </gazebo>
  <gazebo reference="base_link">
    <material>Gazebo/White</material>
    <mu1>0.2</mu1>
    <mu2>0.2</mu2>
    <selfCollide>true</selfCollide>
    <gravity>true</gravity>
  </gazebo>
  <gazebo reference="FinHolder_1">
    <material>Gazebo/Blue</material>
    <mu1>0.2</mu1>
    <mu2>0.2</mu2>
    <selfCollide>true</selfCollide>
  </gazebo>
  <gazebo reference="FinHolder_4">
    <material>Gazebo/Blue</material>
    <mu1>0.2</mu1>
    <mu2>0.2</mu2>
    <selfCollide>true</selfCollide>
  </gazebo>
  <gazebo reference="FinHolder_3">
    <material>Gazebo/Blue</material>
    <mu1>0.2</mu1>
    <mu2>0.2</mu2>
    <selfCollide>true</selfCollide>
  </gazebo>
  <gazebo reference="FinHolder_2">
    <material>Gazebo/Blue</material>
    <mu1>0.2</mu1>
    <mu2>0.2</mu2>
    <selfCollide>true</selfCollide>
  </gazebo>
  <gazebo reference="Wing1_1">
    <material>Gazebo/Orange</material>
    <mu1>0.2</mu1>
    <mu2>0.2</mu2>
    <selfCollide>true</selfCollide>
  </gazebo>
  <gazebo reference="Booster_1">
    <material>Gazebo/Gray</material>
    <mu1>0.2</mu1>
    <mu2>0.2</mu2>
    <selfCollide>true</selfCollide>
    <visual>
      <plugin filename="libForceVisual.so" name="SimpleThrustVisual">
        <topic_name>booster_visual</topic_name>
        <color>Gazebo/Red</color>
      </plugin>
    </visual>
  </gazebo>
  <gazebo reference="Wing1_2">
    <material>Gazebo/Orange</material>
    <mu1>0.2</mu1>
    <mu2>0.2</mu2>
    <selfCollide>true</selfCollide>
  </gazebo>
  <gazebo reference="Wing1_3">
    <material>Gazebo/Orange</material>
    <mu1>0.2</mu1>
    <mu2>0.2</mu2>
    <selfCollide>true</selfCollide>
  </gazebo>
  <gazebo reference="Wing1_4">
    <material>Gazebo/Orange</material>
    <mu1>0.2</mu1>
    <mu2>0.2</mu2>
    <selfCollide>true</selfCollide>
  </gazebo>
  <gazebo reference="Holder_1">
    <material>Gazebo/Grey</material>
    <mu1>0.2</mu1>
    <mu2>0.2</mu2>
    <selfCollide>true</selfCollide>
  </gazebo>
  <gazebo reference="Holder_2">
    <material>Gazebo/Grey</material>
    <mu1>0.2</mu1>
    <mu2>0.2</mu2>
    <selfCollide>true</selfCollide>
  </gazebo>
  <gazebo reference="Holder_3">
    <material>Gazebo/Grey</material>
    <mu1>0.2</mu1>
    <mu2>0.2</mu2>
    <selfCollide>true</selfCollide>
  </gazebo>
  <gazebo reference="Holder_4">
    <material>Gazebo/Grey</material>
    <mu1>0.2</mu1>
    <mu2>0.2</mu2>
    <selfCollide>true</selfCollide>
  </gazebo>
  <gazebo reference="Fin_1">
    <material>Gazebo/Orange</material>
    <mu1>0.2</mu1>
    <mu2>0.2</mu2>
    <selfCollide>true</selfCollide>
  </gazebo>
  <gazebo reference="Fin_2">
    <material>Gazebo/Orange</material>
    <mu1>0.2</mu1>
    <mu2>0.2</mu2>
    <selfCollide>true</selfCollide>
  </gazebo>
  <gazebo reference="Fin_3">
    <material>Gazebo/Orange</material>
    <mu1>0.2</mu1>
    <mu2>0.2</mu2>
    <selfCollide>true</selfCollide>
  </gazebo>
  <gazebo reference="Fin_4">
    <material>Gazebo/Orange</material>
    <mu1>0.2</mu1>
    <mu2>0.2</mu2>
    <selfCollide>true</selfCollide>
  </gazebo>
  <gazebo reference="booster_fixing">
    <preserveFixedJoint>true</preserveFixedJoint>
  </gazebo>
  <gazebo reference="HolderJoint1">
    <preserveFixedJoint>true</preserveFixedJoint>
  </gazebo>
  <gazebo reference="HolderJoint2">
    <preserveFixedJoint>true</preserveFixedJoint>
  </gazebo>
  <gazebo reference="HolderJoint3">
    <preserveFixedJoint>true</preserveFixedJoint>
  </gazebo>
  <gazebo reference="HolderJoint4">
    <preserveFixedJoint>true</preserveFixedJoint>
  </gazebo>
  <!-- <xacro:include filename="$(find ex_mm40b3_description)/urdf/plugins.gazebo"/> -->
  <link name="base_link">
    <inertial>
      <origin rpy="0 0 0" xyz="0.5582187363868036 -9.491428765021313e-11 -7.544864658374226e-10"/>
      <mass value="564.9695328358481"/>
      <inertia ixx="13.560396" ixy="-0.0" ixz="0.0" iyy="1088.286862" iyz="0.0" izz="1088.286862"/>
    </inertial>
    <visual>
      <origin rpy="0 0 0" xyz="0 0 0"/>
      <geometry>
        <mesh filename="package://ex_mm40b3_description/meshes/base_link.stl" scale="0.001 0.001 0.001"/>
      </geometry>
      <material name="white"/>
    </visual>
    <collision>
      <origin rpy="0 0 0" xyz="0 0 0"/>
      <geometry>
        <mesh filename="package://ex_mm40b3_description/meshes/base_link.stl" scale="0.001 0.001 0.001"/>
      </geometry>
    </collision>
  </link>
  <link name="FinHolder_1">
    <inertial>
      <origin rpy="0 0 0" xyz="0.01198993428751427 3.495693953659855e-06 0.03520370329433853"/>
      <mass value="0.6136418967408529"/>
      <inertia ixx="0.000219" ixy="-0.0" ixz="3.8e-05" iyy="0.004162" iyz="-0.0" izz="0.003989"/>
    </inertial>
    <visual>
      <origin rpy="0 0 0" xyz="1.561764 0.0 -0.18"/>
      <geometry>
        <mesh filename="package://ex_mm40b3_description/meshes/FinHolder_1.stl" scale="0.001 0.001 0.001"/>
      </geometry>
      <material name="blue"/>
    </visual>
    <collision>
      <origin rpy="0 0 0" xyz="1.561764 0.0 -0.18"/>
      <geometry>
        <mesh filename="package://ex_mm40b3_description/meshes/FinHolder_1.stl" scale="0.001 0.001 0.001"/>
      </geometry>
    </collision>
  </link>
  <link name="FinHolder_4">
    <inertial>
      <origin rpy="0 0 0" xyz="0.01198993428751427 -0.03520370414373866 3.495034387886701e-06"/>
      <mass value="0.6136418967408529"/>
      <inertia ixx="0.000219" ixy="-3.8e-05" ixz="-0.0" iyy="0.003989" iyz="0.0" izz="0.004162"/>
    </inertial>
    <visual>
      <origin rpy="0 0 0" xyz="1.561764 0.18 0.0"/>
      <geometry>
        <mesh filename="package://ex_mm40b3_description/meshes/FinHolder_4.stl" scale="0.001 0.001 0.001"/>
      </geometry>
      <material name="blue"/>
    </visual>
    <collision>
      <origin rpy="0 0 0" xyz="1.561764 0.18 0.0"/>
      <geometry>
        <mesh filename="package://ex_mm40b3_description/meshes/FinHolder_4.stl" scale="0.001 0.001 0.001"/>
      </geometry>
    </collision>
  </link>
  <link name="FinHolder_3">
    <inertial>
      <origin rpy="0 0 0" xyz="0.01198993428751427 -3.4958837879403273e-06 -0.035203704803304314"/>
      <mass value="0.6136418967408529"/>
      <inertia ixx="0.000219" ixy="0.0" ixz="-3.8e-05" iyy="0.004162" iyz="-0.0" izz="0.003989"/>
    </inertial>
    <visual>
      <origin rpy="0 0 0" xyz="1.561764 0.0 0.18"/>
      <geometry>
        <mesh filename="package://ex_mm40b3_description/meshes/FinHolder_3.stl" scale="0.001 0.001 0.001"/>
      </geometry>
      <material name="blue"/>
    </visual>
    <collision>
      <origin rpy="0 0 0" xyz="1.561764 0.0 0.18"/>
      <geometry>
        <mesh filename="package://ex_mm40b3_description/meshes/FinHolder_3.stl" scale="0.001 0.001 0.001"/>
      </geometry>
    </collision>
  </link>
  <link name="FinHolder_2">
    <inertial>
      <origin rpy="0 0 0" xyz="0.01198993428751427 0.035203703953904264 -3.496543353653529e-06"/>
      <mass value="0.6136418967408529"/>
      <inertia ixx="0.000219" ixy="3.8e-05" ixz="0.0" iyy="0.003989" iyz="0.0" izz="0.004162"/>
    </inertial>
    <visual>
      <origin rpy="0 0 0" xyz="1.561764 -0.18 0.0"/>
      <geometry>
        <mesh filename="package://ex_mm40b3_description/meshes/FinHolder_2.stl" scale="0.001 0.001 0.001"/>
      </geometry>
      <material name="blue"/>
    </visual>
    <collision>
      <origin rpy="0 0 0" xyz="1.561764 -0.18 0.0"/>
      <geometry>
        <mesh filename="package://ex_mm40b3_description/meshes/FinHolder_2.stl" scale="0.001 0.001 0.001"/>
      </geometry>
    </collision>
  </link>
  <link name="Wing1_1">
    <inertial>
      <origin rpy="0 0 0" xyz="-0.04066620765985293 0.0807449272160705 -0.05243595158558506"/>
      <mass value="7.941525705671481"/>
      <inertia ixx="0.045859" ixy="0.016465" ixz="-0.010693" iyy="0.280396" iyz="0.020713" izz="0.29884"/>
    </inertial>
    <visual>
      <origin rpy="0 0 0" xyz="0.108536 0.0 -0.231018"/>
      <geometry>
        <mesh filename="package://ex_mm40b3_description/meshes/Wing1_1.stl" scale="0.001 0.001 0.001"/>
      </geometry>
      <material name="orange"/>
    </visual>
    <collision>
      <origin rpy="0 0 0" xyz="0.108536 0.0 -0.231018"/>
      <geometry>
        <mesh filename="package://ex_mm40b3_description/meshes/Wing1_1.stl" scale="0.001 0.001 0.001"/>
      </geometry>
    </collision>
  </link>
  <link name="Booster_1">
    <inertial>
      <origin rpy="0 0 0" xyz="-0.5309883305776795 1.2931271704902409e-09 7.783320420974786e-11"/>
      <mass value="138.76341026969325"/>
      <inertia ixx="6.064544" ixy="-0.0" ixz="-0.0" iyy="17.450475" iyz="0.0" izz="17.450475"/>
    </inertial>
    <visual>
      <origin rpy="0 0 0" xyz="1.741776 0.0 0.0"/>
      <geometry>
        <mesh filename="package://ex_mm40b3_description/meshes/Booster_1.stl" scale="0.001 0.001 0.001"/>
      </geometry>
      <material name="grey"/>
    </visual>
    <collision>
      <origin rpy="0 0 0" xyz="1.741776 0.0 0.0"/>
      <geometry>
        <mesh filename="package://ex_mm40b3_description/meshes/Booster_1.stl" scale="0.001 0.001 0.001"/>
      </geometry>
    </collision>
  </link>
  <link name="Wing1_2">
    <inertial>
      <origin rpy="0 0 0" xyz="-0.040666207659853376 -0.05189131189100127 -0.079906257497525"/>
      <mass value="7.941525705671481"/>
      <inertia ixx="0.045859" ixy="-0.010693" ixz="-0.016465" iyy="0.29884" iyz="-0.020713" izz="0.280396"/>
    </inertial>
    <visual>
      <origin rpy="0 0 0" xyz="0.108536 -0.231018 0.0"/>
      <geometry>
        <mesh filename="package://ex_mm40b3_description/meshes/Wing1_2.stl" scale="0.001 0.001 0.001"/>
      </geometry>
      <material name="orange"/>
    </visual>
    <collision>
      <origin rpy="0 0 0" xyz="0.108536 -0.231018 0.0"/>
      <geometry>
        <mesh filename="package://ex_mm40b3_description/meshes/Wing1_2.stl" scale="0.001 0.001 0.001"/>
      </geometry>
    </collision>
  </link>
  <link name="Wing1_3">
    <inertial>
      <origin rpy="0 0 0" xyz="-0.04066620765985307 -0.07990625683795603 0.051891311041601024"/>
      <mass value="7.941525705671481"/>
      <inertia ixx="0.045859" ixy="-0.016465" ixz="0.010693" iyy="0.280396" iyz="0.020713" izz="0.29884"/>
    </inertial>
    <visual>
      <origin rpy="0 0 0" xyz="0.108536 0.0 0.231018"/>
      <geometry>
        <mesh filename="package://ex_mm40b3_description/meshes/Wing1_3.stl" scale="0.001 0.001 0.001"/>
      </geometry>
      <material name="orange"/>
    </visual>
    <collision>
      <origin rpy="0 0 0" xyz="0.108536 0.0 0.231018"/>
      <geometry>
        <mesh filename="package://ex_mm40b3_description/meshes/Wing1_3.stl" scale="0.001 0.001 0.001"/>
      </geometry>
    </collision>
  </link>
  <link name="Wing1_4">
    <inertial>
      <origin rpy="0 0 0" xyz="-0.04066620765985285 0.051891311701170034 0.07990625598855573"/>
      <mass value="7.941525705671481"/>
      <inertia ixx="0.045859" ixy="0.010693" ixz="0.016465" iyy="0.29884" iyz="-0.020713" izz="0.280396"/>
    </inertial>
    <visual>
      <origin rpy="0 0 0" xyz="0.108536 0.231018 0.0"/>
      <geometry>
        <mesh filename="package://ex_mm40b3_description/meshes/Wing1_4.stl" scale="0.001 0.001 0.001"/>
      </geometry>
      <material name="orange"/>
    </visual>
    <collision>
      <origin rpy="0 0 0" xyz="0.108536 0.231018 0.0"/>
      <geometry>
        <mesh filename="package://ex_mm40b3_description/meshes/Wing1_4.stl" scale="0.001 0.001 0.001"/>
      </geometry>
    </collision>
  </link>
  <link name="Holder_1">
    <inertial>
      <origin rpy="0 0 0" xyz="-0.1999999917328792 -9.490927239922491e-11 0.03608121241836992"/>
      <mass value="12.085489344125179"/>
      <inertia ixx="0.161772" ixy="-0.0" ixz="-0.0" iyy="0.69521" iyz="-0.0" izz="0.836017"/>
    </inertial>
    <visual>
      <origin rpy="0 0 0" xyz="-1.514695 0.0 -0.187374"/>
      <geometry>
        <mesh filename="package://ex_mm40b3_description/meshes/Holder_1.stl" scale="0.001 0.001 0.001"/>
      </geometry>
      <material name="darkgrey"/>
    </visual>
    <collision>
      <origin rpy="0 0 0" xyz="-1.514695 0.0 -0.187374"/>
      <geometry>
        <mesh filename="package://ex_mm40b3_description/meshes/Holder_1.stl" scale="0.001 0.001 0.001"/>
      </geometry>
    </collision>
  </link>
  <link name="Holder_2">
    <inertial>
      <origin rpy="0 0 0" xyz="-0.1999999917328792 -0.03608121241836992 -9.490925871653939e-11"/>
      <mass value="12.085489344125179"/>
      <inertia ixx="0.161772" ixy="0.0" ixz="-0.0" iyy="0.836017" iyz="0.0" izz="0.69521"/>
    </inertial>
    <visual>
      <origin rpy="0 0 0" xyz="-1.514695 0.187374 0.0"/>
      <geometry>
        <mesh filename="package://ex_mm40b3_description/meshes/Holder_2.stl" scale="0.001 0.001 0.001"/>
      </geometry>
      <material name="darkgrey"/>
    </visual>
    <collision>
      <origin rpy="0 0 0" xyz="-1.514695 0.187374 0.0"/>
      <geometry>
        <mesh filename="package://ex_mm40b3_description/meshes/Holder_2.stl" scale="0.001 0.001 0.001"/>
      </geometry>
    </collision>
  </link>
  <link name="Holder_3">
    <inertial>
      <origin rpy="0 0 0" xyz="-0.1999999917328792 9.490924503385386e-11 -0.03608121241836992"/>
      <mass value="12.085489344125179"/>
      <inertia ixx="0.161772" ixy="0.0" ixz="0.0" iyy="0.69521" iyz="-0.0" izz="0.836017"/>
    </inertial>
    <visual>
      <origin rpy="0 0 0" xyz="-1.514695 0.0 0.187374"/>
      <geometry>
        <mesh filename="package://ex_mm40b3_description/meshes/Holder_3.stl" scale="0.001 0.001 0.001"/>
      </geometry>
      <material name="darkgrey"/>
    </visual>
    <collision>
      <origin rpy="0 0 0" xyz="-1.514695 0.0 0.187374"/>
      <geometry>
        <mesh filename="package://ex_mm40b3_description/meshes/Holder_3.stl" scale="0.001 0.001 0.001"/>
      </geometry>
    </collision>
  </link>
  <link name="Holder_4">
    <inertial>
      <origin rpy="0 0 0" xyz="-0.1999999917328792 0.03608121241836992 9.490923135116832e-11"/>
      <mass value="12.085489344125179"/>
      <inertia ixx="0.161772" ixy="-0.0" ixz="0.0" iyy="0.836017" iyz="-0.0" izz="0.69521"/>
    </inertial>
    <visual>
      <origin rpy="0 0 0" xyz="-1.514695 -0.187374 0.0"/>
      <geometry>
        <mesh filename="package://ex_mm40b3_description/meshes/Holder_4.stl" scale="0.001 0.001 0.001"/>
      </geometry>
      <material name="darkgrey"/>
    </visual>
    <collision>
      <origin rpy="0 0 0" xyz="-1.514695 -0.187374 0.0"/>
      <geometry>
        <mesh filename="package://ex_mm40b3_description/meshes/Holder_4.stl" scale="0.001 0.001 0.001"/>
      </geometry>
    </collision>
  </link>
  <link name="Fin_1">
    <inertial>
      <origin rpy="0 0 0" xyz="-0.015670038509134843 0.05105851518613127 -0.033157788278729644"/>
      <mass value="1.1914641784690367"/>
      <inertia ixx="0.003045" ixy="0.000707" ixz="-0.000459" iyy="0.003419" iyz="0.00136" izz="0.004631"/>
    </inertial>
    <visual>
      <origin rpy="0 0 0" xyz="1.561764 0.0 -0.235"/>
      <geometry>
        <mesh filename="package://ex_mm40b3_description/meshes/Fin_1.stl" scale="0.001 0.001 0.001"/>
      </geometry>
      <material name="orange"/>
    </visual>
    <collision>
      <origin rpy="0 0 0" xyz="1.561764 0.0 -0.235"/>
      <geometry>
        <mesh filename="package://ex_mm40b3_description/meshes/Fin_1.stl" scale="0.001 0.001 0.001"/>
      </geometry>
    </collision>
  </link>
  <link name="Fin_2">
    <inertial>
      <origin rpy="0 0 0" xyz="-0.015670038509135287 -0.03315778761916369 -0.05105880996392321"/>
      <mass value="1.1914641784690367"/>
      <inertia ixx="0.003045" ixy="-0.000459" ixz="-0.000707" iyy="0.004631" iyz="-0.00136" izz="0.003419"/>
    </inertial>
    <visual>
      <origin rpy="0 0 0" xyz="1.561764 -0.235 1.7e-05"/>
      <geometry>
        <mesh filename="package://ex_mm40b3_description/meshes/Fin_2.stl" scale="0.001 0.001 0.001"/>
      </geometry>
      <material name="orange"/>
    </visual>
    <collision>
      <origin rpy="0 0 0" xyz="1.561764 -0.235 1.7e-05"/>
      <geometry>
        <mesh filename="package://ex_mm40b3_description/meshes/Fin_2.stl" scale="0.001 0.001 0.001"/>
      </geometry>
    </collision>
  </link>
  <link name="Fin_3">
    <inertial>
      <origin rpy="0 0 0" xyz="-0.01567003850913551 -0.051058515375965514 0.033157786769763664"/>
      <mass value="1.1914641784690367"/>
      <inertia ixx="0.003045" ixy="-0.000707" ixz="0.000459" iyy="0.003419" iyz="0.00136" izz="0.004631"/>
    </inertial>
    <visual>
      <origin rpy="0 0 0" xyz="1.561764 0.0 0.235"/>
      <geometry>
        <mesh filename="package://ex_mm40b3_description/meshes/Fin_3.stl" scale="0.001 0.001 0.001"/>
      </geometry>
      <material name="orange"/>
    </visual>
    <collision>
      <origin rpy="0 0 0" xyz="1.561764 0.0 0.235"/>
      <geometry>
        <mesh filename="package://ex_mm40b3_description/meshes/Fin_3.stl" scale="0.001 0.001 0.001"/>
      </geometry>
    </collision>
  </link>
  <link name="Fin_4">
    <inertial>
      <origin rpy="0 0 0" xyz="-0.015670038509134843 0.03315778742932951 0.051058514526565395"/>
      <mass value="1.1914641784690367"/>
      <inertia ixx="0.003045" ixy="0.000459" ixz="0.000707" iyy="0.004631" iyz="-0.00136" izz="0.003419"/>
    </inertial>
    <visual>
      <origin rpy="0 0 0" xyz="1.561764 0.235 0.0"/>
      <geometry>
        <mesh filename="package://ex_mm40b3_description/meshes/Fin_4.stl" scale="0.001 0.001 0.001"/>
      </geometry>
      <material name="orange"/>
    </visual>
    <collision>
      <origin rpy="0 0 0" xyz="1.561764 0.235 0.0"/>
      <geometry>
        <mesh filename="package://ex_mm40b3_description/meshes/Fin_4.stl" scale="0.001 0.001 0.001"/>
      </geometry>
    </collision>
  </link>
  <joint name="fins_rev1" type="revolute">
    <origin rpy="0 0 0" xyz="-1.561764 0.0 0.18"/>
    <parent link="base_link"/>
    <child link="FinHolder_1"/>
    <axis xyz="-0.0 -0.0 1.0"/>
    <limit effort="100" lower="-0.349066" upper="0.349066" velocity="100"/>
  </joint>
  <joint name="fins_rev4" type="revolute">
    <origin rpy="0 0 0" xyz="-1.561764 -0.18 0.0"/>
    <parent link="base_link"/>
    <child link="FinHolder_4"/>
    <axis xyz="-0.0 -1.0 -0.0"/>
    <limit effort="100" lower="-0.349066" upper="0.349066" velocity="100"/>
  </joint>
  <joint name="fins_rev3" type="revolute">
    <origin rpy="0 0 0" xyz="-1.561764 0.0 -0.18"/>
    <parent link="base_link"/>
    <child link="FinHolder_3"/>
    <axis xyz="-0.0 0.0 -1.0"/>
    <limit effort="100" lower="-0.349066" upper="0.349066" velocity="100"/>
  </joint>
  <joint name="fins_rev2" type="revolute">
    <origin rpy="0 0 0" xyz="-1.561764 0.18 0.0"/>
    <parent link="base_link"/>
    <child link="FinHolder_2"/>
    <axis xyz="-0.0 1.0 0.0"/>
    <limit effort="100" lower="-0.349066" upper="0.349066" velocity="100"/>
  </joint>
  <joint name="wings_fold1" type="revolute">
    <origin rpy="0 0 0" xyz="-0.108536 0.0 0.231018"/>
    <parent link="base_link"/>
    <child link="Wing1_1"/>
    <axis xyz="1.0 -0.0 -0.0"/>
    <limit effort="100" lower="0.0" upper="2.146755" velocity="100"/>
  </joint>
  <joint name="booster_fixing" type="fixed">
    <origin rpy="0 0 0" xyz="-1.741776 0.0 0.0"/>
    <parent link="base_link"/>
    <child link="Booster_1"/>
  </joint>
  <joint name="wings_fold2" type="revolute">
    <origin rpy="0 0 0" xyz="-0.108536 0.231018 0.0"/>
    <parent link="base_link"/>
    <child link="Wing1_2"/>
    <axis xyz="1.0 0.0 -0.0"/>
    <limit effort="100" lower="0.0" upper="2.146755" velocity="100"/>
  </joint>
  <joint name="wings_fold3" type="revolute">
    <origin rpy="0 0 0" xyz="-0.108536 0.0 -0.231018"/>
    <parent link="base_link"/>
    <child link="Wing1_3"/>
    <axis xyz="1.0 0.0 -0.0"/>
    <limit effort="100" lower="0.0" upper="2.146755" velocity="100"/>
  </joint>
  <joint name="wings_fold4" type="revolute">
    <origin rpy="0 0 0" xyz="-0.108536 -0.231018 0.0"/>
    <parent link="base_link"/>
    <child link="Wing1_4"/>
    <axis xyz="1.0 -0.0 -0.0"/>
    <limit effort="100" lower="0.0" upper="2.146755" velocity="100"/>
  </joint>
  <joint name="HolderJoint1" type="fixed">
    <origin rpy="0 0 0" xyz="1.514695 0.0 0.187374"/>
    <parent link="base_link"/>
    <child link="Holder_1"/>
  </joint>
  <joint name="HolderJoint2" type="fixed">
    <origin rpy="0 0 0" xyz="1.514695 -0.187374 0.0"/>
    <parent link="base_link"/>
    <child link="Holder_2"/>
  </joint>
  <joint name="HolderJoint3" type="fixed">
    <origin rpy="0 0 0" xyz="1.514695 0.0 -0.187374"/>
    <parent link="base_link"/>
    <child link="Holder_3"/>
  </joint>
  <joint name="HolderJoint4" type="fixed">
    <origin rpy="0 0 0" xyz="1.514695 0.187374 0.0"/>
    <parent link="base_link"/>
    <child link="Holder_4"/>
  </joint>
  <joint name="fin_fold1" type="revolute">
    <origin rpy="0 0 0" xyz="0.0 0.0 0.055"/>
    <parent link="FinHolder_1"/>
    <child link="Fin_1"/>
    <axis xyz="1.0 -0.0 0.0"/>
    <limit effort="100" lower="0.0" upper="2.146755" velocity="100"/>
  </joint>
  <joint name="fin_fold2" type="revolute">
    <origin rpy="0 0 0" xyz="0.0 0.055 -1.7e-05"/>
    <parent link="FinHolder_2"/>
    <child link="Fin_2"/>
    <axis xyz="1.0 -0.0 -0.0"/>
    <limit effort="100" lower="0.0" upper="2.146755" velocity="100"/>
  </joint>
  <joint name="fin_fold3" type="revolute">
    <origin rpy="0 0 0" xyz="0.0 0.0 -0.055"/>
    <parent link="FinHolder_3"/>
    <child link="Fin_3"/>
    <axis xyz="1.0 -0.0 0.0"/>
    <limit effort="100" lower="0.0" upper="2.146755" velocity="100"/>
  </joint>
  <joint name="fin_fold4" type="revolute">
    <origin rpy="0 0 0" xyz="0.0 -0.055 0.0"/>
    <parent link="FinHolder_4"/>
    <child link="Fin_4"/>
    <axis xyz="1.0 -0.0 -0.0"/>
    <limit effort="100" lower="0.0" upper="2.146755" velocity="100"/>
  </joint>
</robot>

