<?xml version="1.0" ?>
<!-- =================================================================================== -->
<!-- |    This document was autogenerated by xacro from src/exocet_launcher_half_description/urdf/exocet_launcher_half.xacro | -->
<!-- |    EDITING THIS FILE BY HAND IS NOT RECOMMENDED                                 | -->
<!-- =================================================================================== -->
<robot name="exocet_launcher_half">
  <material name="grey">
    <color rgba="0.2 0.2 0.2 1.0"/>
  </material>
  <material name="darkgrey">
    <color rgba="0.18359375 0.30859375 0.30859375 1.000"/>
  </material>
  <material name="silver">
    <color rgba="0.700 0.700 0.700 1.000"/>
  </material>
  <material name="white">
    <color rgba="1 1 1 1"/>
  </material>
  <material name="orange">
    <color rgba="1 0.3 0.1 1"/>
  </material>
  <material name="blue">
    <color rgba="0.2 0.2 1 1"/>
  </material>
  <material name="red">
    <color rgba="0.8 0 0 1"/>
  </material>
  <material name="green">
    <color rgba="0.0 1 0.0 1"/>
  </material>
  <material name="black">
    <color rgba="0 0 0 1"/>
  </material>
  <transmission name="CupOpener_tran">
    <type>transmission_interface/SimpleTransmission</type>
    <joint name="CupOpener">
      <hardwareInterface>hardware_interface/EffortJointInterface</hardwareInterface>
    </joint>
    <actuator name="CupOpener_actr">
      <hardwareInterface>hardware_interface/EffortJointInterface</hardwareInterface>
      <mechanicalReduction>1</mechanicalReduction>
    </actuator>
  </transmission>
  <gazebo reference="base_link">
    <material>Gazebo/DarkGrey</material>
    <mu1>0.2</mu1>
    <mu2>0.2</mu2>
    <selfCollide>true</selfCollide>
    <gravity>true</gravity>
  </gazebo>
  <gazebo reference="Canister_1">
    <material>Gazebo/White</material>
    <mu1>0.2</mu1>
    <mu2>0.2</mu2>
    <selfCollide>true</selfCollide>
    <visual>
      <transparency>0.75</transparency>
    </visual>
  </gazebo>
  <!-- <gazebo reference="Cup_3">
    <material>Gazebo/Black</material>
    <mu1>0.2</mu1>
    <mu2>0.2</mu2>
    <selfCollide>true</selfCollide>
  </gazebo> -->
  <gazebo reference="Cup_1">
    <material>Gazebo/Black</material>
    <mu1>0.2</mu1>
    <mu2>0.2</mu2>
    <selfCollide>true</selfCollide>
  </gazebo>
  <gazebo reference="CanisterHolder_1">
    <material>Gazebo/Green</material>
    <mu1>0.2</mu1>
    <mu2>0.2</mu2>
    <selfCollide>true</selfCollide>
  </gazebo>
  <gazebo reference="CanisterHolder_2">
    <material>Gazebo/Green</material>
    <mu1>0.2</mu1>
    <mu2>0.2</mu2>
    <selfCollide>true</selfCollide>
  </gazebo>
  <link name="base_link">
    <inertial>
      <origin rpy="0 0 0" xyz="0.21956009217606984 4.3636388735968575e-16 0.6746334924440056"/>
      <mass value="10722.621074762288"/>
      <inertia ixx="3680.005759" ixy="0.0" ixz="-2210.827735" iyy="13504.573497" iyz="0.0" izz="12126.040929"/>
    </inertial>
    <visual>
      <origin rpy="0 0 0" xyz="0 0 0"/>
      <geometry>
        <mesh filename="package://exocet_launcher_half_description/meshes/base_link.stl" scale="0.001 0.001 0.001"/>
      </geometry>
      <material name="darkgrey"/>
    </visual>
    <collision>
      <origin rpy="0 0 0" xyz="0 0 0"/>
      <geometry>
        <mesh filename="package://exocet_launcher_half_description/meshes/base_link.stl" scale="0.001 0.001 0.001"/>
      </geometry>
    </collision>
  </link>
  <link name="Canister_1">
    <inertial>
      <origin rpy="0 0 0" xyz="-1.3455029394993274 -5.851690442643435e-12 -0.6889676216530494"/>
      <mass value="804.672730610412"/>
      <inertia ixx="373.324731" ixy="-0.0" ixz="-924.286606" iyy="2888.906844" iyz="-0.0" izz="2576.368498"/>
    </inertial>
    <visual>
      <origin rpy="0 0 0" xyz="-1.262326 0.0 -2.249618"/>
      <geometry>
        <mesh filename="package://exocet_launcher_half_description/meshes/Canister_1.stl" scale="0.001 0.001 0.001"/>
      </geometry>
      <material name="white"/>
    </visual>
    <collision>
      <origin rpy="0 0 0" xyz="-1.262326 0.0 -2.249618"/>
      <geometry>
        <mesh filename="package://exocet_launcher_half_description/meshes/Canister_1.stl" scale="0.001 0.001 0.001"/>
      </geometry>
    </collision>
  </link>
  <link name="Cup_3">
    <inertial>
      <origin rpy="0 0 0" xyz="-0.10791790928581646 -8.207033013996926e-09 0.281244501140661"/>
      <mass value="124.35780308588551"/>
      <inertia ixx="5.91815" ixy="0.0" ixz="0.997121" iyy="3.153552" iyz="0.0" izz="3.54169"/>
    </inertial>
    <visual>
      <origin rpy="0 0 0" xyz="-2.805247 0.0 -2.491208"/>
      <geometry>
        <mesh filename="package://exocet_launcher_half_description/meshes/Cup_3.stl" scale="0.001 0.001 0.001"/>
      </geometry>
      <material name="black"/>
    </visual>
    <collision>
      <origin rpy="0 0 0" xyz="-2.805247 0.0 -2.491208"/>
      <geometry>
        <mesh filename="package://exocet_launcher_half_description/meshes/Cup_3.stl" scale="0.001 0.001 0.001"/>
      </geometry>
    </collision>
  </link>
  <link name="Cup_1">
    <inertial>
      <origin rpy="0 0 0" xyz="0.1876428588086605 8.207050409553099e-09 -0.6865610652939461"/>
      <mass value="124.35780308588551"/>
      <inertia ixx="5.918226" ixy="0.0" ixz="0.99703" iyy="3.153552" iyz="-0.0" izz="3.541614"/>
    </inertial>
    <visual>
      <origin rpy="0 0 0" xyz="3.177629 -0.0 -1.389734"/>
      <geometry>
        <mesh filename="package://exocet_launcher_half_description/meshes/Cup_1.stl" scale="0.001 0.001 0.001"/>
      </geometry>
      <material name="black"/>
    </visual>
    <collision>
      <origin rpy="0 0 0" xyz="3.177629 -0.0 -1.389734"/>
      <geometry>
        <mesh filename="package://exocet_launcher_half_description/meshes/Cup_1.stl" scale="0.001 0.001 0.001"/>
      </geometry>
    </collision>
  </link>
  <link name="CanisterHolder_1">
    <inertial>
      <origin rpy="0 0 0" xyz="-0.05951337321479344 1.4715522383126382e-16 0.16351174115532052"/>
      <mass value="335.0395971576902"/>
      <inertia ixx="43.686085" ixy="0.0" ixz="-3.25077" iyy="22.365267" iyz="0.0" izz="51.43432"/>
    </inertial>
    <visual>
      <origin rpy="0 0 0" xyz="1.419944 0.0 -0.847681"/>
      <geometry>
        <mesh filename="package://exocet_launcher_half_description/meshes/CanisterHolder_1.stl" scale="0.001 0.001 0.001"/>
      </geometry>
      <material name="green"/>
    </visual>
    <collision>
      <origin rpy="0 0 0" xyz="1.419944 0.0 -0.847681"/>
      <geometry>
        <mesh filename="package://exocet_launcher_half_description/meshes/CanisterHolder_1.stl" scale="0.001 0.001 0.001"/>
      </geometry>
    </collision>
  </link>
  <link name="CanisterHolder_2">
    <inertial>
      <origin rpy="0 0 0" xyz="-0.05951351085707057 1.4715522383126382e-16 0.16351217113232974"/>
      <mass value="335.0395971576902"/>
      <inertia ixx="43.686085" ixy="0.0" ixz="-3.25077" iyy="22.365267" iyz="0.0" izz="51.43432"/>
    </inertial>
    <visual>
      <origin rpy="0 0 0" xyz="-1.399134 0.0 -1.873741"/>
      <geometry>
        <mesh filename="package://exocet_launcher_half_description/meshes/CanisterHolder_2.stl" scale="0.001 0.001 0.001"/>
      </geometry>
      <material name="green"/>
    </visual>
    <collision>
      <origin rpy="0 0 0" xyz="-1.399134 0.0 -1.873741"/>
      <geometry>
        <mesh filename="package://exocet_launcher_half_description/meshes/CanisterHolder_2.stl" scale="0.001 0.001 0.001"/>
      </geometry>
    </collision>
  </link>
  <joint name="CanisterToHolder2" type="fixed">
    <origin rpy="0 0 0" xyz="-0.136808 0.0 0.375877"/>
    <parent link="CanisterHolder_2"/>
    <child link="Canister_1"/>
  </joint>
  <joint name="CupOpener" type="revolute">
    <origin rpy="0 0 0" xyz="1.542921 0.0 0.24159"/>
    <parent link="Canister_1"/>
    <child link="Cup_3"/>
    <axis xyz="0.0 1.0 0.0"/>
    <limit effort="100" lower="0.0" upper="4.712389" velocity="100"/>
  </joint>
  <joint name="CupCloser" type="fixed">
    <origin rpy="0 0 0" xyz="-4.439955 0.0 -0.859884"/>
    <parent link="Canister_1"/>
    <child link="Cup_1"/>
  </joint>
  <joint name="BaseToHolder1" type="fixed">
    <origin rpy="0 0 0" xyz="-1.419944 0.0 0.847681"/>
    <parent link="base_link"/>
    <child link="CanisterHolder_1"/>
  </joint>
  <joint name="BaseToHolder2" type="fixed">
    <origin rpy="0 0 0" xyz="1.399134 0.0 1.873741"/>
    <parent link="base_link"/>
    <child link="CanisterHolder_2"/>
  </joint>
</robot>
