<sdf version='1.7'>
  <model name='model_missile'>
    <link name='base_link'>
      <inertial>
        <pose>-0 -0 -0 0 -0 0</pose>
        <mass>562.768</mass>
        <inertia>
          <ixx>12.0787</ixx>
          <ixy>0</ixy>
          <ixz>0</ixz>
          <iyy>817.099</iyy>
          <iyz>0</iyz>
          <izz>817.099</izz>
        </inertia>
      </inertial>
      <collision name='base_link_collision'>
        <pose>0 0 0 0 -0 0</pose>
        <geometry>
          <mesh>
            <scale>0.001 0.001 0.001</scale>
            <uri>model://model_missile_description/meshes/base_link.stl</uri>
          </mesh>
        </geometry>
        <surface>
          <contact>
            <ode/>
          </contact>
          <friction>
            <ode>
              <mu>0.2</mu>
              <mu2>0.2</mu2>
            </ode>
          </friction>
        </surface>
      </collision>
      <visual name='base_link_visual'>
        <pose>0 0 0 0 -0 0</pose>
        <geometry>
          <mesh>
            <scale>0.001 0.001 0.001</scale>
            <uri>model://model_missile_description/meshes/base_link.stl</uri>
          </mesh>
        </geometry>
        <plugin name='LiftDragVisual' filename='libMultiplevectorVisual.so'>
          <topic_name vector_size='5'>AeroVectors</topic_name>
        </plugin>
        <plugin name='VectoredThrustVisual' filename='libForceVisual.so'>
          <topic_name>thrust_visual</topic_name>
          <color>Gazebo/Green</color>
        </plugin>
        <material>
          <script>
            <name>Gazebo/White</name>
            <uri>file://media/materials/scripts/gazebo.material</uri>
          </script>
        </material>
      </visual>
      <self_collide>1</self_collide>
      <gravity>1</gravity>
      <sensor name='camera_top_side' type='camera'>
        <pose>-3.2 0 1 0 0.5236 0</pose>
        <camera>
          <horizontal_fov>1.347</horizontal_fov>
          <image>
            <width>640</width>
            <height>480</height>
          </image>
          <clip>
            <near>0.1</near>
            <far>100</far>
          </clip>
        </camera>
        <always_on>1</always_on>
        <update_rate>30</update_rate>
      </sensor>
      <sensor name='camera_deflection' type='camera'>
        <pose>-1 -1 0 0 -0 2.3562</pose>
        <camera>
          <horizontal_fov>1.347</horizontal_fov>
          <image>
            <width>640</width>
            <height>480</height>
          </image>
          <clip>
            <near>0.1</near>
            <far>1000</far>
          </clip>
        </camera>
        <always_on>1</always_on>
        <update_rate>30</update_rate>
      </sensor>
    </link>
    <joint name='fins_rev1' type='revolute'>
      <pose relative_to='base_link'>-1.70084 0.127279 0.127279 0 -0 0</pose>
      <parent>base_link</parent>
      <child>FinHolder_1</child>
      <axis>
        <xyz>0 0.707107 0.707107</xyz>
        <limit>
          <lower>-0.349066</lower>
          <upper>0.349066</upper>
          <effort>100</effort>
          <velocity>100</velocity>
        </limit>
        <dynamics>
          <spring_reference>0</spring_reference>
          <spring_stiffness>0</spring_stiffness>
        </dynamics>
      </axis>
    </joint>
    <link name='FinHolder_1'>
      <pose relative_to='fins_rev1'>0 0 0 0 -0 0</pose>
      <inertial>
        <pose>0.01199 0.024895 0.024891 0 -0 0</pose>
        <mass>0.7</mass>
        <inertia>
          <ixx>0.00025</ixx>
          <ixy>3e-05</ixy>
          <ixz>3e-05</ixz>
          <iyy>0.004649</iyy>
          <iyz>-9.8e-05</iyz>
          <izz>0.004649</izz>
        </inertia>
      </inertial>
      <collision name='FinHolder_1_collision'>
        <pose>1.70084 -0.127279 -0.127279 0 -0 0</pose>
        <geometry>
          <mesh>
            <scale>0.001 0.001 0.001</scale>
            <uri>model://model_missile_description/meshes/FinHolder_1.stl</uri>
          </mesh>
        </geometry>
        <surface>
          <contact>
            <ode/>
          </contact>
          <friction>
            <ode>
              <mu>0.2</mu>
              <mu2>0.2</mu2>
            </ode>
          </friction>
        </surface>
      </collision>
      <visual name='FinHolder_1_visual'>
        <pose>1.70084 -0.127279 -0.127279 0 -0 0</pose>
        <geometry>
          <mesh>
            <scale>0.001 0.001 0.001</scale>
            <uri>model://model_missile_description/meshes/FinHolder_1.stl</uri>
          </mesh>
        </geometry>
        <material>
          <script>
            <name>Gazebo/Blue</name>
            <uri>file://media/materials/scripts/gazebo.material</uri>
          </script>
        </material>
      </visual>
      <self_collide>1</self_collide>
    </link>
    <joint name='fin_fold1' type='revolute'>
      <pose relative_to='FinHolder_1'>0 0.038891 0.038891 0 -0 0</pose>
      <parent>FinHolder_1</parent>
      <child>Fin_1</child>
      <axis>
        <xyz>1 0 0</xyz>
        <limit>
          <lower>0</lower>
          <upper>2.14676</upper>
          <effort>100</effort>
          <velocity>100</velocity>
        </limit>
        <dynamics>
          <spring_reference>0</spring_reference>
          <spring_stiffness>0</spring_stiffness>
        </dynamics>
      </axis>
    </joint>
    <link name='Fin_1'>
      <pose relative_to='fin_fold1'>0 0 0 0 -0 0</pose>
      <inertial>
        <pose>-0.014318 0.061397 0.061397 0 -0 0</pose>
        <mass>1.5</mass>
        <inertia>
          <ixx>0.006929</ixx>
          <ixy>0.000899</ixy>
          <ixz>0.000899</ixz>
          <iyy>0.007262</iyy>
          <iyz>-0.003432</iyz>
          <izz>0.007262</izz>
        </inertia>
      </inertial>
      <collision name='Fin_1_collision'>
        <pose>1.70084 -0.16617 -0.16617 0 -0 0</pose>
        <geometry>
          <mesh>
            <scale>0.001 0.001 0.001</scale>
            <uri>model://model_missile_description/meshes/Fin_1.stl</uri>
          </mesh>
        </geometry>
        <surface>
          <contact>
            <ode/>
          </contact>
          <friction>
            <ode>
              <mu>0.2</mu>
              <mu2>0.2</mu2>
            </ode>
          </friction>
        </surface>
      </collision>
      <visual name='Fin_1_visual'>
        <pose>1.70084 -0.16617 -0.16617 0 -0 0</pose>
        <geometry>
          <mesh>
            <scale>0.001 0.001 0.001</scale>
            <uri>model://model_missile_description/meshes/Fin_1.stl</uri>
          </mesh>
        </geometry>
        <material>
          <script>
            <name>Gazebo/Orange</name>
            <uri>file://media/materials/scripts/gazebo.material</uri>
          </script>
        </material>
      </visual>
      <self_collide>1</self_collide>
    </link>
    <joint name='fins_rev2' type='revolute'>
      <pose relative_to='base_link'>-1.70084 0.127279 -0.127279 0 -0 0</pose>
      <parent>base_link</parent>
      <child>FinHolder_2</child>
      <axis>
        <xyz>0 0.707107 -0.707107</xyz>
        <limit>
          <lower>-0.349066</lower>
          <upper>0.349066</upper>
          <effort>100</effort>
          <velocity>100</velocity>
        </limit>
        <dynamics>
          <spring_reference>0</spring_reference>
          <spring_stiffness>0</spring_stiffness>
        </dynamics>
      </axis>
    </joint>
    <link name='FinHolder_2'>
      <pose relative_to='fins_rev2'>0 0 0 0 -0 0</pose>
      <inertial>
        <pose>0.01199 0.024891 -0.024895 0 -0 0</pose>
        <mass>0.7</mass>
        <inertia>
          <ixx>0.00025</ixx>
          <ixy>3e-05</ixy>
          <ixz>-3e-05</ixz>
          <iyy>0.004649</iyy>
          <iyz>9.8e-05</iyz>
          <izz>0.004649</izz>
        </inertia>
      </inertial>
      <collision name='FinHolder_2_collision'>
        <pose>1.70084 -0.127279 0.127279 0 -0 0</pose>
        <geometry>
          <mesh>
            <scale>0.001 0.001 0.001</scale>
            <uri>model://model_missile_description/meshes/FinHolder_2.stl</uri>
          </mesh>
        </geometry>
        <surface>
          <contact>
            <ode/>
          </contact>
          <friction>
            <ode>
              <mu>0.2</mu>
              <mu2>0.2</mu2>
            </ode>
          </friction>
        </surface>
      </collision>
      <visual name='FinHolder_2_visual'>
        <pose>1.70084 -0.127279 0.127279 0 -0 0</pose>
        <geometry>
          <mesh>
            <scale>0.001 0.001 0.001</scale>
            <uri>model://model_missile_description/meshes/FinHolder_2.stl</uri>
          </mesh>
        </geometry>
        <material>
          <script>
            <name>Gazebo/Blue</name>
            <uri>file://media/materials/scripts/gazebo.material</uri>
          </script>
        </material>
      </visual>
      <self_collide>1</self_collide>
    </link>
    <joint name='fin_fold2' type='revolute'>
      <pose relative_to='FinHolder_2'>0 0.038879 -0.038903 0 -0 0</pose>
      <parent>FinHolder_2</parent>
      <child>Fin_2</child>
      <axis>
        <xyz>1 0 0</xyz>
        <limit>
          <lower>0</lower>
          <upper>2.14676</upper>
          <effort>100</effort>
          <velocity>100</velocity>
        </limit>
        <dynamics>
          <spring_reference>0</spring_reference>
          <spring_stiffness>0</spring_stiffness>
        </dynamics>
      </axis>
    </joint>
    <link name='Fin_2'>
      <pose relative_to='fin_fold2'>0 0 0 0 -0 0</pose>
      <inertial>
        <pose>-0.014318 0.061396 -0.061397 0 -0 0</pose>
        <mass>1.5</mass>
        <inertia>
          <ixx>0.006929</ixx>
          <ixy>0.000899</ixy>
          <ixz>-0.000899</ixz>
          <iyy>0.007262</iyy>
          <iyz>0.003432</iyz>
          <izz>0.007262</izz>
        </inertia>
      </inertial>
      <collision name='Fin_2_collision'>
        <pose>1.70084 -0.166158 0.166182 0 -0 0</pose>
        <geometry>
          <mesh>
            <scale>0.001 0.001 0.001</scale>
            <uri>model://model_missile_description/meshes/Fin_2.stl</uri>
          </mesh>
        </geometry>
        <surface>
          <contact>
            <ode/>
          </contact>
          <friction>
            <ode>
              <mu>0.2</mu>
              <mu2>0.2</mu2>
            </ode>
          </friction>
        </surface>
      </collision>
      <visual name='Fin_2_visual'>
        <pose>1.70084 -0.166158 0.166182 0 -0 0</pose>
        <geometry>
          <mesh>
            <scale>0.001 0.001 0.001</scale>
            <uri>model://model_missile_description/meshes/Fin_2.stl</uri>
          </mesh>
        </geometry>
        <material>
          <script>
            <name>Gazebo/Orange</name>
            <uri>file://media/materials/scripts/gazebo.material</uri>
          </script>
        </material>
      </visual>
      <self_collide>1</self_collide>
    </link>
    <joint name='fins_rev3' type='revolute'>
      <pose relative_to='base_link'>-1.70084 -0.127279 -0.127279 0 -0 0</pose>
      <parent>base_link</parent>
      <child>FinHolder_3</child>
      <axis>
        <xyz>0 -0.707107 -0.707107</xyz>
        <limit>
          <lower>-0.349066</lower>
          <upper>0.349066</upper>
          <effort>100</effort>
          <velocity>100</velocity>
        </limit>
        <dynamics>
          <spring_reference>0</spring_reference>
          <spring_stiffness>0</spring_stiffness>
        </dynamics>
      </axis>
    </joint>
    <link name='FinHolder_3'>
      <pose relative_to='fins_rev3'>0 0 0 0 -0 0</pose>
      <inertial>
        <pose>0.01199 -0.024895 -0.024891 0 -0 0</pose>
        <mass>0.7</mass>
        <inertia>
          <ixx>0.00025</ixx>
          <ixy>-3e-05</ixy>
          <ixz>-3e-05</ixz>
          <iyy>0.004649</iyy>
          <iyz>-9.8e-05</iyz>
          <izz>0.004649</izz>
        </inertia>
      </inertial>
      <collision name='FinHolder_3_collision'>
        <pose>1.70084 0.127279 0.127279 0 -0 0</pose>
        <geometry>
          <mesh>
            <scale>0.001 0.001 0.001</scale>
            <uri>model://model_missile_description/meshes/FinHolder_3.stl</uri>
          </mesh>
        </geometry>
        <surface>
          <contact>
            <ode/>
          </contact>
          <friction>
            <ode>
              <mu>0.2</mu>
              <mu2>0.2</mu2>
            </ode>
          </friction>
        </surface>
      </collision>
      <visual name='FinHolder_3_visual'>
        <pose>1.70084 0.127279 0.127279 0 -0 0</pose>
        <geometry>
          <mesh>
            <scale>0.001 0.001 0.001</scale>
            <uri>model://model_missile_description/meshes/FinHolder_3.stl</uri>
          </mesh>
        </geometry>
        <material>
          <script>
            <name>Gazebo/Blue</name>
            <uri>file://media/materials/scripts/gazebo.material</uri>
          </script>
        </material>
      </visual>
      <self_collide>1</self_collide>
    </link>
    <joint name='fin_fold3' type='revolute'>
      <pose relative_to='FinHolder_3'>0 -0.038891 -0.038891 0 -0 0</pose>
      <parent>FinHolder_3</parent>
      <child>Fin_3</child>
      <axis>
        <xyz>1 0 0</xyz>
        <limit>
          <lower>0</lower>
          <upper>2.14676</upper>
          <effort>100</effort>
          <velocity>100</velocity>
        </limit>
        <dynamics>
          <spring_reference>0</spring_reference>
          <spring_stiffness>0</spring_stiffness>
        </dynamics>
      </axis>
    </joint>
    <link name='Fin_3'>
      <pose relative_to='fin_fold3'>0 0 0 0 -0 0</pose>
      <inertial>
        <pose>-0.014318 -0.061397 -0.061397 0 -0 0</pose>
        <mass>1.5</mass>
        <inertia>
          <ixx>0.006929</ixx>
          <ixy>-0.000899</ixy>
          <ixz>-0.000899</ixz>
          <iyy>0.007262</iyy>
          <iyz>-0.003432</iyz>
          <izz>0.007262</izz>
        </inertia>
      </inertial>
      <collision name='Fin_3_collision'>
        <pose>1.70084 0.16617 0.16617 0 -0 0</pose>
        <geometry>
          <mesh>
            <scale>0.001 0.001 0.001</scale>
            <uri>model://model_missile_description/meshes/Fin_3.stl</uri>
          </mesh>
        </geometry>
        <surface>
          <contact>
            <ode/>
          </contact>
          <friction>
            <ode>
              <mu>0.2</mu>
              <mu2>0.2</mu2>
            </ode>
          </friction>
        </surface>
      </collision>
      <visual name='Fin_3_visual'>
        <pose>1.70084 0.16617 0.16617 0 -0 0</pose>
        <geometry>
          <mesh>
            <scale>0.001 0.001 0.001</scale>
            <uri>model://model_missile_description/meshes/Fin_3.stl</uri>
          </mesh>
        </geometry>
        <material>
          <script>
            <name>Gazebo/Orange</name>
            <uri>file://media/materials/scripts/gazebo.material</uri>
          </script>
        </material>
      </visual>
      <self_collide>1</self_collide>
    </link>
    <joint name='fins_rev4' type='revolute'>
      <pose relative_to='base_link'>-1.70084 -0.127279 0.127279 0 -0 0</pose>
      <parent>base_link</parent>
      <child>FinHolder_4</child>
      <axis>
        <xyz>0 -0.707107 0.707107</xyz>
        <limit>
          <lower>-0.349066</lower>
          <upper>0.349066</upper>
          <effort>100</effort>
          <velocity>100</velocity>
        </limit>
        <dynamics>
          <spring_reference>0</spring_reference>
          <spring_stiffness>0</spring_stiffness>
        </dynamics>
      </axis>
    </joint>
    <link name='FinHolder_4'>
      <pose relative_to='fins_rev4'>0 0 0 0 -0 0</pose>
      <inertial>
        <pose>0.01199 -0.024891 0.024895 0 -0 0</pose>
        <mass>0.7</mass>
        <inertia>
          <ixx>0.00025</ixx>
          <ixy>-3e-05</ixy>
          <ixz>3e-05</ixz>
          <iyy>0.004649</iyy>
          <iyz>9.8e-05</iyz>
          <izz>0.004649</izz>
        </inertia>
      </inertial>
      <collision name='FinHolder_4_collision'>
        <pose>1.70084 0.127279 -0.127279 0 -0 0</pose>
        <geometry>
          <mesh>
            <scale>0.001 0.001 0.001</scale>
            <uri>model://model_missile_description/meshes/FinHolder_4.stl</uri>
          </mesh>
        </geometry>
        <surface>
          <contact>
            <ode/>
          </contact>
          <friction>
            <ode>
              <mu>0.2</mu>
              <mu2>0.2</mu2>
            </ode>
          </friction>
        </surface>
      </collision>
      <visual name='FinHolder_4_visual'>
        <pose>1.70084 0.127279 -0.127279 0 -0 0</pose>
        <geometry>
          <mesh>
            <scale>0.001 0.001 0.001</scale>
            <uri>model://model_missile_description/meshes/FinHolder_4.stl</uri>
          </mesh>
        </geometry>
        <material>
          <script>
            <name>Gazebo/Blue</name>
            <uri>file://media/materials/scripts/gazebo.material</uri>
          </script>
        </material>
      </visual>
      <self_collide>1</self_collide>
    </link>
    <joint name='fin_fold4' type='revolute'>
      <pose relative_to='FinHolder_4'>0 -0.038891 0.038891 0 -0 0</pose>
      <parent>FinHolder_4</parent>
      <child>Fin_4</child>
      <axis>
        <xyz>1 0 0</xyz>
        <limit>
          <lower>0</lower>
          <upper>2.14676</upper>
          <effort>100</effort>
          <velocity>100</velocity>
        </limit>
        <dynamics>
          <spring_reference>0</spring_reference>
          <spring_stiffness>0</spring_stiffness>
        </dynamics>
      </axis>
    </joint>
    <link name='Fin_4'>
      <pose relative_to='fin_fold4'>0 0 0 0 -0 0</pose>
      <inertial>
        <pose>-0.014318 -0.061397 0.061397 0 -0 0</pose>
        <mass>1.5</mass>
        <inertia>
          <ixx>0.006929</ixx>
          <ixy>-0.000899</ixy>
          <ixz>0.000899</ixz>
          <iyy>0.007262</iyy>
          <iyz>0.003432</iyz>
          <izz>0.007262</izz>
        </inertia>
      </inertial>
      <collision name='Fin_4_collision'>
        <pose>1.70084 0.16617 -0.16617 0 -0 0</pose>
        <geometry>
          <mesh>
            <scale>0.001 0.001 0.001</scale>
            <uri>model://model_missile_description/meshes/Fin_4.stl</uri>
          </mesh>
        </geometry>
        <surface>
          <contact>
            <ode/>
          </contact>
          <friction>
            <ode>
              <mu>0.2</mu>
              <mu2>0.2</mu2>
            </ode>
          </friction>
        </surface>
      </collision>
      <visual name='Fin_4_visual'>
        <pose>1.70084 0.16617 -0.16617 0 -0 0</pose>
        <geometry>
          <mesh>
            <scale>0.001 0.001 0.001</scale>
            <uri>model://model_missile_description/meshes/Fin_4.stl</uri>
          </mesh>
        </geometry>
        <material>
          <script>
            <name>Gazebo/Orange</name>
            <uri>file://media/materials/scripts/gazebo.material</uri>
          </script>
        </material>
      </visual>
      <self_collide>1</self_collide>
    </link>
    <joint name='wings_fold1' type='revolute'>
      <pose relative_to='base_link'>-0.380856 0.163355 0.163355 0 -0 0</pose>
      <parent>base_link</parent>
      <child>Wing1_1</child>
      <axis>
        <xyz>1 0 0</xyz>
        <limit>
          <lower>0</lower>
          <upper>2.14676</upper>
          <effort>100</effort>
          <velocity>100</velocity>
        </limit>
        <dynamics>
          <spring_reference>0</spring_reference>
          <spring_stiffness>0</spring_stiffness>
        </dynamics>
      </axis>
    </joint>
    <link name='Wing1_1'>
      <pose relative_to='wings_fold1'>0 0 0 0 -0 0</pose>
      <inertial>
        <pose>-0.031208 0.071282 0.071282 0 -0 0</pose>
        <mass>9.29998</mass>
        <inertia>
          <ixx>0.055746</ixx>
          <ixy>0.012327</ixy>
          <ixz>0.012327</ixz>
          <iyy>0.41744</iyy>
          <iyz>-0.02758</iyz>
          <izz>0.41744</izz>
        </inertia>
      </inertial>
      <collision name='Wing1_1_collision'>
        <pose>0.380856 -0.163355 -0.163355 0 -0 0</pose>
        <geometry>
          <mesh>
            <scale>0.001 0.001 0.001</scale>
            <uri>model://model_missile_description/meshes/Wing1_1.stl</uri>
          </mesh>
        </geometry>
        <surface>
          <contact>
            <ode/>
          </contact>
          <friction>
            <ode>
              <mu>0.2</mu>
              <mu2>0.2</mu2>
            </ode>
          </friction>
        </surface>
      </collision>
      <visual name='Wing1_1_visual'>
        <pose>0.380856 -0.163355 -0.163355 0 -0 0</pose>
        <geometry>
          <mesh>
            <scale>0.001 0.001 0.001</scale>
            <uri>model://model_missile_description/meshes/Wing1_1.stl</uri>
          </mesh>
        </geometry>
        <material>
          <script>
            <name>Gazebo/Orange</name>
            <uri>file://media/materials/scripts/gazebo.material</uri>
          </script>
        </material>
      </visual>
      <self_collide>1</self_collide>
    </link>
    <joint name='wings_fold2' type='revolute'>
      <pose relative_to='base_link'>-0.380856 0.163355 -0.163355 0 -0 0</pose>
      <parent>base_link</parent>
      <child>Wing1_2</child>
      <axis>
        <xyz>1 0 0</xyz>
        <limit>
          <lower>0</lower>
          <upper>2.14676</upper>
          <effort>100</effort>
          <velocity>100</velocity>
        </limit>
        <dynamics>
          <spring_reference>0</spring_reference>
          <spring_stiffness>0</spring_stiffness>
        </dynamics>
      </axis>
    </joint>
    <link name='Wing1_2'>
      <pose relative_to='wings_fold2'>0 0 0 0 -0 0</pose>
      <inertial>
        <pose>-0.031208 0.070575 -0.070575 0 -0 0</pose>
        <mass>9.29998</mass>
        <inertia>
          <ixx>0.055746</ixx>
          <ixy>0.012327</ixy>
          <ixz>-0.012327</ixz>
          <iyy>0.41744</iyy>
          <iyz>0.02758</iyz>
          <izz>0.41744</izz>
        </inertia>
      </inertial>
      <collision name='Wing1_2_collision'>
        <pose>0.380856 -0.163355 0.163355 0 -0 0</pose>
        <geometry>
          <mesh>
            <scale>0.001 0.001 0.001</scale>
            <uri>model://model_missile_description/meshes/Wing1_2.stl</uri>
          </mesh>
        </geometry>
        <surface>
          <contact>
            <ode/>
          </contact>
          <friction>
            <ode>
              <mu>0.2</mu>
              <mu2>0.2</mu2>
            </ode>
          </friction>
        </surface>
      </collision>
      <visual name='Wing1_2_visual'>
        <pose>0.380856 -0.163355 0.163355 0 -0 0</pose>
        <geometry>
          <mesh>
            <scale>0.001 0.001 0.001</scale>
            <uri>model://model_missile_description/meshes/Wing1_2.stl</uri>
          </mesh>
        </geometry>
        <material>
          <script>
            <name>Gazebo/Orange</name>
            <uri>file://media/materials/scripts/gazebo.material</uri>
          </script>
        </material>
      </visual>
      <self_collide>1</self_collide>
    </link>
    <joint name='wings_fold3' type='revolute'>
      <pose relative_to='base_link'>-0.380856 -0.163355 -0.163355 0 -0 0</pose>
      <parent>base_link</parent>
      <child>Wing1_3</child>
      <axis>
        <xyz>1 0 0</xyz>
        <limit>
          <lower>0</lower>
          <upper>2.14676</upper>
          <effort>100</effort>
          <velocity>100</velocity>
        </limit>
        <dynamics>
          <spring_reference>0</spring_reference>
          <spring_stiffness>0</spring_stiffness>
        </dynamics>
      </axis>
    </joint>
    <link name='Wing1_3'>
      <pose relative_to='wings_fold3'>0 0 0 0 -0 0</pose>
      <inertial>
        <pose>-0.031208 -0.070575 -0.070575 0 -0 0</pose>
        <mass>9.29998</mass>
        <inertia>
          <ixx>0.055746</ixx>
          <ixy>-0.012327</ixy>
          <ixz>-0.012327</ixz>
          <iyy>0.41744</iyy>
          <iyz>-0.02758</iyz>
          <izz>0.41744</izz>
        </inertia>
      </inertial>
      <collision name='Wing1_3_collision'>
        <pose>0.380856 0.163355 0.163355 0 -0 0</pose>
        <geometry>
          <mesh>
            <scale>0.001 0.001 0.001</scale>
            <uri>model://model_missile_description/meshes/Wing1_3.stl</uri>
          </mesh>
        </geometry>
        <surface>
          <contact>
            <ode/>
          </contact>
          <friction>
            <ode>
              <mu>0.2</mu>
              <mu2>0.2</mu2>
            </ode>
          </friction>
        </surface>
      </collision>
      <visual name='Wing1_3_visual'>
        <pose>0.380856 0.163355 0.163355 0 -0 0</pose>
        <geometry>
          <mesh>
            <scale>0.001 0.001 0.001</scale>
            <uri>model://model_missile_description/meshes/Wing1_3.stl</uri>
          </mesh>
        </geometry>
        <material>
          <script>
            <name>Gazebo/Orange</name>
            <uri>file://media/materials/scripts/gazebo.material</uri>
          </script>
        </material>
      </visual>
      <self_collide>1</self_collide>
    </link>
    <joint name='wings_fold4' type='revolute'>
      <pose relative_to='base_link'>-0.380856 -0.163355 0.163355 0 -0 0</pose>
      <parent>base_link</parent>
      <child>Wing1_4</child>
      <axis>
        <xyz>1 0 0</xyz>
        <limit>
          <lower>0</lower>
          <upper>2.14676</upper>
          <effort>100</effort>
          <velocity>100</velocity>
        </limit>
        <dynamics>
          <spring_reference>0</spring_reference>
          <spring_stiffness>0</spring_stiffness>
        </dynamics>
      </axis>
    </joint>
    <link name='Wing1_4'>
      <pose relative_to='wings_fold4'>0 0 0 0 -0 0</pose>
      <inertial>
        <pose>-0.031208 -0.070575 0.070575 0 -0 0</pose>
        <mass>9.29998</mass>
        <inertia>
          <ixx>0.055746</ixx>
          <ixy>-0.012327</ixy>
          <ixz>0.012327</ixz>
          <iyy>0.41744</iyy>
          <iyz>0.02758</iyz>
          <izz>0.41744</izz>
        </inertia>
      </inertial>
      <collision name='Wing1_4_collision'>
        <pose>0.380856 0.163355 -0.163355 0 -0 0</pose>
        <geometry>
          <mesh>
            <scale>0.001 0.001 0.001</scale>
            <uri>model://model_missile_description/meshes/Wing1_4.stl</uri>
          </mesh>
        </geometry>
        <surface>
          <contact>
            <ode/>
          </contact>
          <friction>
            <ode>
              <mu>0.2</mu>
              <mu2>0.2</mu2>
            </ode>
          </friction>
        </surface>
      </collision>
      <visual name='Wing1_4_visual'>
        <pose>0.380856 0.163355 -0.163355 0 -0 0</pose>
        <geometry>
          <mesh>
            <scale>0.001 0.001 0.001</scale>
            <uri>model://model_missile_description/meshes/Wing1_4.stl</uri>
          </mesh>
        </geometry>
        <material>
          <script>
            <name>Gazebo/Orange</name>
            <uri>file://media/materials/scripts/gazebo.material</uri>
          </script>
        </material>
      </visual>
      <self_collide>1</self_collide>
    </link>
    <static>0</static>
    <plugin name='model_missile_controller' filename='libgazebo_ros_control.so'>
      <robotNamespace>model_missile_controller</robotNamespace>
      <robotSimType>gazebo_ros_control/DefaultRobotHWSim</robotSimType>
    </plugin>
    <plugin name='ThrustVectoring' filename='libThrustVectoring.so'>
      <link_name>base_link</link_name>
      <forward_dir>1 0 0</forward_dir>
      <thrust_origin>-1.880 0 0</thrust_origin>
      <robotNamespace/>
      <topic_name>thrust_visual</topic_name>
      <vector_topic>thrust_force</vector_topic>
    </plugin>
    <plugin name='FullBodyAerodynamic' filename='libAerodynamic.so'>
      <cp>-0.238 0.0 0.0</cp>
      <sref>0.096</sref>
      <lref>0.350</lref>
      <topic_name>AeroVectors</topic_name>
      <air_density>1.2041</air_density>
      <link_name>base_link</link_name>
      <robotNamespace/>
      <radial_symmetry>1/</radial_symmetry>
      <forward>1 0 0</forward>
    </plugin>
  </model>
</sdf>
