<?xml version="1.0" ?>
<!-- =================================================================================== -->
<!-- |    This document was autogenerated by xacro from urdf/model_missile.xacro       | -->
<!-- |    EDITING THIS FILE BY HAND IS NOT RECOMMENDED                                 | -->
<!-- =================================================================================== -->
<robot name="model_missile">
  <material name="grey">
    <color rgba="0.82421875 0.82421875 0.82421875 1.0"/>
  </material>
  <material name="darkgrey">
    <color rgba="0.1843137254901961 0.30980392156862746 0.30980392156862746 1.000"/>
  </material>
  <material name="silver">
    <color rgba="0.700 0.700 0.700 1.000"/>
  </material>
  <material name="white">
    <color rgba="1 1 1 1"/>
  </material>
  <material name="orange">
    <color rgba="1 0.3 0.1 1"/>
  </material>
  <material name="blue">
    <color rgba="0.2 0.2 1 1"/>
  </material>
  <material name="red">
    <color rgba="0.8 0 0 1"/>
  </material>
  <material name="green">
    <color rgba="0.0 1 0.0 1"/>
  </material>
  <material name="black">
    <color rgba="0 0 0 1"/>
  </material>
  <transmission name="fins_rev1_tran">
    <type>transmission_interface/SimpleTransmission</type>
    <joint name="fins_rev1">
      <hardwareInterface>hardware_interface/EffortJointInterface</hardwareInterface>
    </joint>
    <actuator name="fins_rev1_actr">
      <hardwareInterface>hardware_interface/EffortJointInterface</hardwareInterface>
      <mechanicalReduction>1</mechanicalReduction>
    </actuator>
  </transmission>
  <transmission name="fins_rev4_tran">
    <type>transmission_interface/SimpleTransmission</type>
    <joint name="fins_rev4">
      <hardwareInterface>hardware_interface/EffortJointInterface</hardwareInterface>
    </joint>
    <actuator name="fins_rev4_actr">
      <hardwareInterface>hardware_interface/EffortJointInterface</hardwareInterface>
      <mechanicalReduction>1</mechanicalReduction>
    </actuator>
  </transmission>
  <transmission name="fins_rev3_tran">
    <type>transmission_interface/SimpleTransmission</type>
    <joint name="fins_rev3">
      <hardwareInterface>hardware_interface/EffortJointInterface</hardwareInterface>
    </joint>
    <actuator name="fins_rev3_actr">
      <hardwareInterface>hardware_interface/EffortJointInterface</hardwareInterface>
      <mechanicalReduction>1</mechanicalReduction>
    </actuator>
  </transmission>
  <transmission name="fins_rev2_tran">
    <type>transmission_interface/SimpleTransmission</type>
    <joint name="fins_rev2">
      <hardwareInterface>hardware_interface/EffortJointInterface</hardwareInterface>
    </joint>
    <actuator name="fins_rev2_actr">
      <hardwareInterface>hardware_interface/EffortJointInterface</hardwareInterface>
      <mechanicalReduction>1</mechanicalReduction>
    </actuator>
  </transmission>
  <transmission name="wings_fold1_tran">
    <type>transmission_interface/SimpleTransmission</type>
    <joint name="wings_fold1">
      <hardwareInterface>hardware_interface/EffortJointInterface</hardwareInterface>
    </joint>
    <actuator name="wings_fold1_actr">
      <hardwareInterface>hardware_interface/EffortJointInterface</hardwareInterface>
      <mechanicalReduction>1</mechanicalReduction>
    </actuator>
  </transmission>
  <transmission name="wings_fold2_tran">
    <type>transmission_interface/SimpleTransmission</type>
    <joint name="wings_fold2">
      <hardwareInterface>hardware_interface/EffortJointInterface</hardwareInterface>
    </joint>
    <actuator name="wings_fold2_actr">
      <hardwareInterface>hardware_interface/EffortJointInterface</hardwareInterface>
      <mechanicalReduction>1</mechanicalReduction>
    </actuator>
  </transmission>
  <transmission name="wings_fold3_tran">
    <type>transmission_interface/SimpleTransmission</type>
    <joint name="wings_fold3">
      <hardwareInterface>hardware_interface/EffortJointInterface</hardwareInterface>
    </joint>
    <actuator name="wings_fold3_actr">
      <hardwareInterface>hardware_interface/EffortJointInterface</hardwareInterface>
      <mechanicalReduction>1</mechanicalReduction>
    </actuator>
  </transmission>
  <transmission name="wings_fold4_tran">
    <type>transmission_interface/SimpleTransmission</type>
    <joint name="wings_fold4">
      <hardwareInterface>hardware_interface/EffortJointInterface</hardwareInterface>
    </joint>
    <actuator name="wings_fold4_actr">
      <hardwareInterface>hardware_interface/EffortJointInterface</hardwareInterface>
      <mechanicalReduction>1</mechanicalReduction>
    </actuator>
  </transmission>
  <transmission name="fin_fold1_tran">
    <type>transmission_interface/SimpleTransmission</type>
    <joint name="fin_fold1">
      <hardwareInterface>hardware_interface/EffortJointInterface</hardwareInterface>
    </joint>
    <actuator name="fin_fold1_actr">
      <hardwareInterface>hardware_interface/EffortJointInterface</hardwareInterface>
      <mechanicalReduction>1</mechanicalReduction>
    </actuator>
  </transmission>
  <transmission name="fin_fold2_tran">
    <type>transmission_interface/SimpleTransmission</type>
    <joint name="fin_fold2">
      <hardwareInterface>hardware_interface/EffortJointInterface</hardwareInterface>
    </joint>
    <actuator name="fin_fold2_actr">
      <hardwareInterface>hardware_interface/EffortJointInterface</hardwareInterface>
      <mechanicalReduction>1</mechanicalReduction>
    </actuator>
  </transmission>
  <transmission name="fin_fold3_tran">
    <type>transmission_interface/SimpleTransmission</type>
    <joint name="fin_fold3">
      <hardwareInterface>hardware_interface/EffortJointInterface</hardwareInterface>
    </joint>
    <actuator name="fin_fold3_actr">
      <hardwareInterface>hardware_interface/EffortJointInterface</hardwareInterface>
      <mechanicalReduction>1</mechanicalReduction>
    </actuator>
  </transmission>
  <transmission name="fin_fold4_tran">
    <type>transmission_interface/SimpleTransmission</type>
    <joint name="fin_fold4">
      <hardwareInterface>hardware_interface/EffortJointInterface</hardwareInterface>
    </joint>
    <actuator name="fin_fold4_actr">
      <hardwareInterface>hardware_interface/EffortJointInterface</hardwareInterface>
      <mechanicalReduction>1</mechanicalReduction>
    </actuator>
  </transmission>
  <gazebo>
    <plugin filename="libgazebo_ros_control.so" name="model_missile_controller">
      <robotNamespace>model_missile_controller</robotNamespace>
      <robotSimType>gazebo_ros_control/DefaultRobotHWSim</robotSimType>
    </plugin>
    <plugin filename="libSimpleThruster.so" name="BoosterThrust">
      <link_name>Booster_1</link_name>
      <forward_dir>1 0 0</forward_dir>
      <thrust_origin>-0.920 0 0</thrust_origin>
      <robotNamespace/>
      <topic_name>booster_visual</topic_name>
      <thrust_topic>booster_force</thrust_topic>
    </plugin>
    <plugin filename="libThrustVectoring.so" name="ThrustVectoring">
      <link_name>base_link</link_name>
      <forward_dir>1 0 0</forward_dir>
      <thrust_origin>-1.880 0 0</thrust_origin>
      <robotNamespace/>
      <topic_name>thrust_visual</topic_name>
      <vector_topic>thrust_force</vector_topic>
    </plugin>
    <plugin filename="libAerodynamic.so" name="FullBodyAerodynamic">
      <cp>-0.238 0.0 0.0</cp>
      <sref>0.096</sref>
      <lref>0.350</lref>
      <air_density>1.2041</air_density>
      <link_name>base_link</link_name>
      <radial_symmetry>1/</radial_symmetry>
      <!-- <upward>0 0 1</upward> -->
      <forward>1 0 0</forward>
      <robotNamespace/>
      <topic_name>AeroVectors</topic_name>
      <aerodynamics axis_type="wind" case="with_booster">
        <mach_table>0.2 0.4 0.5 0.6 0.7 0.75 0.8 0.93</mach_table>
        <alpha_table>.00, 4.00, 8.00, 12.00, 16.00, 20.00, 24.00, 28.00</alpha_table>
        <mach nr="0.2">
          <cn_table>0.000, 1.037, 2.115, 3.322, 4.383, 5.449, 6.445, 7.475</cn_table>
          <cm_table>0.000, -0.222, -0.289, -0.558, -0.080, 0.688, 1.595, 2.038</cm_table>
          <ca_table>0.266, 0.249, 0.194, 0.148, 0.134, 0.160, 0.128, 0.050</ca_table>
          <cl_table>0.000, 1.017, 2.067, 3.218, 4.176, 5.066, 5.836, 6.576</cl_table>
          <cd_table>0.266, 0.321, 0.487, 0.835, 1.337, 2.014, 2.738, 3.553</cd_table>
        </mach>
        <mach nr="0.4">
          <cn_table>0.000, 1.051, 2.134, 3.337, 4.373, 5.448, 6.500, 7.626</cn_table>
          <cm_table>0.000, -0.250, -0.333, -0.604, -0.055, 0.655, 1.426, 1.835</cm_table>
          <ca_table>0.263, 0.246, 0.193, 0.147, 0.133, 0.157, 0.121, 0.037</ca_table>
          <cl_table>0.000, 1.031, 2.087, 3.233, 4.167, 5.066, 5.889, 6.716</cl_table>
          <cd_table>0.263, 0.318, 0.488, 0.838, 1.333, 2.011, 2.754, 3.613</cd_table>
        </mach>
        <mach nr="0.5">
          <cn_table>0.000, 1.070, 2.169, 3.390, 4.433, 5.517, 6.603, 7.866</cn_table>
          <cm_table>0.000, -0.276, -0.389, -0.727, -0.210, 0.446, 1.204, 1.690</cm_table>
          <ca_table>0.261, 0.243, 0.187, 0.141, 0.127, 0.152, 0.116, 0.025</ca_table>
          <cl_table>0.000, 1.051, 2.121, 3.286, 4.227, 5.132, 5.986, 6.934</cl_table>
          <cd_table>0.261, 0.317, 0.487, 0.842, 1.344, 2.030, 2.791, 3.715</cd_table>
        </mach>
        <mach nr="0.6">
          <cn_table>0.000, 1.093, 2.208, 3.444, 4.494, 5.607, 6.812, 8.206</cn_table>
          <cm_table>0.000, -0.305, -0.444, -0.825, -0.337, 0.307, 1.051, 1.581</cm_table>
          <ca_table>0.259, 0.240, 0.183, 0.135, 0.121, 0.148, 0.108, 0.011</ca_table>
          <cl_table>0.000, 1.074, 2.161, 3.341, 4.287, 5.219, 6.179, 7.240</cl_table>
          <cd_table>0.259, 0.316, 0.488, 0.848, 1.355, 2.056, 2.869, 3.862</cd_table>
        </mach>
        <mach nr="0.7">
          <cn_table>0.000, 1.101, 2.218, 3.456, 4.531, 5.736, 7.029, 8.570</cn_table>
          <cm_table>0.000, -0.320, -0.476, -0.877, -0.474, 0.203, 0.845, 1.353</cm_table>
          <ca_table>0.257, 0.238, 0.180, 0.132, 0.119, 0.144, 0.101, -0.002</ca_table>
          <cl_table>0.000, 1.081, 2.172, 3.353, 4.323, 5.341, 6.381, 7.568</cl_table>
          <cd_table>0.257, 0.314, 0.487, 0.848, 1.363, 2.097, 2.951, 4.021</cd_table>
        </mach>
        <mach nr="0.75">
          <cn_table>0.000, 1.118, 2.250, 3.503, 4.607, 5.853, 7.206, 8.818</cn_table>
          <cm_table>0.000, -0.345, -0.528, -0.974, -0.628, 0.040, 0.636, 1.106</cm_table>
          <ca_table>0.256, 0.236, 0.178, 0.129, 0.116, 0.141, 0.097, -0.009</ca_table>
          <cl_table>0.000, 1.099, 2.204, 3.399, 4.397, 5.452, 6.543, 7.790</cl_table>
          <cd_table>0.256, 0.314, 0.489, 0.855, 1.382, 2.135, 3.020, 4.132</cd_table>
        </mach>
        <mach nr="0.8">
          <cn_table>0.000, 1.148, 2.324, 3.656, 4.850, 6.177, 7.617, 9.288</cn_table>
          <cm_table>0.000, -0.366, -0.575, -1.115, -0.810, -0.218, 0.398, 0.701</cm_table>
          <ca_table>0.271, 0.251, 0.189, 0.137, 0.123, 0.151, 0.107, -0.001</ca_table>
          <cl_table>0.000, 1.128, 2.275, 3.547, 4.628, 5.753, 6.915, 8.201</cl_table>
          <cd_table>0.271, 0.330, 0.510, 0.894, 1.455, 2.255, 3.196, 4.359</cd_table>
        </mach>
        <mach nr="0.93">
          <cn_table>0.000, 1.254, 2.540, 4.024, 5.393, 6.903, 8.553, 10.586</cn_table>
          <cm_table>0.000, -0.458, -0.795, -1.620,-1.509, -0.989, -0.510, -0.389</cm_table>
          <ca_table>0.458, 0.455, 0.440, 0.421, 0.399, 0.370, 0.294, 0.147</ca_table>
          <cl_table>0.000, 1.219, 2.454, 3.848, 5.074, 6.360, 7.694, 9.278</cl_table>
          <cd_table>0.458, 0.541, 0.790, 1.248, 1.870, 2.709, 3.748, 5.100</cd_table>
        </mach>
      </aerodynamics>
      <aerodynamics axis_type="wind" case="boosterless">
        <mach_table>0.2, 0.4, 0.5, 0.6, 0.7, 0.75, 0.8, 0.93</mach_table>
        <alpha_table>.00, 4.00, 8.00, 12.00, 16.00, 20.00, 24.00, 28.00</alpha_table>
        <mach nr="0.2">
          <cn_table>0.000, 1.013, 2.044, 3.181, 4.150, 5.103, 5.967, 6.846</cn_table>
          <cm_table>0.000, -0.041, 0.192, 0.339, 1.345, 2.745, 4.378, 5.630</cm_table>
          <ca_table>0.239, 0.221, 0.167, 0.122, 0.110, 0.141, 0.118, 0.056</ca_table>
          <cl_table>0.000, 0.995, 2.001, 3.086, 3.959, 4.747, 5.403, 6.019</cl_table>
          <cd_table>0.239, 0.292, 0.450, 0.780, 1.249, 1.878, 2.535, 3.264</cd_table>
        </mach>
        <mach nr="0.4">
          <cn_table>0.000, 1.027, 2.062, 3.192, 4.132, 5.086, 5.996, 6.957</cn_table>
          <cm_table>0.000, -0.068, 0.153, 0.311, 1.412, 2.792, 4.345, 5.636</cm_table>
          <ca_table>0.236, 0.219, 0.166, 0.122, 0.110, 0.138, 0.112, 0.046</ca_table>
          <cl_table>0.000, 1.009, 2.019, 3.097, 3.941, 4.732, 5.432, 6.121</cl_table>
          <cd_table>0.236, 0.290, 0.451, 0.783, 1.244, 1.869, 2.541, 3.306</cd_table>
        </mach>
        <mach nr="0.5">
          <cn_table>0.000, 1.046, 2.096, 3.243, 4.188, 5.148, 6.084, 7.158</cn_table>
          <cm_table>0.000, -0.094, 0.100, 0.197, 1.278, 2.623, 4.198, 5.696</cm_table>
          <ca_table>0.234, 0.216, 0.161, 0.115, 0.103, 0.134, 0.108, 0.036</ca_table>
          <cl_table>0.000, 1.028, 2.053, 3.149, 3.997, 4.792, 5.515, 6.304</cl_table>
          <cd_table>0.234, 0.289, 0.451, 0.787, 1.254, 1.886, 2.573, 3.392</cd_table>
        </mach>
        <mach nr="0.6">
          <cn_table>0.000, 1.069, 2.135, 3.296, 4.245, 5.229, 6.262, 7.452</cn_table>
          <cm_table>0.000, -0.123, 0.047, 0.108, 1.172, 2.533, 4.201, 5.827</cm_table>
          <ca_table>0.232, 0.213, 0.156, 0.109, 0.098, 0.130, 0.101, 0.025</ca_table>
          <cl_table>0.000, 1.051, 2.093, 3.202, 4.053, 4.869, 5.680, 6.568</cl_table>
          <cd_table>0.232, 0.288, 0.452, 0.792, 1.264, 1.910, 2.639, 3.520</cd_table>
        </mach>
        <mach nr="0.7">
          <cn_table>0.000, 1.076, 2.145, 3.306, 4.278, 5.339, 6.450, 7.770</cn_table>
          <cm_table>0.000, -0.137, 0.019, 0.065, 1.056, 2.521, 4.151, 5.839</cm_table>
          <ca_table>0.230, 0.211, 0.154, 0.107, 0.096, 0.127, 0.095, 0.014</ca_table>
          <cl_table>0.000, 1.059, 2.103, 3.212, 4.086, 4.974, 5.854, 6.854</cl_table>
          <cd_table>0.230, 0.286, 0.451, 0.792, 1.271, 1.945, 2.711, 3.660</cd_table>
        </mach>
        <mach nr="0.75">
          <cn_table>0.000, 1.094, 2.176, 3.352, 4.351, 5.448, 6.612, 7.995</cn_table>
          <cm_table>0.000, -0.161, -0.032, -0.027, 0.919, 2.405, 4.021, 5.713</cm_table>
          <ca_table>0.230, 0.210, 0.152, 0.104, 0.093, 0.124, 0.092, 0.008</ca_table>
          <cl_table>0.000, 1.077, 2.134, 3.258, 4.156, 5.077, 6.002, 7.055</cl_table>
          <cd_table>0.230, 0.286, 0.453, 0.799, 1.289, 1.980, 2.774, 3.761</cd_table>
        </mach>
        <mach nr="0.8">
          <cn_table>0.000, 1.124, 2.250, 3.504, 4.588, 5.763, 7.008, 8.441</cn_table>
          <cm_table>0.000, -0.183, -0.077, -0.163, 0.762, 2.194, 3.861, 5.428</cm_table>
          <ca_table>0.245, 0.225, 0.163, 0.112, 0.100, 0.134, 0.103, 0.017</ca_table>
          <cl_table>0.000, 1.106, 2.205, 3.404, 4.383, 5.369, 6.360, 7.445</cl_table>
          <cd_table>0.245, 0.302, 0.474, 0.838, 1.361, 2.097, 2.944, 3.978</cd_table>
        </mach>
        <mach nr="0.93">
          <cn_table>0.000, 1.227, 2.460, 3.862, 5.108, 6.451, 7.887, 9.638</cn_table>
          <cm_table>0.000, -0.249, -0.243, -0.576, 0.241, 1.695, 3.348, 4.986</cm_table>
          <ca_table>0.433, 0.430, 0.416, 0.397, 0.377, 0.355, 0.292, 0.172</ca_table>
          <cl_table>0.000, 1.194, 2.378, 3.695, 4.806, 5.941, 7.086, 8.429</cl_table>
          <cd_table>0.433, 0.514, 0.754, 1.191, 1.771, 2.540, 3.475, 4.676</cd_table>
        </mach>
      </aerodynamics>
    </plugin>
    <plugin filename="libDetachableJoint.so" name="DetachHolder1">
      <parent_link>base_link</parent_link>
      <link_to_detach>Holder_1</link_to_detach>
      <joint_to_detach>HolderJoint1</joint_to_detach>
      <detach_direction>0 1 1</detach_direction>
      <!-- <detach_acc>10000</detach_acc> -->
      <detach_topic>holder1_detach</detach_topic>
      <robotNamespace/>
      <visual_offset/>
      <topic_name>holder1visual</topic_name>
    </plugin>
    <plugin filename="libDetachableJoint.so" name="DetachHolder2">
      <parent_link>base_link</parent_link>
      <link_to_detach>Holder_2</link_to_detach>
      <joint_to_detach>HolderJoint2</joint_to_detach>
      <detach_direction>0 -1 1</detach_direction>
      <detach_acc>10</detach_acc>
      <detach_topic>holder2_detach</detach_topic>
      <robotNamespace/>
      <visual_offset/>
      <topic_name>holder2visual</topic_name>
    </plugin>
    <plugin filename="libDetachableJoint.so" name="DetachHolder3">
      <parent_link>base_link</parent_link>
      <link_to_detach>Holder_3</link_to_detach>
      <joint_to_detach>HolderJoint3</joint_to_detach>
      <detach_direction>0 -1 -1</detach_direction>
      <detach_acc>10</detach_acc>
      <detach_topic>holder3_detach</detach_topic>
      <robotNamespace/>
      <visual_offset/>
      <topic_name>holder3visual</topic_name>
    </plugin>
    <plugin filename="libDetachableJoint.so" name="DetachHolder4">
      <parent_link>base_link</parent_link>
      <link_to_detach>Holder_4</link_to_detach>
      <joint_to_detach>HolderJoint4</joint_to_detach>
      <detach_direction>0 1 -1</detach_direction>
      <detach_acc>100</detach_acc>
      <detach_topic>holder4_detach</detach_topic>
      <robotNamespace/>
      <visual_offset/>
      <topic_name>holder4visual</topic_name>
    </plugin>
    <plugin filename="libDetachableJoint.so" name="DetachBooster">
      <parent_link>base_link</parent_link>
      <link_to_detach>Booster_1</link_to_detach>
      <joint_to_detach>booster_fixing</joint_to_detach>
      <detach_direction>-1 0 0</detach_direction>
      <detach_acc>10</detach_acc>
      <detach_topic>booster_detach</detach_topic>
      <visual_offset/>
      <robotNamespace/>
    </plugin>
    <plugin filename="libAerodynamic.so" name="Fin1Aerodynamic">
      <cp>0.0 0.1 0.1</cp>
      <sref>0.044</sref>
      <lref>0.044</lref>
      <air_density>1.2041</air_density>
      <link_name>FinHolder_1</link_name>
      <radial_symmetry>1/</radial_symmetry>
      <!-- <upward>0 0 1</upward> -->
      <forward>1 0 0</forward>
      <robotNamespace/>
      <topic_name>AeroVectors</topic_name>
      <aerodynamics axis_type="body" case="with_booster">
        <mach_table>0.2 0.4 0.5 0.6 0.7 0.75 0.8 0.93</mach_table>
        <alpha_table>.00, 4.00, 8.00, 12.00, 16.00, 20.00, 24.00, 28.00</alpha_table>
        <mach nr="0.2">
          <cn_table>.0000, .2863, .5432, .8305, .9726, 1.0564, 1.0950, 1.1860</cn_table>
          <cm_table>.0000, -1.1294, -2.1425, -3.2754, -3.8362, -4.1665, -4.3190, -4.6776</cm_table>
          <ca_table>.0229, .0229, .0229, .0229, .0229, .0229, .0229, .0229</ca_table>
        </mach>
        <mach nr="0.4">
          <cn_table>.0000, .2923, .5521, .8386, .9666, 1.0587, 1.1216, 1.2260</cn_table>
          <cm_table>.0000, -1.1529, -2.1774, -3.3071, -3.8121, -4.1751, -4.4232, -4.8352</cm_table>
          <ca_table>.0225, .0225, .0225, .0225, .0225, .0225, .0225, .0225</ca_table>
        </mach>
        <mach nr="0.5">
          <cn_table>.0000, .2986, .5646, .8627, .9958, 1.0958, 1.1631, 1.2684</cn_table>
          <cm_table>.0000, -1.1776, -2.2265, -3.4022, -3.9270, -4.3213, -4.5867, -5.0019</cm_table>
          <ca_table>.0222, .0222, .0222, .0222, .0222, .0222, .0222, .0222</ca_table>
        </mach>
        <mach nr="0.6">
          <cn_table>.0000, .3058, .5776, .8835, 1.0210, 1.1251, 1.2047, 1.3162</cn_table>
          <cm_table> .0000, -1.2057, -2.2773, -3.4837, -4.0256, -4.4363, -4.7500, -5.1897</cm_table>
          <ca_table>.0220, .0220, .0220, .0220, .0220, .0220, .0220, .0220</ca_table>
        </mach>
        <mach nr="0.7">
          <cn_table>.0000, .3090, .5835, .8925, 1.0449, 1.1529, 1.2554, 1.3839</cn_table>
          <cm_table>.0000, -1.2180, -2.3000, -3.5184, -4.1193, -4.5447, -4.9488, -5.4556</cm_table>
          <ca_table>.0217, .0217, .0217, .0217, .0217, .0217, .0217, .0217</ca_table>
        </mach>
        <mach nr="0.75">
          <cn_table>.0000, .3148, .5951, .9124, 1.0761, 1.1889, 1.3036, 1.4442</cn_table>
          <cm_table>.0000, -1.2408, -2.3455, -3.5963, -4.2415, -4.6862, -5.1381, -5.6925</cm_table>
          <ca_table>.0215, .0215, .0215, .0215, .0215, .0215, .0215, .0215</ca_table>
        </mach>
        <mach nr="0.8">
          <cn_table>.0000, .3217, .6110, .9516, 1.1309, 1.2632, 1.3835, 1.5524</cn_table>
          <cm_table>.0000, -1.2678, -2.4078, -3.7498, -4.4566, -4.9777, -5.4518, -6.1174</cm_table>
          <ca_table>.0214, .0214, .0214, .0214, .0214, .0214, .0214, .0214</ca_table>
        </mach>
        <mach nr="0.93">
          <cn_table>.0000, .3446, .6624, 1.0588, 1.2808, 1.4380, 1.5948, 1.8203</cn_table>
          <cm_table>.0000, -1.3555, -2.6054, -4.1647, -5.0379, -5.6562, -6.2730, -7.1600</cm_table>
          <ca_table>.0561, .0561, .0561, .0561, .0561, .0561, .0561, .0561</ca_table>
        </mach>
      </aerodynamics>
    </plugin>
    <plugin filename="libAerodynamic.so" name="Fin2Aerodynamic">
      <cp>0.0 0.1 0.1</cp>
      <sref>0.044</sref>
      <lref>0.044</lref>
      <air_density>1.2041</air_density>
      <link_name>FinHolder_2</link_name>
      <radial_symmetry>1/</radial_symmetry>
      <!-- <upward>0 0 1</upward> -->
      <forward>1 0 0</forward>
      <robotNamespace/>
      <topic_name>AeroVectors</topic_name>
      <aerodynamics axis_type="body" case="with_booster">
        <mach_table>0.2 0.4 0.5 0.6 0.7 0.75 0.8 0.93</mach_table>
        <alpha_table>.00, 4.00, 8.00, 12.00, 16.00, 20.00, 24.00, 28.00</alpha_table>
        <mach nr="0.2">
          <cn_table>.0000, .2863, .5432, .8305, .9726, 1.0564, 1.0950, 1.1860</cn_table>
          <cm_table>.0000, -1.1294, -2.1425, -3.2754, -3.8362, -4.1665, -4.3190, -4.6776</cm_table>
          <ca_table>.0229, .0229, .0229, .0229, .0229, .0229, .0229, .0229</ca_table>
        </mach>
        <mach nr="0.4">
          <cn_table>.0000, .2923, .5521, .8386, .9666, 1.0587, 1.1216, 1.2260</cn_table>
          <cm_table>.0000, -1.1529, -2.1774, -3.3071, -3.8121, -4.1751, -4.4232, -4.8352</cm_table>
          <ca_table>.0225, .0225, .0225, .0225, .0225, .0225, .0225, .0225</ca_table>
        </mach>
        <mach nr="0.5">
          <cn_table>.0000, .2986, .5646, .8627, .9958, 1.0958, 1.1631, 1.2684</cn_table>
          <cm_table>.0000, -1.1776, -2.2265, -3.4022, -3.9270, -4.3213, -4.5867, -5.0019</cm_table>
          <ca_table>.0222, .0222, .0222, .0222, .0222, .0222, .0222, .0222</ca_table>
        </mach>
        <mach nr="0.6">
          <cn_table>.0000, .3058, .5776, .8835, 1.0210, 1.1251, 1.2047, 1.3162</cn_table>
          <cm_table> .0000, -1.2057, -2.2773, -3.4837, -4.0256, -4.4363, -4.7500, -5.1897</cm_table>
          <ca_table>.0220, .0220, .0220, .0220, .0220, .0220, .0220, .0220</ca_table>
        </mach>
        <mach nr="0.7">
          <cn_table>.0000, .3090, .5835, .8925, 1.0449, 1.1529, 1.2554, 1.3839</cn_table>
          <cm_table>.0000, -1.2180, -2.3000, -3.5184, -4.1193, -4.5447, -4.9488, -5.4556</cm_table>
          <ca_table>.0217, .0217, .0217, .0217, .0217, .0217, .0217, .0217</ca_table>
        </mach>
        <mach nr="0.75">
          <cn_table>.0000, .3148, .5951, .9124, 1.0761, 1.1889, 1.3036, 1.4442</cn_table>
          <cm_table>.0000, -1.2408, -2.3455, -3.5963, -4.2415, -4.6862, -5.1381, -5.6925</cm_table>
          <ca_table>.0215, .0215, .0215, .0215, .0215, .0215, .0215, .0215</ca_table>
        </mach>
        <mach nr="0.8">
          <cn_table>.0000, .3217, .6110, .9516, 1.1309, 1.2632, 1.3835, 1.5524</cn_table>
          <cm_table>.0000, -1.2678, -2.4078, -3.7498, -4.4566, -4.9777, -5.4518, -6.1174</cm_table>
          <ca_table>.0214, .0214, .0214, .0214, .0214, .0214, .0214, .0214</ca_table>
        </mach>
        <mach nr="0.93">
          <cn_table>.0000, .3446, .6624, 1.0588, 1.2808, 1.4380, 1.5948, 1.8203</cn_table>
          <cm_table>.0000, -1.3555, -2.6054, -4.1647, -5.0379, -5.6562, -6.2730, -7.1600</cm_table>
          <ca_table>.0561, .0561, .0561, .0561, .0561, .0561, .0561, .0561</ca_table>
        </mach>
      </aerodynamics>
    </plugin>
    <plugin filename="libAerodynamic.so" name="Fin3Aerodynamic">
      <cp>0.0 0.1 0.1</cp>
      <sref>0.044</sref>
      <lref>0.044</lref>
      <air_density>1.2041</air_density>
      <link_name>FinHolder_3</link_name>
      <radial_symmetry>1/</radial_symmetry>
      <!-- <upward>0 0 1</upward> -->
      <forward>1 0 0</forward>
      <robotNamespace/>
      <topic_name>AeroVectors</topic_name>
      <aerodynamics axis_type="body" case="with_booster">
        <mach_table>0.2 0.4 0.5 0.6 0.7 0.75 0.8 0.93</mach_table>
        <alpha_table>.00, 4.00, 8.00, 12.00, 16.00, 20.00, 24.00, 28.00</alpha_table>
        <mach nr="0.2">
          <cn_table>.0000, .2863, .5432, .8305, .9726, 1.0564, 1.0950, 1.1860</cn_table>
          <cm_table>.0000, -1.1294, -2.1425, -3.2754, -3.8362, -4.1665, -4.3190, -4.6776</cm_table>
          <ca_table>.0229, .0229, .0229, .0229, .0229, .0229, .0229, .0229</ca_table>
        </mach>
        <mach nr="0.4">
          <cn_table>.0000, .2923, .5521, .8386, .9666, 1.0587, 1.1216, 1.2260</cn_table>
          <cm_table>.0000, -1.1529, -2.1774, -3.3071, -3.8121, -4.1751, -4.4232, -4.8352</cm_table>
          <ca_table>.0225, .0225, .0225, .0225, .0225, .0225, .0225, .0225</ca_table>
        </mach>
        <mach nr="0.5">
          <cn_table>.0000, .2986, .5646, .8627, .9958, 1.0958, 1.1631, 1.2684</cn_table>
          <cm_table>.0000, -1.1776, -2.2265, -3.4022, -3.9270, -4.3213, -4.5867, -5.0019</cm_table>
          <ca_table>.0222, .0222, .0222, .0222, .0222, .0222, .0222, .0222</ca_table>
        </mach>
        <mach nr="0.6">
          <cn_table>.0000, .3058, .5776, .8835, 1.0210, 1.1251, 1.2047, 1.3162</cn_table>
          <cm_table> .0000, -1.2057, -2.2773, -3.4837, -4.0256, -4.4363, -4.7500, -5.1897</cm_table>
          <ca_table>.0220, .0220, .0220, .0220, .0220, .0220, .0220, .0220</ca_table>
        </mach>
        <mach nr="0.7">
          <cn_table>.0000, .3090, .5835, .8925, 1.0449, 1.1529, 1.2554, 1.3839</cn_table>
          <cm_table>.0000, -1.2180, -2.3000, -3.5184, -4.1193, -4.5447, -4.9488, -5.4556</cm_table>
          <ca_table>.0217, .0217, .0217, .0217, .0217, .0217, .0217, .0217</ca_table>
        </mach>
        <mach nr="0.75">
          <cn_table>.0000, .3148, .5951, .9124, 1.0761, 1.1889, 1.3036, 1.4442</cn_table>
          <cm_table>.0000, -1.2408, -2.3455, -3.5963, -4.2415, -4.6862, -5.1381, -5.6925</cm_table>
          <ca_table>.0215, .0215, .0215, .0215, .0215, .0215, .0215, .0215</ca_table>
        </mach>
        <mach nr="0.8">
          <cn_table>.0000, .3217, .6110, .9516, 1.1309, 1.2632, 1.3835, 1.5524</cn_table>
          <cm_table>.0000, -1.2678, -2.4078, -3.7498, -4.4566, -4.9777, -5.4518, -6.1174</cm_table>
          <ca_table>.0214, .0214, .0214, .0214, .0214, .0214, .0214, .0214</ca_table>
        </mach>
        <mach nr="0.93">
          <cn_table>.0000, .3446, .6624, 1.0588, 1.2808, 1.4380, 1.5948, 1.8203</cn_table>
          <cm_table>.0000, -1.3555, -2.6054, -4.1647, -5.0379, -5.6562, -6.2730, -7.1600</cm_table>
          <ca_table>.0561, .0561, .0561, .0561, .0561, .0561, .0561, .0561</ca_table>
        </mach>
      </aerodynamics>
    </plugin>
    <plugin filename="libAerodynamic.so" name="Fin4Aerodynamic">
      <cp>0.0 0.1 0.1</cp>
      <sref>0.044</sref>
      <lref>0.044</lref>
      <air_density>1.2041</air_density>
      <link_name>FinHolder_4</link_name>
      <radial_symmetry>1/</radial_symmetry>
      <!-- <upward>0 0 1</upward> -->
      <forward>1 0 0</forward>
      <robotNamespace/>
      <topic_name>AeroVectors</topic_name>
      <aerodynamics axis_type="body" case="with_booster">
        <mach_table>0.2 0.4 0.5 0.6 0.7 0.75 0.8 0.93</mach_table>
        <alpha_table>.00, 4.00, 8.00, 12.00, 16.00, 20.00, 24.00, 28.00</alpha_table>
        <mach nr="0.2">
          <cn_table>.0000, .2863, .5432, .8305, .9726, 1.0564, 1.0950, 1.1860</cn_table>
          <cm_table>.0000, -1.1294, -2.1425, -3.2754, -3.8362, -4.1665, -4.3190, -4.6776</cm_table>
          <ca_table>.0229, .0229, .0229, .0229, .0229, .0229, .0229, .0229</ca_table>
        </mach>
        <mach nr="0.4">
          <cn_table>.0000, .2923, .5521, .8386, .9666, 1.0587, 1.1216, 1.2260</cn_table>
          <cm_table>.0000, -1.1529, -2.1774, -3.3071, -3.8121, -4.1751, -4.4232, -4.8352</cm_table>
          <ca_table>.0225, .0225, .0225, .0225, .0225, .0225, .0225, .0225</ca_table>
        </mach>
        <mach nr="0.5">
          <cn_table>.0000, .2986, .5646, .8627, .9958, 1.0958, 1.1631, 1.2684</cn_table>
          <cm_table>.0000, -1.1776, -2.2265, -3.4022, -3.9270, -4.3213, -4.5867, -5.0019</cm_table>
          <ca_table>.0222, .0222, .0222, .0222, .0222, .0222, .0222, .0222</ca_table>
        </mach>
        <mach nr="0.6">
          <cn_table>.0000, .3058, .5776, .8835, 1.0210, 1.1251, 1.2047, 1.3162</cn_table>
          <cm_table> .0000, -1.2057, -2.2773, -3.4837, -4.0256, -4.4363, -4.7500, -5.1897</cm_table>
          <ca_table>.0220, .0220, .0220, .0220, .0220, .0220, .0220, .0220</ca_table>
        </mach>
        <mach nr="0.7">
          <cn_table>.0000, .3090, .5835, .8925, 1.0449, 1.1529, 1.2554, 1.3839</cn_table>
          <cm_table>.0000, -1.2180, -2.3000, -3.5184, -4.1193, -4.5447, -4.9488, -5.4556</cm_table>
          <ca_table>.0217, .0217, .0217, .0217, .0217, .0217, .0217, .0217</ca_table>
        </mach>
        <mach nr="0.75">
          <cn_table>.0000, .3148, .5951, .9124, 1.0761, 1.1889, 1.3036, 1.4442</cn_table>
          <cm_table>.0000, -1.2408, -2.3455, -3.5963, -4.2415, -4.6862, -5.1381, -5.6925</cm_table>
          <ca_table>.0215, .0215, .0215, .0215, .0215, .0215, .0215, .0215</ca_table>
        </mach>
        <mach nr="0.8">
          <cn_table>.0000, .3217, .6110, .9516, 1.1309, 1.2632, 1.3835, 1.5524</cn_table>
          <cm_table>.0000, -1.2678, -2.4078, -3.7498, -4.4566, -4.9777, -5.4518, -6.1174</cm_table>
          <ca_table>.0214, .0214, .0214, .0214, .0214, .0214, .0214, .0214</ca_table>
        </mach>
        <mach nr="0.93">
          <cn_table>.0000, .3446, .6624, 1.0588, 1.2808, 1.4380, 1.5948, 1.8203</cn_table>
          <cm_table>.0000, -1.3555, -2.6054, -4.1647, -5.0379, -5.6562, -6.2730, -7.1600</cm_table>
          <ca_table>.0561, .0561, .0561, .0561, .0561, .0561, .0561, .0561</ca_table>
        </mach>
      </aerodynamics>
    </plugin>
  </gazebo>
  <gazebo reference="base_link">
    <material>Gazebo/White</material>
    <mu1>0.2</mu1>
    <mu2>0.2</mu2>
    <selfCollide>true</selfCollide>
    <gravity>true</gravity>
    <visual>
      <plugin filename="libMultiplevectorVisual.so" name="LiftDragVisual">
        <topic_name vector_size="5">AeroVectors</topic_name>
      </plugin>
      <plugin filename="libForceVisual.so" name="VectoredThrustVisual">
        <topic_name>thrust_visual</topic_name>
        <color>Gazebo/Green</color>
      </plugin>
    </visual>
    <sensor name="camera_top_side" type="camera">
      <pose>-2 0.0 2 0.0 0.5236000000000001 0.0</pose>
      <camera>
        <horizontal_fov>1.347</horizontal_fov>
        <image>
          <width>640</width>
          <height>480</height>
        </image>
        <clip>
          <near>0.1</near>
          <far>100</far>
        </clip>
      </camera>
      <always_on>1</always_on>
      <update_rate>30</update_rate>
      <!-- <visualize>true</visualize> -->
    </sensor>
    <sensor name="camera_deflection" type="camera">
      <pose>-1.0 -1.0 0.0 0.0 0.0 2.3562</pose>
      <camera>
        <horizontal_fov>1.347</horizontal_fov>
        <image>
          <width>640</width>
          <height>480</height>
        </image>
        <clip>
          <near>0.1</near>
          <far>1000</far>
        </clip>
      </camera>
      <always_on>1</always_on>
      <update_rate>30</update_rate>
      <!-- <visualize>true</visualize> -->
    </sensor>
    <!-- <sensor name='imu_sensor' type='imu'>
    <always_on>1</always_on>
    <update_rate>30</update_rate>
    <imu/>
  </sensor> -->
    <sensor name="touching_ground" type="contact">
      <contact>
        <collision>base_link_collision</collision>
      </contact>
    </sensor>
  </gazebo>
  <gazebo reference="Booster_1">
    <material>Gazebo/Gray</material>
    <mu1>0.2</mu1>
    <mu2>0.2</mu2>
    <selfCollide>true</selfCollide>
    <visual>
      <plugin filename="libForceVisual.so" name="SimpleThrustVisual">
        <topic_name>booster_visual</topic_name>
        <color>Gazebo/Green</color>
      </plugin>
    </visual>
  </gazebo>
  <gazebo reference="FinHolder_1">
    <material>Gazebo/Blue</material>
    <mu1>0.2</mu1>
    <mu2>0.2</mu2>
    <selfCollide>true</selfCollide>
  </gazebo>
  <gazebo reference="FinHolder_4">
    <material>Gazebo/Blue</material>
    <mu1>0.2</mu1>
    <mu2>0.2</mu2>
    <selfCollide>true</selfCollide>
  </gazebo>
  <gazebo reference="FinHolder_3">
    <material>Gazebo/Blue</material>
    <mu1>0.2</mu1>
    <mu2>0.2</mu2>
    <selfCollide>true</selfCollide>
  </gazebo>
  <gazebo reference="FinHolder_2">
    <material>Gazebo/Blue</material>
    <mu1>0.2</mu1>
    <mu2>0.2</mu2>
    <selfCollide>true</selfCollide>
  </gazebo>
  <gazebo reference="Wing1_1">
    <material>Gazebo/Orange</material>
    <mu1>0.2</mu1>
    <mu2>0.2</mu2>
    <selfCollide>true</selfCollide>
  </gazebo>
  <gazebo reference="Wing1_2">
    <material>Gazebo/Orange</material>
    <mu1>0.2</mu1>
    <mu2>0.2</mu2>
    <selfCollide>true</selfCollide>
  </gazebo>
  <gazebo reference="Wing1_3">
    <material>Gazebo/Orange</material>
    <mu1>0.2</mu1>
    <mu2>0.2</mu2>
    <selfCollide>true</selfCollide>
  </gazebo>
  <gazebo reference="Wing1_4">
    <material>Gazebo/Orange</material>
    <mu1>0.2</mu1>
    <mu2>0.2</mu2>
    <selfCollide>true</selfCollide>
  </gazebo>
  <gazebo reference="Fin_1">
    <material>Gazebo/Orange</material>
    <mu1>0.2</mu1>
    <mu2>0.2</mu2>
    <selfCollide>true</selfCollide>
  </gazebo>
  <gazebo reference="Fin_2">
    <material>Gazebo/Orange</material>
    <mu1>0.2</mu1>
    <mu2>0.2</mu2>
    <selfCollide>true</selfCollide>
  </gazebo>
  <gazebo reference="Fin_3">
    <material>Gazebo/Orange</material>
    <mu1>0.2</mu1>
    <mu2>0.2</mu2>
    <selfCollide>true</selfCollide>
  </gazebo>
  <gazebo reference="Fin_4">
    <material>Gazebo/Orange</material>
    <mu1>0.2</mu1>
    <mu2>0.2</mu2>
    <selfCollide>true</selfCollide>
  </gazebo>
  <gazebo reference="Holder_1">
    <material>Gazebo/Grey</material>
    <mu1>0.2</mu1>
    <mu2>0.2</mu2>
    <selfCollide>true</selfCollide>
    <visual>
      <plugin filename="libForceVisual.so" name="Holder1Visual">
        <topic_name>holder1visual</topic_name>
        <color>Gazebo/Purple</color>
      </plugin>
    </visual>
  </gazebo>
  <gazebo reference="Holder_2">
    <material>Gazebo/Grey</material>
    <mu1>0.2</mu1>
    <mu2>0.2</mu2>
    <selfCollide>true</selfCollide>
    <visual>
      <plugin filename="libForceVisual.so" name="Holder2Visual">
        <topic_name>holder2visual</topic_name>
        <color>Gazebo/Purple</color>
      </plugin>
    </visual>
  </gazebo>
  <gazebo reference="Holder_3">
    <material>Gazebo/Grey</material>
    <mu1>0.2</mu1>
    <mu2>0.2</mu2>
    <selfCollide>true</selfCollide>
    <visual>
      <plugin filename="libForceVisual.so" name="Holder3Visual">
        <topic_name>holder3visual</topic_name>
        <color>Gazebo/Purple</color>
      </plugin>
    </visual>
  </gazebo>
  <gazebo reference="Holder_4">
    <material>Gazebo/Grey</material>
    <mu1>0.2</mu1>
    <mu2>0.2</mu2>
    <selfCollide>true</selfCollide>
    <visual>
      <plugin filename="libForceVisual.so" name="Holder4Visual">
        <topic_name>holder4visual</topic_name>
        <color>Gazebo/Purple</color>
      </plugin>
    </visual>
  </gazebo>
   --&gt;


  <gazebo reference="booster_fixing">
    <preserveFixedJoint>true</preserveFixedJoint>
  </gazebo>
  <gazebo reference="HolderJoint1">
    <preserveFixedJoint>true</preserveFixedJoint>
  </gazebo>
  <gazebo reference="HolderJoint2">
    <preserveFixedJoint>true</preserveFixedJoint>
  </gazebo>
  <gazebo reference="HolderJoint3">
    <preserveFixedJoint>true</preserveFixedJoint>
  </gazebo>
  <gazebo reference="HolderJoint4">
    <preserveFixedJoint>true</preserveFixedJoint>
  </gazebo>
  <link name="base_link">
    <inertial>
      <origin rpy="0 0 0" xyz="-4.5938008952361996e-12 -5.330786024108829e-16 -2.382079374378753e-16"/>
      <mass value="562.7679612503737"/>
      <inertia ixx="12.078708" ixy="0.0" ixz="0.0" iyy="817.09871" iyz="-0.0" izz="817.09871"/>
    </inertial>
    <visual>
      <origin rpy="0 0 0" xyz="0 0 0"/>
      <geometry>
        <mesh filename="package://model_missile_description/meshes/base_link.stl" scale="0.001 0.001 0.001"/>
      </geometry>
      <material name="white"/>
    </visual>
    <collision>
      <origin rpy="0 0 0" xyz="0 0 0"/>
      <geometry>
        <mesh filename="package://model_missile_description/meshes/base_link.stl" scale="0.001 0.001 0.001"/>
      </geometry>
    </collision>
  </link>
  <link name="Booster_1">
    <inertial>
      <origin rpy="0 0 0" xyz="-0.5305587019886722 3.685572621648184e-09 -9.224211236366606e-10"/>
      <mass value="120.00001114591107"/>
      <inertia ixx="5.768641" ixy="-0.0" ixz="0.0" iyy="16.618567" iyz="-0.0" izz="16.618567"/>
    </inertial>
    <visual>
      <origin rpy="0 0 0" xyz="1.880856 -0.0 -0.0"/>
      <geometry>
        <mesh filename="package://model_missile_description/meshes/Booster_1.stl" scale="0.001 0.001 0.001"/>
      </geometry>
      <material name="grey"/>
    </visual>
    <collision>
      <origin rpy="0 0 0" xyz="1.880856 -0.0 -0.0"/>
      <geometry>
        <mesh filename="package://model_missile_description/meshes/Booster_1.stl" scale="0.001 0.001 0.001"/>
      </geometry>
    </collision>
  </link>
  <link name="FinHolder_1">
    <inertial>
      <origin rpy="0 0 0" xyz="0.011989970177444853 0.024895470365400352 0.02489052657337168"/>
      <mass value="0.6999999481439694"/>
      <inertia ixx="0.00025" ixy="3e-05" ixz="3e-05" iyy="0.004649" iyz="-9.8e-05" izz="0.004649"/>
    </inertial>
    <visual>
      <origin rpy="0 0 0" xyz="1.700844 -0.127279 -0.127279"/>
      <geometry>
        <mesh filename="package://model_missile_description/meshes/FinHolder_1.stl" scale="0.001 0.001 0.001"/>
      </geometry>
      <material name="blue"/>
    </visual>
    <collision>
      <origin rpy="0 0 0" xyz="1.700844 -0.127279 -0.127279"/>
      <geometry>
        <mesh filename="package://model_missile_description/meshes/FinHolder_1.stl" scale="0.001 0.001 0.001"/>
      </geometry>
    </collision>
  </link>
  <link name="FinHolder_4">
    <inertial>
      <origin rpy="0 0 0" xyz="0.011989970177444853 -0.024890526573368127 0.0248954703654041"/>
      <mass value="0.6999999481439694"/>
      <inertia ixx="0.00025" ixy="-3e-05" ixz="3e-05" iyy="0.004649" iyz="9.8e-05" izz="0.004649"/>
    </inertial>
    <visual>
      <origin rpy="0 0 0" xyz="1.700844 0.127279 -0.127279"/>
      <geometry>
        <mesh filename="package://model_missile_description/meshes/FinHolder_4.stl" scale="0.001 0.001 0.001"/>
      </geometry>
      <material name="blue"/>
    </visual>
    <collision>
      <origin rpy="0 0 0" xyz="1.700844 0.127279 -0.127279"/>
      <geometry>
        <mesh filename="package://model_missile_description/meshes/FinHolder_4.stl" scale="0.001 0.001 0.001"/>
      </geometry>
    </collision>
  </link>
  <link name="FinHolder_3">
    <inertial>
      <origin rpy="0 0 0" xyz="0.011989970177444853 -0.024895470365400463 -0.02489052657336438"/>
      <mass value="0.6999999481439694"/>
      <inertia ixx="0.00025" ixy="-3e-05" ixz="-3e-05" iyy="0.004649" iyz="-9.8e-05" izz="0.004649"/>
    </inertial>
    <visual>
      <origin rpy="0 0 0" xyz="1.700844 0.127279 0.127279"/>
      <geometry>
        <mesh filename="package://model_missile_description/meshes/FinHolder_3.stl" scale="0.001 0.001 0.001"/>
      </geometry>
      <material name="blue"/>
    </visual>
    <collision>
      <origin rpy="0 0 0" xyz="1.700844 0.127279 0.127279"/>
      <geometry>
        <mesh filename="package://model_missile_description/meshes/FinHolder_3.stl" scale="0.001 0.001 0.001"/>
      </geometry>
    </collision>
  </link>
  <link name="FinHolder_2">
    <inertial>
      <origin rpy="0 0 0" xyz="0.011989970177444409 0.024890526573368155 -0.024895470365396688"/>
      <mass value="0.6999999481439694"/>
      <inertia ixx="0.00025" ixy="3e-05" ixz="-3e-05" iyy="0.004649" iyz="9.8e-05" izz="0.004649"/>
    </inertial>
    <visual>
      <origin rpy="0 0 0" xyz="1.700844 -0.127279 0.127279"/>
      <geometry>
        <mesh filename="package://model_missile_description/meshes/FinHolder_2.stl" scale="0.001 0.001 0.001"/>
      </geometry>
      <material name="blue"/>
    </visual>
    <collision>
      <origin rpy="0 0 0" xyz="1.700844 -0.127279 0.127279"/>
      <geometry>
        <mesh filename="package://model_missile_description/meshes/FinHolder_2.stl" scale="0.001 0.001 0.001"/>
      </geometry>
    </collision>
  </link>
  <link name="Wing1_1">
    <inertial>
      <origin rpy="0 0 0" xyz="-0.031208061901909834 0.07128204697290338 0.07128204710602434"/>
      <mass value="9.299979574219194"/>
      <inertia ixx="0.055746" ixy="0.012327" ixz="0.012327" iyy="0.41744" iyz="-0.02758" izz="0.41744"/>
    </inertial>
    <visual>
      <origin rpy="0 0 0" xyz="0.380856 -0.163355 -0.163355"/>
      <geometry>
        <mesh filename="package://model_missile_description/meshes/Wing1_1.stl" scale="0.001 0.001 0.001"/>
      </geometry>
      <material name="orange"/>
    </visual>
    <collision>
      <origin rpy="0 0 0" xyz="0.380856 -0.163355 -0.163355"/>
      <geometry>
        <mesh filename="package://model_missile_description/meshes/Wing1_1.stl" scale="0.001 0.001 0.001"/>
      </geometry>
    </collision>
  </link>
  <link name="Wing1_2">
    <inertial>
      <origin rpy="0 0 0" xyz="-0.031208061901910722 0.07057494032483622 -0.07057494019171545"/>
      <mass value="9.299979574219194"/>
      <inertia ixx="0.055746" ixy="0.012327" ixz="-0.012327" iyy="0.41744" iyz="0.02758" izz="0.41744"/>
    </inertial>
    <visual>
      <origin rpy="0 0 0" xyz="0.380856 -0.163355 0.163355"/>
      <geometry>
        <mesh filename="package://model_missile_description/meshes/Wing1_2.stl" scale="0.001 0.001 0.001"/>
      </geometry>
      <material name="orange"/>
    </visual>
    <collision>
      <origin rpy="0 0 0" xyz="0.380856 -0.163355 0.163355"/>
      <geometry>
        <mesh filename="package://model_missile_description/meshes/Wing1_2.stl" scale="0.001 0.001 0.001"/>
      </geometry>
    </collision>
  </link>
  <link name="Wing1_3">
    <inertial>
      <origin rpy="0 0 0" xyz="-0.031208061901910722 -0.07057494019171678 -0.0705749403248346"/>
      <mass value="9.299979574219194"/>
      <inertia ixx="0.055746" ixy="-0.012327" ixz="-0.012327" iyy="0.41744" iyz="-0.02758" izz="0.41744"/>
    </inertial>
    <visual>
      <origin rpy="0 0 0" xyz="0.380856 0.163355 0.163355"/>
      <geometry>
        <mesh filename="package://model_missile_description/meshes/Wing1_3.stl" scale="0.001 0.001 0.001"/>
      </geometry>
      <material name="orange"/>
    </visual>
    <collision>
      <origin rpy="0 0 0" xyz="0.380856 0.163355 0.163355"/>
      <geometry>
        <mesh filename="package://model_missile_description/meshes/Wing1_3.stl" scale="0.001 0.001 0.001"/>
      </geometry>
    </collision>
  </link>
  <link name="Wing1_4">
    <inertial>
      <origin rpy="0 0 0" xyz="-0.031208061901909945 -0.07057494032483608 0.07057494019171842"/>
      <mass value="9.299979574219194"/>
      <inertia ixx="0.055746" ixy="-0.012327" ixz="0.012327" iyy="0.41744" iyz="0.02758" izz="0.41744"/>
    </inertial>
    <visual>
      <origin rpy="0 0 0" xyz="0.380856 0.163355 -0.163355"/>
      <geometry>
        <mesh filename="package://model_missile_description/meshes/Wing1_4.stl" scale="0.001 0.001 0.001"/>
      </geometry>
      <material name="orange"/>
    </visual>
    <collision>
      <origin rpy="0 0 0" xyz="0.380856 0.163355 -0.163355"/>
      <geometry>
        <mesh filename="package://model_missile_description/meshes/Wing1_4.stl" scale="0.001 0.001 0.001"/>
      </geometry>
    </collision>
  </link>
  <link name="Fin_1">
    <inertial>
      <origin rpy="0 0 0" xyz="-0.014318251120852166 0.06139665026364291 0.061396650263642966"/>
      <mass value="1.500000007859579"/>
      <inertia ixx="0.006929" ixy="0.000899" ixz="0.000899" iyy="0.007262" iyz="-0.003432" izz="0.007262"/>
    </inertial>
    <visual>
      <origin rpy="0 0 0" xyz="1.700844 -0.16617 -0.16617"/>
      <geometry>
        <mesh filename="package://model_missile_description/meshes/Fin_1.stl" scale="0.001 0.001 0.001"/>
      </geometry>
      <material name="orange"/>
    </visual>
    <collision>
      <origin rpy="0 0 0" xyz="1.700844 -0.16617 -0.16617"/>
      <geometry>
        <mesh filename="package://model_missile_description/meshes/Fin_1.stl" scale="0.001 0.001 0.001"/>
      </geometry>
    </collision>
  </link>
  <link name="Fin_2">
    <inertial>
      <origin rpy="0 0 0" xyz="-0.01431825112085261 0.06139642160960024 -0.061396878917678394"/>
      <mass value="1.500000007859579"/>
      <inertia ixx="0.006929" ixy="0.000899" ixz="-0.000899" iyy="0.007262" iyz="0.003432" izz="0.007262"/>
    </inertial>
    <visual>
      <origin rpy="0 0 0" xyz="1.700844 -0.166158 0.166182"/>
      <geometry>
        <mesh filename="package://model_missile_description/meshes/Fin_2.stl" scale="0.001 0.001 0.001"/>
      </geometry>
      <material name="orange"/>
    </visual>
    <collision>
      <origin rpy="0 0 0" xyz="1.700844 -0.166158 0.166182"/>
      <geometry>
        <mesh filename="package://model_missile_description/meshes/Fin_2.stl" scale="0.001 0.001 0.001"/>
      </geometry>
    </collision>
  </link>
  <link name="Fin_3">
    <inertial>
      <origin rpy="0 0 0" xyz="-0.014318251120852166 -0.06139665026364283 -0.06139665026363558"/>
      <mass value="1.500000007859579"/>
      <inertia ixx="0.006929" ixy="-0.000899" ixz="-0.000899" iyy="0.007262" iyz="-0.003432" izz="0.007262"/>
    </inertial>
    <visual>
      <origin rpy="0 0 0" xyz="1.700844 0.16617 0.16617"/>
      <geometry>
        <mesh filename="package://model_missile_description/meshes/Fin_3.stl" scale="0.001 0.001 0.001"/>
      </geometry>
      <material name="orange"/>
    </visual>
    <collision>
      <origin rpy="0 0 0" xyz="1.700844 0.16617 0.16617"/>
      <geometry>
        <mesh filename="package://model_missile_description/meshes/Fin_3.stl" scale="0.001 0.001 0.001"/>
      </geometry>
    </collision>
  </link>
  <link name="Fin_4">
    <inertial>
      <origin rpy="0 0 0" xyz="-0.014318251120852166 -0.061396650263639274 0.06139665026364652"/>
      <mass value="1.500000007859579"/>
      <inertia ixx="0.006929" ixy="-0.000899" ixz="0.000899" iyy="0.007262" iyz="0.003432" izz="0.007262"/>
    </inertial>
    <visual>
      <origin rpy="0 0 0" xyz="1.700844 0.16617 -0.16617"/>
      <geometry>
        <mesh filename="package://model_missile_description/meshes/Fin_4.stl" scale="0.001 0.001 0.001"/>
      </geometry>
      <material name="orange"/>
    </visual>
    <collision>
      <origin rpy="0 0 0" xyz="1.700844 0.16617 -0.16617"/>
      <geometry>
        <mesh filename="package://model_missile_description/meshes/Fin_4.stl" scale="0.001 0.001 0.001"/>
      </geometry>
    </collision>
  </link>
  <link name="Holder_1">
    <inertial>
      <origin rpy="0 0 0" xyz="-0.19999995584291042 0.025232520282130994 0.02523252028212361"/>
      <mass value="13.50000107858645"/>
      <inertia ixx="0.184494" ixy="-0.0" ixz="-0.0" iyy="0.864601" iyz="0.079825" izz="0.864601"/>
    </inertial>
    <visual>
      <origin rpy="0 0 0" xyz="-1.375615 -0.132493 -0.132493"/>
      <geometry>
        <mesh filename="package://model_missile_description/meshes/Holder_1.stl" scale="0.001 0.001 0.001"/>
      </geometry>
      <material name="darkgrey"/>
    </visual>
    <collision>
      <origin rpy="0 0 0" xyz="-1.375615 -0.132493 -0.132493"/>
      <geometry>
        <mesh filename="package://model_missile_description/meshes/Holder_1.stl" scale="0.001 0.001 0.001"/>
      </geometry>
    </collision>
  </link>
  <link name="Holder_2">
    <inertial>
      <origin rpy="0 0 0" xyz="-0.19999995584291042 -0.02523252028212361 0.025232520282130994"/>
      <mass value="13.50000107858645"/>
      <inertia ixx="0.184494" ixy="0.0" ixz="-0.0" iyy="0.864601" iyz="-0.079825" izz="0.864601"/>
    </inertial>
    <visual>
      <origin rpy="0 0 0" xyz="-1.375615 0.132493 -0.132493"/>
      <geometry>
        <mesh filename="package://model_missile_description/meshes/Holder_2.stl" scale="0.001 0.001 0.001"/>
      </geometry>
      <material name="darkgrey"/>
    </visual>
    <collision>
      <origin rpy="0 0 0" xyz="-1.375615 0.132493 -0.132493"/>
      <geometry>
        <mesh filename="package://model_missile_description/meshes/Holder_2.stl" scale="0.001 0.001 0.001"/>
      </geometry>
    </collision>
  </link>
  <link name="Holder_3">
    <inertial>
      <origin rpy="0 0 0" xyz="-0.19999995584291042 -0.025232520282130994 -0.025232520282123555"/>
      <mass value="13.50000107858645"/>
      <inertia ixx="0.184494" ixy="0.0" ixz="0.0" iyy="0.864601" iyz="0.079825" izz="0.864601"/>
    </inertial>
    <visual>
      <origin rpy="0 0 0" xyz="-1.375615 0.132493 0.132493"/>
      <geometry>
        <mesh filename="package://model_missile_description/meshes/Holder_3.stl" scale="0.001 0.001 0.001"/>
      </geometry>
      <material name="darkgrey"/>
    </visual>
    <collision>
      <origin rpy="0 0 0" xyz="-1.375615 0.132493 0.132493"/>
      <geometry>
        <mesh filename="package://model_missile_description/meshes/Holder_3.stl" scale="0.001 0.001 0.001"/>
      </geometry>
    </collision>
  </link>
  <link name="Holder_4">
    <inertial>
      <origin rpy="0 0 0" xyz="-0.19999995584291042 0.025232520282123555 -0.025232520282130994"/>
      <mass value="13.50000107858645"/>
      <inertia ixx="0.184494" ixy="-0.0" ixz="0.0" iyy="0.864601" iyz="-0.079825" izz="0.864601"/>
    </inertial>
    <visual>
      <origin rpy="0 0 0" xyz="-1.375615 -0.132493 0.132493"/>
      <geometry>
        <mesh filename="package://model_missile_description/meshes/Holder_4.stl" scale="0.001 0.001 0.001"/>
      </geometry>
      <material name="darkgrey"/>
    </visual>
    <collision>
      <origin rpy="0 0 0" xyz="-1.375615 -0.132493 0.132493"/>
      <geometry>
        <mesh filename="package://model_missile_description/meshes/Holder_4.stl" scale="0.001 0.001 0.001"/>
      </geometry>
    </collision>
  </link>
  <joint name="booster_fixing" type="fixed">
    <origin rpy="0 0 0" xyz="-1.880856 0.0 0.0"/>
    <parent link="base_link"/>
    <child link="Booster_1"/>
  </joint>
  <joint name="fins_rev1" type="revolute">
    <origin rpy="0 0 0" xyz="-1.700844 0.127279 0.127279"/>
    <parent link="base_link"/>
    <child link="FinHolder_1"/>
    <axis xyz="-0.0 0.707107 0.707107"/>
    <limit effort="100" lower="-0.349066" upper="0.349066" velocity="100"/>
  </joint>
  <joint name="fins_rev4" type="revolute">
    <origin rpy="0 0 0" xyz="-1.700844 -0.127279 0.127279"/>
    <parent link="base_link"/>
    <child link="FinHolder_4"/>
    <axis xyz="-0.0 -0.707107 0.707107"/>
    <limit effort="100" lower="-0.349066" upper="0.349066" velocity="100"/>
  </joint>
  <joint name="fins_rev3" type="revolute">
    <origin rpy="0 0 0" xyz="-1.700844 -0.127279 -0.127279"/>
    <parent link="base_link"/>
    <child link="FinHolder_3"/>
    <axis xyz="-0.0 -0.707107 -0.707107"/>
    <limit effort="100" lower="-0.349066" upper="0.349066" velocity="100"/>
  </joint>
  <joint name="fins_rev2" type="revolute">
    <origin rpy="0 0 0" xyz="-1.700844 0.127279 -0.127279"/>
    <parent link="base_link"/>
    <child link="FinHolder_2"/>
    <axis xyz="-0.0 0.707107 -0.707107"/>
    <limit effort="100" lower="-0.349066" upper="0.349066" velocity="100"/>
  </joint>
  <joint name="wings_fold1" type="revolute">
    <origin rpy="0 0 0" xyz="-0.380856 0.163355 0.163355"/>
    <parent link="base_link"/>
    <child link="Wing1_1"/>
    <axis xyz="1.0 -0.0 -0.0"/>
    <limit effort="100" lower="0.0" upper="2.146755" velocity="100"/>
  </joint>
  <joint name="wings_fold2" type="revolute">
    <origin rpy="0 0 0" xyz="-0.380856 0.163355 -0.163355"/>
    <parent link="base_link"/>
    <child link="Wing1_2"/>
    <axis xyz="1.0 0.0 -0.0"/>
    <limit effort="100" lower="0.0" upper="2.146755" velocity="100"/>
  </joint>
  <joint name="wings_fold3" type="revolute">
    <origin rpy="0 0 0" xyz="-0.380856 -0.163355 -0.163355"/>
    <parent link="base_link"/>
    <child link="Wing1_3"/>
    <axis xyz="1.0 0.0 -0.0"/>
    <limit effort="100" lower="0.0" upper="2.146755" velocity="100"/>
  </joint>
  <joint name="wings_fold4" type="revolute">
    <origin rpy="0 0 0" xyz="-0.380856 -0.163355 0.163355"/>
    <parent link="base_link"/>
    <child link="Wing1_4"/>
    <axis xyz="1.0 -0.0 -0.0"/>
    <limit effort="100" lower="0.0" upper="2.146755" velocity="100"/>
  </joint>
  <joint name="fin_fold1" type="revolute">
    <origin rpy="0 0 0" xyz="0.0 0.038891 0.038891"/>
    <parent link="FinHolder_1"/>
    <child link="Fin_1"/>
    <axis xyz="1.0 0.0 0.0"/>
    <limit effort="100" lower="0.0" upper="2.146755" velocity="100"/>
  </joint>
  <joint name="fin_fold2" type="revolute">
    <origin rpy="0 0 0" xyz="0.0 0.038879 -0.038903"/>
    <parent link="FinHolder_2"/>
    <child link="Fin_2"/>
    <axis xyz="1.0 0.0 -0.0"/>
    <limit effort="100" lower="0.0" upper="2.146755" velocity="100"/>
  </joint>
  <joint name="fin_fold3" type="revolute">
    <origin rpy="0 0 0" xyz="0.0 -0.038891 -0.038891"/>
    <parent link="FinHolder_3"/>
    <child link="Fin_3"/>
    <axis xyz="1.0 -0.0 -0.0"/>
    <limit effort="100" lower="0.0" upper="2.146755" velocity="100"/>
  </joint>
  <joint name="fin_fold4" type="revolute">
    <origin rpy="0 0 0" xyz="0.0 -0.038891 0.038891"/>
    <parent link="FinHolder_4"/>
    <child link="Fin_4"/>
    <axis xyz="1.0 -0.0 0.0"/>
    <limit effort="100" lower="0.0" upper="2.146755" velocity="100"/>
  </joint>
  <joint name="HolderJoint1" type="fixed">
    <origin rpy="0 0 0" xyz="1.375615 0.132493 0.132493"/>
    <parent link="base_link"/>
    <child link="Holder_1"/>
  </joint>
  <joint name="HolderJoint2" type="fixed">
    <origin rpy="0 0 0" xyz="1.375615 -0.132493 0.132493"/>
    <parent link="base_link"/>
    <child link="Holder_2"/>
  </joint>
  <joint name="HolderJoint3" type="fixed">
    <origin rpy="0 0 0" xyz="1.375615 -0.132493 -0.132493"/>
    <parent link="base_link"/>
    <child link="Holder_3"/>
  </joint>
  <joint name="HolderJoint4" type="fixed">
    <origin rpy="0 0 0" xyz="1.375615 0.132493 -0.132493"/>
    <parent link="base_link"/>
    <child link="Holder_4"/>
  </joint>
</robot>

