<?xml version="1.0" ?>
<!-- =================================================================================== -->
<!-- |    This document was autogenerated by xacro from src/ssm_models/model_missile_description/urdf/model_missile.xacro | -->
<!-- |    EDITING THIS FILE BY HAND IS NOT RECOMMENDED                                 | -->
<!-- =================================================================================== -->
<robot name="model_missile">
  <material name="grey">
    <color rgba="0.82421875 0.82421875 0.82421875 1.0"/>
  </material>
  <material name="darkgrey">
    <color rgba="0.1843137254901961 0.30980392156862746 0.30980392156862746 1.000"/>
  </material>
  <material name="silver">
    <color rgba="0.700 0.700 0.700 1.000"/>
  </material>
  <material name="white">
    <color rgba="1 1 1 1"/>
  </material>
  <material name="orange">
    <color rgba="1 0.3 0.1 1"/>
  </material>
  <material name="blue">
    <color rgba="0.2 0.2 1 1"/>
  </material>
  <material name="red">
    <color rgba="0.8 0 0 1"/>
  </material>
  <material name="green">
    <color rgba="0.0 1 0.0 1"/>
  </material>
  <material name="black">
    <color rgba="0 0 0 1"/>
  </material>
  <transmission name="fins_rev1_tran">
    <type>transmission_interface/SimpleTransmission</type>
    <joint name="fins_rev1">
      <hardwareInterface>hardware_interface/EffortJointInterface</hardwareInterface>
    </joint>
    <actuator name="fins_rev1_actr">
      <hardwareInterface>hardware_interface/EffortJointInterface</hardwareInterface>
      <mechanicalReduction>1</mechanicalReduction>
    </actuator>
  </transmission>
  <transmission name="fins_rev4_tran">
    <type>transmission_interface/SimpleTransmission</type>
    <joint name="fins_rev4">
      <hardwareInterface>hardware_interface/EffortJointInterface</hardwareInterface>
    </joint>
    <actuator name="fins_rev4_actr">
      <hardwareInterface>hardware_interface/EffortJointInterface</hardwareInterface>
      <mechanicalReduction>1</mechanicalReduction>
    </actuator>
  </transmission>
  <transmission name="fins_rev3_tran">
    <type>transmission_interface/SimpleTransmission</type>
    <joint name="fins_rev3">
      <hardwareInterface>hardware_interface/EffortJointInterface</hardwareInterface>
    </joint>
    <actuator name="fins_rev3_actr">
      <hardwareInterface>hardware_interface/EffortJointInterface</hardwareInterface>
      <mechanicalReduction>1</mechanicalReduction>
    </actuator>
  </transmission>
  <transmission name="fins_rev2_tran">
    <type>transmission_interface/SimpleTransmission</type>
    <joint name="fins_rev2">
      <hardwareInterface>hardware_interface/EffortJointInterface</hardwareInterface>
    </joint>
    <actuator name="fins_rev2_actr">
      <hardwareInterface>hardware_interface/EffortJointInterface</hardwareInterface>
      <mechanicalReduction>1</mechanicalReduction>
    </actuator>
  </transmission>
  <transmission name="wings_fold1_tran">
    <type>transmission_interface/SimpleTransmission</type>
    <joint name="wings_fold1">
      <hardwareInterface>hardware_interface/EffortJointInterface</hardwareInterface>
    </joint>
    <actuator name="wings_fold1_actr">
      <hardwareInterface>hardware_interface/EffortJointInterface</hardwareInterface>
      <mechanicalReduction>1</mechanicalReduction>
    </actuator>
  </transmission>
  <transmission name="wings_fold2_tran">
    <type>transmission_interface/SimpleTransmission</type>
    <joint name="wings_fold2">
      <hardwareInterface>hardware_interface/EffortJointInterface</hardwareInterface>
    </joint>
    <actuator name="wings_fold2_actr">
      <hardwareInterface>hardware_interface/EffortJointInterface</hardwareInterface>
      <mechanicalReduction>1</mechanicalReduction>
    </actuator>
  </transmission>
  <transmission name="wings_fold3_tran">
    <type>transmission_interface/SimpleTransmission</type>
    <joint name="wings_fold3">
      <hardwareInterface>hardware_interface/EffortJointInterface</hardwareInterface>
    </joint>
    <actuator name="wings_fold3_actr">
      <hardwareInterface>hardware_interface/EffortJointInterface</hardwareInterface>
      <mechanicalReduction>1</mechanicalReduction>
    </actuator>
  </transmission>
  <transmission name="wings_fold4_tran">
    <type>transmission_interface/SimpleTransmission</type>
    <joint name="wings_fold4">
      <hardwareInterface>hardware_interface/EffortJointInterface</hardwareInterface>
    </joint>
    <actuator name="wings_fold4_actr">
      <hardwareInterface>hardware_interface/EffortJointInterface</hardwareInterface>
      <mechanicalReduction>1</mechanicalReduction>
    </actuator>
  </transmission>
  <transmission name="fin_fold1_tran">
    <type>transmission_interface/SimpleTransmission</type>
    <joint name="fin_fold1">
      <hardwareInterface>hardware_interface/EffortJointInterface</hardwareInterface>
    </joint>
    <actuator name="fin_fold1_actr">
      <hardwareInterface>hardware_interface/EffortJointInterface</hardwareInterface>
      <mechanicalReduction>1</mechanicalReduction>
    </actuator>
  </transmission>
  <transmission name="fin_fold2_tran">
    <type>transmission_interface/SimpleTransmission</type>
    <joint name="fin_fold2">
      <hardwareInterface>hardware_interface/EffortJointInterface</hardwareInterface>
    </joint>
    <actuator name="fin_fold2_actr">
      <hardwareInterface>hardware_interface/EffortJointInterface</hardwareInterface>
      <mechanicalReduction>1</mechanicalReduction>
    </actuator>
  </transmission>
  <transmission name="fin_fold3_tran">
    <type>transmission_interface/SimpleTransmission</type>
    <joint name="fin_fold3">
      <hardwareInterface>hardware_interface/EffortJointInterface</hardwareInterface>
    </joint>
    <actuator name="fin_fold3_actr">
      <hardwareInterface>hardware_interface/EffortJointInterface</hardwareInterface>
      <mechanicalReduction>1</mechanicalReduction>
    </actuator>
  </transmission>
  <transmission name="fin_fold4_tran">
    <type>transmission_interface/SimpleTransmission</type>
    <joint name="fin_fold4">
      <hardwareInterface>hardware_interface/EffortJointInterface</hardwareInterface>
    </joint>
    <actuator name="fin_fold4_actr">
      <hardwareInterface>hardware_interface/EffortJointInterface</hardwareInterface>
      <mechanicalReduction>1</mechanicalReduction>
    </actuator>
  </transmission>
  <gazebo>
    <plugin filename="libgazebo_ros_control.so" name="model_missile_controller">
      <robotNamespace>model_missile_controller</robotNamespace>
      <robotSimType>gazebo_ros_control/DefaultRobotHWSim</robotSimType>
    </plugin>
    <plugin filename="libThrustVectoring.so" name="ThrustVectoring">
      <link_name>base_link</link_name>
      <forward_dir>1 0 0</forward_dir>
      <thrust_origin>-1.880 0 0</thrust_origin>
      <robotNamespace/>
      <topic_name>thrust_visual</topic_name>
      <vector_topic>thrust_force</vector_topic>
    </plugin>
    <plugin filename="libAerodynamic.so" name="FullBodyAerodynamic">
      <!-- <upward>0 0 1</upward> -->
      <cp>-0.238 0.0 0.0</cp>
      <sref>0.096</sref>
      <lref>0.350</lref>
      <topic_name>AeroVectors</topic_name>
      <air_density>1.2041</air_density>
      <link_name>base_link</link_name>
      <robotNamespace/>
      <radial_symmetry>1/</radial_symmetry>
      <forward>1 0 0</forward>
    </plugin>
  </gazebo>
  <gazebo reference="base_link">
    <material>Gazebo/White</material>
    <mu1>0.2</mu1>
    <mu2>0.2</mu2>
    <selfCollide>true</selfCollide>
    <gravity>true</gravity>
    <visual>
      <plugin filename="libMultiplevectorVisual.so" name="LiftDragVisual">
        <topic_name vector_size="5">AeroVectors</topic_name>
      </plugin>
      <plugin filename="libForceVisual.so" name="VectoredThrustVisual">
        <topic_name>thrust_visual</topic_name>
        <color>Gazebo/Green</color>
      </plugin>
    </visual>
    <sensor name="camera_top_side" type="camera">
      <pose>-3.2 0.0 1 0.0 0.5236000000000001 0.0</pose>
      <camera>
        <horizontal_fov>1.347</horizontal_fov>
        <image>
          <width>640</width>
          <height>480</height>
        </image>
        <clip>
          <near>0.1</near>
          <far>100</far>
        </clip>
      </camera>
      <always_on>1</always_on>
      <update_rate>30</update_rate>
      <!-- <visualize>true</visualize> -->
    </sensor>
    <sensor name="camera_deflection" type="camera">
      <pose>-1.0 -1.0 0.0 0.0 0.0 2.3562</pose>
      <camera>
        <horizontal_fov>1.347</horizontal_fov>
        <image>
          <width>640</width>
          <height>480</height>
        </image>
        <clip>
          <near>0.1</near>
          <far>1000</far>
        </clip>
      </camera>
      <always_on>1</always_on>
      <update_rate>30</update_rate>
      <!-- <visualize>true</visualize> -->
    </sensor>
    <!-- <sensor name='imu_sensor' type='imu'>
    <always_on>1</always_on>
    <update_rate>30</update_rate>
    <imu/>
  </sensor> -->
  </gazebo>
  <gazebo reference="FinHolder_1">
    <material>Gazebo/Blue</material>
    <mu1>0.2</mu1>
    <mu2>0.2</mu2>
    <selfCollide>true</selfCollide>
  </gazebo>
  <gazebo reference="FinHolder_4">
    <material>Gazebo/Blue</material>
    <mu1>0.2</mu1>
    <mu2>0.2</mu2>
    <selfCollide>true</selfCollide>
  </gazebo>
  <gazebo reference="FinHolder_3">
    <material>Gazebo/Blue</material>
    <mu1>0.2</mu1>
    <mu2>0.2</mu2>
    <selfCollide>true</selfCollide>
  </gazebo>
  <gazebo reference="FinHolder_2">
    <material>Gazebo/Blue</material>
    <mu1>0.2</mu1>
    <mu2>0.2</mu2>
    <selfCollide>true</selfCollide>
  </gazebo>
  <gazebo reference="Wing1_1">
    <material>Gazebo/Orange</material>
    <mu1>0.2</mu1>
    <mu2>0.2</mu2>
    <selfCollide>true</selfCollide>
  </gazebo>
  <gazebo reference="Wing1_2">
    <material>Gazebo/Orange</material>
    <mu1>0.2</mu1>
    <mu2>0.2</mu2>
    <selfCollide>true</selfCollide>
  </gazebo>
  <gazebo reference="Wing1_3">
    <material>Gazebo/Orange</material>
    <mu1>0.2</mu1>
    <mu2>0.2</mu2>
    <selfCollide>true</selfCollide>
  </gazebo>
  <gazebo reference="Wing1_4">
    <material>Gazebo/Orange</material>
    <mu1>0.2</mu1>
    <mu2>0.2</mu2>
    <selfCollide>true</selfCollide>
  </gazebo>
  <gazebo reference="Fin_1">
    <material>Gazebo/Orange</material>
    <mu1>0.2</mu1>
    <mu2>0.2</mu2>
    <selfCollide>true</selfCollide>
  </gazebo>
  <gazebo reference="Fin_2">
    <material>Gazebo/Orange</material>
    <mu1>0.2</mu1>
    <mu2>0.2</mu2>
    <selfCollide>true</selfCollide>
  </gazebo>
  <gazebo reference="Fin_3">
    <material>Gazebo/Orange</material>
    <mu1>0.2</mu1>
    <mu2>0.2</mu2>
    <selfCollide>true</selfCollide>
  </gazebo>
  <gazebo reference="Fin_4">
    <material>Gazebo/Orange</material>
    <mu1>0.2</mu1>
    <mu2>0.2</mu2>
    <selfCollide>true</selfCollide>
  </gazebo>
   --&gt;


  <link name="base_link">
    <inertial>
      <origin rpy="0 0 0" xyz="-4.5938008952361996e-12 -5.330786024108829e-16 -2.382079374378753e-16"/>
      <mass value="562.7679612503737"/>
      <inertia ixx="12.078708" ixy="0.0" ixz="0.0" iyy="817.09871" iyz="-0.0" izz="817.09871"/>
    </inertial>
    <visual>
      <origin rpy="0 0 0" xyz="0 0 0"/>
      <geometry>
        <mesh filename="package://model_missile_description/meshes/base_link.stl" scale="0.001 0.001 0.001"/>
      </geometry>
      <material name="white"/>
    </visual>
    <collision>
      <origin rpy="0 0 0" xyz="0 0 0"/>
      <geometry>
        <mesh filename="package://model_missile_description/meshes/base_link.stl" scale="0.001 0.001 0.001"/>
      </geometry>
    </collision>
  </link>
  <link name="FinHolder_1">
    <inertial>
      <origin rpy="0 0 0" xyz="0.011989970177444853 0.024895470365400352 0.02489052657337168"/>
      <mass value="0.6999999481439694"/>
      <inertia ixx="0.00025" ixy="3e-05" ixz="3e-05" iyy="0.004649" iyz="-9.8e-05" izz="0.004649"/>
    </inertial>
    <visual>
      <origin rpy="0 0 0" xyz="1.700844 -0.127279 -0.127279"/>
      <geometry>
        <mesh filename="package://model_missile_description/meshes/FinHolder_1.stl" scale="0.001 0.001 0.001"/>
      </geometry>
      <material name="blue"/>
    </visual>
    <collision>
      <origin rpy="0 0 0" xyz="1.700844 -0.127279 -0.127279"/>
      <geometry>
        <mesh filename="package://model_missile_description/meshes/FinHolder_1.stl" scale="0.001 0.001 0.001"/>
      </geometry>
    </collision>
  </link>
  <link name="FinHolder_4">
    <inertial>
      <origin rpy="0 0 0" xyz="0.011989970177444853 -0.024890526573368127 0.0248954703654041"/>
      <mass value="0.6999999481439694"/>
      <inertia ixx="0.00025" ixy="-3e-05" ixz="3e-05" iyy="0.004649" iyz="9.8e-05" izz="0.004649"/>
    </inertial>
    <visual>
      <origin rpy="0 0 0" xyz="1.700844 0.127279 -0.127279"/>
      <geometry>
        <mesh filename="package://model_missile_description/meshes/FinHolder_4.stl" scale="0.001 0.001 0.001"/>
      </geometry>
      <material name="blue"/>
    </visual>
    <collision>
      <origin rpy="0 0 0" xyz="1.700844 0.127279 -0.127279"/>
      <geometry>
        <mesh filename="package://model_missile_description/meshes/FinHolder_4.stl" scale="0.001 0.001 0.001"/>
      </geometry>
    </collision>
  </link>
  <link name="FinHolder_3">
    <inertial>
      <origin rpy="0 0 0" xyz="0.011989970177444853 -0.024895470365400463 -0.02489052657336438"/>
      <mass value="0.6999999481439694"/>
      <inertia ixx="0.00025" ixy="-3e-05" ixz="-3e-05" iyy="0.004649" iyz="-9.8e-05" izz="0.004649"/>
    </inertial>
    <visual>
      <origin rpy="0 0 0" xyz="1.700844 0.127279 0.127279"/>
      <geometry>
        <mesh filename="package://model_missile_description/meshes/FinHolder_3.stl" scale="0.001 0.001 0.001"/>
      </geometry>
      <material name="blue"/>
    </visual>
    <collision>
      <origin rpy="0 0 0" xyz="1.700844 0.127279 0.127279"/>
      <geometry>
        <mesh filename="package://model_missile_description/meshes/FinHolder_3.stl" scale="0.001 0.001 0.001"/>
      </geometry>
    </collision>
  </link>
  <link name="FinHolder_2">
    <inertial>
      <origin rpy="0 0 0" xyz="0.011989970177444409 0.024890526573368155 -0.024895470365396688"/>
      <mass value="0.6999999481439694"/>
      <inertia ixx="0.00025" ixy="3e-05" ixz="-3e-05" iyy="0.004649" iyz="9.8e-05" izz="0.004649"/>
    </inertial>
    <visual>
      <origin rpy="0 0 0" xyz="1.700844 -0.127279 0.127279"/>
      <geometry>
        <mesh filename="package://model_missile_description/meshes/FinHolder_2.stl" scale="0.001 0.001 0.001"/>
      </geometry>
      <material name="blue"/>
    </visual>
    <collision>
      <origin rpy="0 0 0" xyz="1.700844 -0.127279 0.127279"/>
      <geometry>
        <mesh filename="package://model_missile_description/meshes/FinHolder_2.stl" scale="0.001 0.001 0.001"/>
      </geometry>
    </collision>
  </link>
  <link name="Wing1_1">
    <inertial>
      <origin rpy="0 0 0" xyz="-0.031208061901909834 0.07128204697290338 0.07128204710602434"/>
      <mass value="9.299979574219194"/>
      <inertia ixx="0.055746" ixy="0.012327" ixz="0.012327" iyy="0.41744" iyz="-0.02758" izz="0.41744"/>
    </inertial>
    <visual>
      <origin rpy="0 0 0" xyz="0.380856 -0.163355 -0.163355"/>
      <geometry>
        <mesh filename="package://model_missile_description/meshes/Wing1_1.stl" scale="0.001 0.001 0.001"/>
      </geometry>
      <material name="orange"/>
    </visual>
    <collision>
      <origin rpy="0 0 0" xyz="0.380856 -0.163355 -0.163355"/>
      <geometry>
        <mesh filename="package://model_missile_description/meshes/Wing1_1.stl" scale="0.001 0.001 0.001"/>
      </geometry>
    </collision>
  </link>
  <link name="Wing1_2">
    <inertial>
      <origin rpy="0 0 0" xyz="-0.031208061901910722 0.07057494032483622 -0.07057494019171545"/>
      <mass value="9.299979574219194"/>
      <inertia ixx="0.055746" ixy="0.012327" ixz="-0.012327" iyy="0.41744" iyz="0.02758" izz="0.41744"/>
    </inertial>
    <visual>
      <origin rpy="0 0 0" xyz="0.380856 -0.163355 0.163355"/>
      <geometry>
        <mesh filename="package://model_missile_description/meshes/Wing1_2.stl" scale="0.001 0.001 0.001"/>
      </geometry>
      <material name="orange"/>
    </visual>
    <collision>
      <origin rpy="0 0 0" xyz="0.380856 -0.163355 0.163355"/>
      <geometry>
        <mesh filename="package://model_missile_description/meshes/Wing1_2.stl" scale="0.001 0.001 0.001"/>
      </geometry>
    </collision>
  </link>
  <link name="Wing1_3">
    <inertial>
      <origin rpy="0 0 0" xyz="-0.031208061901910722 -0.07057494019171678 -0.0705749403248346"/>
      <mass value="9.299979574219194"/>
      <inertia ixx="0.055746" ixy="-0.012327" ixz="-0.012327" iyy="0.41744" iyz="-0.02758" izz="0.41744"/>
    </inertial>
    <visual>
      <origin rpy="0 0 0" xyz="0.380856 0.163355 0.163355"/>
      <geometry>
        <mesh filename="package://model_missile_description/meshes/Wing1_3.stl" scale="0.001 0.001 0.001"/>
      </geometry>
      <material name="orange"/>
    </visual>
    <collision>
      <origin rpy="0 0 0" xyz="0.380856 0.163355 0.163355"/>
      <geometry>
        <mesh filename="package://model_missile_description/meshes/Wing1_3.stl" scale="0.001 0.001 0.001"/>
      </geometry>
    </collision>
  </link>
  <link name="Wing1_4">
    <inertial>
      <origin rpy="0 0 0" xyz="-0.031208061901909945 -0.07057494032483608 0.07057494019171842"/>
      <mass value="9.299979574219194"/>
      <inertia ixx="0.055746" ixy="-0.012327" ixz="0.012327" iyy="0.41744" iyz="0.02758" izz="0.41744"/>
    </inertial>
    <visual>
      <origin rpy="0 0 0" xyz="0.380856 0.163355 -0.163355"/>
      <geometry>
        <mesh filename="package://model_missile_description/meshes/Wing1_4.stl" scale="0.001 0.001 0.001"/>
      </geometry>
      <material name="orange"/>
    </visual>
    <collision>
      <origin rpy="0 0 0" xyz="0.380856 0.163355 -0.163355"/>
      <geometry>
        <mesh filename="package://model_missile_description/meshes/Wing1_4.stl" scale="0.001 0.001 0.001"/>
      </geometry>
    </collision>
  </link>
  <link name="Fin_1">
    <inertial>
      <origin rpy="0 0 0" xyz="-0.014318251120852166 0.06139665026364291 0.061396650263642966"/>
      <mass value="1.500000007859579"/>
      <inertia ixx="0.006929" ixy="0.000899" ixz="0.000899" iyy="0.007262" iyz="-0.003432" izz="0.007262"/>
    </inertial>
    <visual>
      <origin rpy="0 0 0" xyz="1.700844 -0.16617 -0.16617"/>
      <geometry>
        <mesh filename="package://model_missile_description/meshes/Fin_1.stl" scale="0.001 0.001 0.001"/>
      </geometry>
      <material name="orange"/>
    </visual>
    <collision>
      <origin rpy="0 0 0" xyz="1.700844 -0.16617 -0.16617"/>
      <geometry>
        <mesh filename="package://model_missile_description/meshes/Fin_1.stl" scale="0.001 0.001 0.001"/>
      </geometry>
    </collision>
  </link>
  <link name="Fin_2">
    <inertial>
      <origin rpy="0 0 0" xyz="-0.01431825112085261 0.06139642160960024 -0.061396878917678394"/>
      <mass value="1.500000007859579"/>
      <inertia ixx="0.006929" ixy="0.000899" ixz="-0.000899" iyy="0.007262" iyz="0.003432" izz="0.007262"/>
    </inertial>
    <visual>
      <origin rpy="0 0 0" xyz="1.700844 -0.166158 0.166182"/>
      <geometry>
        <mesh filename="package://model_missile_description/meshes/Fin_2.stl" scale="0.001 0.001 0.001"/>
      </geometry>
      <material name="orange"/>
    </visual>
    <collision>
      <origin rpy="0 0 0" xyz="1.700844 -0.166158 0.166182"/>
      <geometry>
        <mesh filename="package://model_missile_description/meshes/Fin_2.stl" scale="0.001 0.001 0.001"/>
      </geometry>
    </collision>
  </link>
  <link name="Fin_3">
    <inertial>
      <origin rpy="0 0 0" xyz="-0.014318251120852166 -0.06139665026364283 -0.06139665026363558"/>
      <mass value="1.500000007859579"/>
      <inertia ixx="0.006929" ixy="-0.000899" ixz="-0.000899" iyy="0.007262" iyz="-0.003432" izz="0.007262"/>
    </inertial>
    <visual>
      <origin rpy="0 0 0" xyz="1.700844 0.16617 0.16617"/>
      <geometry>
        <mesh filename="package://model_missile_description/meshes/Fin_3.stl" scale="0.001 0.001 0.001"/>
      </geometry>
      <material name="orange"/>
    </visual>
    <collision>
      <origin rpy="0 0 0" xyz="1.700844 0.16617 0.16617"/>
      <geometry>
        <mesh filename="package://model_missile_description/meshes/Fin_3.stl" scale="0.001 0.001 0.001"/>
      </geometry>
    </collision>
  </link>
  <link name="Fin_4">
    <inertial>
      <origin rpy="0 0 0" xyz="-0.014318251120852166 -0.061396650263639274 0.06139665026364652"/>
      <mass value="1.500000007859579"/>
      <inertia ixx="0.006929" ixy="-0.000899" ixz="0.000899" iyy="0.007262" iyz="0.003432" izz="0.007262"/>
    </inertial>
    <visual>
      <origin rpy="0 0 0" xyz="1.700844 0.16617 -0.16617"/>
      <geometry>
        <mesh filename="package://model_missile_description/meshes/Fin_4.stl" scale="0.001 0.001 0.001"/>
      </geometry>
      <material name="orange"/>
    </visual>
    <collision>
      <origin rpy="0 0 0" xyz="1.700844 0.16617 -0.16617"/>
      <geometry>
        <mesh filename="package://model_missile_description/meshes/Fin_4.stl" scale="0.001 0.001 0.001"/>
      </geometry>
    </collision>
  </link>
  <joint name="fins_rev1" type="revolute">
    <origin rpy="0 0 0" xyz="-1.700844 0.127279 0.127279"/>
    <parent link="base_link"/>
    <child link="FinHolder_1"/>
    <axis xyz="-0.0 0.707107 0.707107"/>
    <limit effort="100" lower="-0.349066" upper="0.349066" velocity="100"/>
  </joint>
  <joint name="fins_rev4" type="revolute">
    <origin rpy="0 0 0" xyz="-1.700844 -0.127279 0.127279"/>
    <parent link="base_link"/>
    <child link="FinHolder_4"/>
    <axis xyz="-0.0 -0.707107 0.707107"/>
    <limit effort="100" lower="-0.349066" upper="0.349066" velocity="100"/>
  </joint>
  <joint name="fins_rev3" type="revolute">
    <origin rpy="0 0 0" xyz="-1.700844 -0.127279 -0.127279"/>
    <parent link="base_link"/>
    <child link="FinHolder_3"/>
    <axis xyz="-0.0 -0.707107 -0.707107"/>
    <limit effort="100" lower="-0.349066" upper="0.349066" velocity="100"/>
  </joint>
  <joint name="fins_rev2" type="revolute">
    <origin rpy="0 0 0" xyz="-1.700844 0.127279 -0.127279"/>
    <parent link="base_link"/>
    <child link="FinHolder_2"/>
    <axis xyz="-0.0 0.707107 -0.707107"/>
    <limit effort="100" lower="-0.349066" upper="0.349066" velocity="100"/>
  </joint>
  <joint name="wings_fold1" type="revolute">
    <origin rpy="0 0 0" xyz="-0.380856 0.163355 0.163355"/>
    <parent link="base_link"/>
    <child link="Wing1_1"/>
    <axis xyz="1.0 -0.0 -0.0"/>
    <limit effort="100" lower="0.0" upper="2.146755" velocity="100"/>
  </joint>
  <joint name="wings_fold2" type="revolute">
    <origin rpy="0 0 0" xyz="-0.380856 0.163355 -0.163355"/>
    <parent link="base_link"/>
    <child link="Wing1_2"/>
    <axis xyz="1.0 0.0 -0.0"/>
    <limit effort="100" lower="0.0" upper="2.146755" velocity="100"/>
  </joint>
  <joint name="wings_fold3" type="revolute">
    <origin rpy="0 0 0" xyz="-0.380856 -0.163355 -0.163355"/>
    <parent link="base_link"/>
    <child link="Wing1_3"/>
    <axis xyz="1.0 0.0 -0.0"/>
    <limit effort="100" lower="0.0" upper="2.146755" velocity="100"/>
  </joint>
  <joint name="wings_fold4" type="revolute">
    <origin rpy="0 0 0" xyz="-0.380856 -0.163355 0.163355"/>
    <parent link="base_link"/>
    <child link="Wing1_4"/>
    <axis xyz="1.0 -0.0 -0.0"/>
    <limit effort="100" lower="0.0" upper="2.146755" velocity="100"/>
  </joint>
  <joint name="fin_fold1" type="revolute">
    <origin rpy="0 0 0" xyz="0.0 0.038891 0.038891"/>
    <parent link="FinHolder_1"/>
    <child link="Fin_1"/>
    <axis xyz="1.0 0.0 0.0"/>
    <limit effort="100" lower="0.0" upper="2.146755" velocity="100"/>
  </joint>
  <joint name="fin_fold2" type="revolute">
    <origin rpy="0 0 0" xyz="0.0 0.038879 -0.038903"/>
    <parent link="FinHolder_2"/>
    <child link="Fin_2"/>
    <axis xyz="1.0 0.0 -0.0"/>
    <limit effort="100" lower="0.0" upper="2.146755" velocity="100"/>
  </joint>
  <joint name="fin_fold3" type="revolute">
    <origin rpy="0 0 0" xyz="0.0 -0.038891 -0.038891"/>
    <parent link="FinHolder_3"/>
    <child link="Fin_3"/>
    <axis xyz="1.0 -0.0 -0.0"/>
    <limit effort="100" lower="0.0" upper="2.146755" velocity="100"/>
  </joint>
  <joint name="fin_fold4" type="revolute">
    <origin rpy="0 0 0" xyz="0.0 -0.038891 0.038891"/>
    <parent link="FinHolder_4"/>
    <child link="Fin_4"/>
    <axis xyz="1.0 -0.0 0.0"/>
    <limit effort="100" lower="0.0" upper="2.146755" velocity="100"/>
  </joint>
</robot>

